Workbook

Sheet Sheet1
A11: 魔法小屋 | B11: 梅林 | F11: 动物店 | G11: 丝特芬妮 | H11: 魔法小屋 | I11: 1 | K11: 饭店 | L11: 奥蒂莉亚 | M11: 家具店 | N11: 坎蒂丝 | P11: 饭店 | Q11: 黛芙妮 | R11: 家具店 | S11: 布蓝达
D12: 1 | G12: 1 | I12: 希贝儿 | L12: 1 | N12: 1 | Q12: 1 | S12: 1
A13: 1
A24: 亚度尼斯 | C24: 动物店 | D24: 格吉尔 | G24: 1 | H24: 道具店 | I24: 1 | J24: 工具店 | K24: 爱格伯特 | N24: 赫伯特 | P24: 朱利尔斯
H25: 布莱兹 | I25: 布拉德利
A35: 工具店 | B35: 1 | C35: 饭店 | D35: 1 | E35: 广场 | F35: 1 | G35: 道具店 | H35: 1 | L35: 城门 | M35: 1 | N35: 城门 | O35: 1 | P35: 家具店 | Q35: 1
A36: 莱特 | C36: 艾琳娜 | F36: 帕特里克 | H36: 玛德琳 | L36: 阿尔杰农 | N36: 瓦尔特 | P36: 班尼迪克
C47: 1 | D47: 多莉丝

Sheet Sheet2
A2: 价值设定 | B2: 1HP=1 | D2: 1金币=1 | E2: 1红晶=100
B3: 1AT=1
B4: 1DF=1
B5: 1Power=1
A7: 农田 | C7: 消耗Rp | D7: 金币 | E7: 金币递增 | F7: 总消耗 | I7: 总Rp
A8: 开垦数 | B8: 8 | C8: 5 | I8: =B8*C8 -> 40
A10: 每块农田数 | B10: 6
A12: 制造
B13: 配方消耗RP=生产道具价值

Sheet 道具
A1: 种子
B2: 3 | C2: 3 | D2: 3 | E2: 3
A5: 植物
A7: 作物名称 | F7: 冬 | G7: 竹笋 | M7: 牧场 | N7: 鸡 | O7: 鸡蛋 | P7: 鸡肉
F8: 春 | G8: 芜菁 | H8: 青椒 | N8: 牛 | O8: 羊毛 | P8: 牛肉
A9: 卷心菜 | F9: 春夏 | G9: 菠菜 | H9: 黄瓜 | I9: 番茄 | J9: 卷心菜 | K9: 萝卜 | N9: 羊 | O9: 牛奶 | P9: 羊肉
F10: 夏秋 | G10: 南瓜 | H10: 玉米 | I10: 红薯 | J10: 马铃薯 | K10: 胡萝卜 | L10: 洋葱
F11: 春秋 | G11: 白菜 | H11: 大葱 | I11: 黄瓜
A12: 南瓜
A13: 黄瓜 | F13: 食材 | G13: 米饭 | H13: 面粉 | I13: 发酵粉 | J13: 盐 | K13: 糖 | L13: 可可
A14: 玉米 | F14: 食物 | G14: 腌芜菁 | H14: 腌黄瓜 | I14: 腌萝卜 | J14: 凉拌西红柿 | K14: 竹笋饭 | L14: 鲑鱼饭团 | M14: 奶酪 | N14: 鱼刺身
G15: 清炒蔬菜 | H15: 番茄炒鸡蛋 | I15: 萝卜炖牛肉 | J15: 烤红薯 | K15: 烤玉米 | L15: 炖羊肉 | M15: 盐焗鸡 | N15: 地三鲜 | O15: 炒饭 | P15: 玉米片 | Q15: 饺子
A16: 番茄
A17: 茄子 | F17: 杂货铺
F18: 种子
A19: 马铃薯 | F19: 食材
A20: 胡萝卜
F21: 饭店
F22: 厨具
A23: 芜菁 | F23: 食物
A24: 萝卜 | F24: 食物配方
A25: 大葱
A26: 紫甘蓝 | F26: 工具店
F27: 工具台
A28: 葡萄 | F28: 武器
A29: 蓝莓 | F29: 防具
A30: 辣椒 | F30: 装备配方
A31: 大蒜
A32: 草莓 | F32: 家具店
A33: 小麦 | F33: 家具
A34: 牧草
F35: 魔法小屋
F36: 药剂
F37: 药剂配方
F38: 药剂台
F40: 动物店
F41: 动物
F42: 牧草

Sheet 装备
C1: 等级 | D1: 值
A2: 长剑 | B2: 剑 | C2: 1 | D2: 1 | E2: 废铁 | F2: 刀刃 | J2: 史莱姆 | K2: 春之山脉 | L2: 1 | M2: 粘液球
A3: 法杖 | B3: 杖 | C3: 1 | D3: 1 | E3: 木棒 | F3: 水晶球 | J3: 进化史莱姆 | K3: 春之山脉 | L3: 2 | M3: 粘液球 | N3: 阿莫尔之水
A4: 铁枪 | B4: 枪 | C4: 2 | D4: 2 | E4: 木棒 | F4: 废铁 | G4: 刀刃 | H4: 刀刃 | J4: 蝙蝠 | K4: 春之山脉 | L4: 3 | M4: 恶魔之翼
A5: 风雷之杖 | B5: 杖 | D5: 2 | E5: 法杖 | F5: 风元素结晶 | J5: 狼蝠 | K5: 春之山脉 | L5: 4 | M5: 恶魔之翼 | N5: 狼牙
A6: 蛇皮鞭 | B6: 鞭 | C6: 3 | D6: 3 | E6: 蛇皮 | F6: 马尾 | J6: 蛮兽 | K6: 春之山脉 | L6: 5 | M6: 兽角
A7: 龙尾鞭 | B7: 鞭 | D7: 3 | E7: 蛇皮鞭 | F7: 龙鳞 | G7: 蜂刺 | J7: 雷霆蛮兽 | K7: 春之山脉 | L7: 6 | M7: 兽角 | N7: 兽皮
A8: 诅咒之剑 | B8: 剑 | D8: 3 | E8: 长剑 | F8: 眼球 | G8: 石化之眼 | J8: 风精灵 | K8: 春之山脉 | L8: 7 | M8: 风元素结晶
A9: 银杖 | B9: 杖 | D9: 4 | E9: 法杖 | F9: 银块 | J9: 利刃蜘蛛 | K9: 瀑布洞穴 | L9: 2 | M9: 刀刃 | N9: 蛛丝
A10: 战斧 | B10: 斧 | C10: 2 | D10: 4 | E10: 钢 | F10: 钢 | G10: 刀刃 | J10: 鬼脸蜘蛛 | K10: 瀑布洞穴 | L10: 1 | M10: 蛛丝
A11: 三叉戟 | B11: 枪 | D11: 4 | E11: 铁枪 | F11: 兽角 | G11: 兽角 | J11: 邪眼 | K11: 瀑布洞穴 | L11: 3 | M11: 眼球
A12: 毒蜥之牙 | B12: 斧 | D12: 5 | E12: 战斧 | F12: 狼牙 | J12: 浮空斜眼 | K12: 瀑布洞穴 | L12: 4 | M12: 眼球
A13: 大地之剑 | B13: 剑 | D13: 5 | E13: 长剑 | F13: 土元素结晶 | J13: 巨魔 | K13: 瀑布洞穴 | L13: 6 | M13: 香菇 | N13: 木棒
A14: 骑士长枪 | B14: 枪 | D14: 5 | E14: 铁枪 | F14: 铁枪 | G14: 兽角 | J14: 哥布林战士 | K14: 瀑布洞穴 | L14: 5 | M14: 布片
A15: 藤鞭 | B15: 鞭 | D15: 6 | E15: 植物的茎 | F15: 马尾 | J15: 守护者 | K15: 瀑布洞穴 | L15: 7 | M15: 废铁 | N15: 钢
A16: 魔力法杖 | B16: 杖 | D16: 6 | E16: 雷霆之杖 | F16: 水元素法杖 | G16: 土元素结晶 | H16: 暗元素结晶 | J16: 彩虹鸟 | K16: 夏之丛林 | L16: 3 | M16: 彩色羽毛
A17: 女王鞭 | B17: 鞭 | D17: 6 | E17: 藤鞭 | F17: 刀刃 | J17: 青龙 | K17: 夏之丛林 | L17: 7 | M17: 龙鳞
A18: 暴雪斧 | B18: 斧 | D18: 7 | E18: 战斧 | F18: 雪球 | J18: 毒蜂 | K18: 夏之丛林 | L18: 1 | M18: 蜂刺 | N18: 蜂蜜
A19: 冰之刃 | B19: 剑 | D19: 7 | E19: 长剑 | F19: 冰晶 | G19: 冰晶 | H19: 雪球 | J19: 食人花 | K19: 夏之丛林 | L19: 2 | M19: 番茄 | N19: 植物的茎
A20: 亡灵之杖 | B20: 杖 | D20: 7 | E20: 法杖 | F20: 亡者之土 | G20: 石化之眼 | H20: 幽魂 | J20: 速龙 | K20: 夏之丛林 | L20: 4 | M20: 亚龙之血
A21: 恶魔之斧 | B21: 斧 | D21: 8 | E21: 战斧 | F21: 魔族之血 | G21: 暗元素结晶 | J21: 巨蟒 | K21: 夏之丛林 | L21: 5 | M21: 蛇皮
J22: 魔狼 | K22: 夏之丛林 | L22: 6 | M22: 狼牙 | N22: 魔兽皮毛
A23: 布衣 | B23: 衣 | D23: 1 | E23: 布片 | F23: 蛛丝 | J23: 蓝龙 | K23: 和风海岸 | L23: 7 | M23: 龙鳞 | N23: 蓝水晶球
A24: 皮铠 | B24: 铠 | D24: 1 | E24: 兽皮 | F24: 蛛丝 | J24: 水元素 | K24: 和风海岸 | L24: 5 | M24: 水元素结晶
A25: 锁子甲 | B25: 铠 | D25: 4 | E25: 皮铠 | F25: 珊瑚 | G25: 废铁 | J25: 水螅 | K25: 和风海岸 | L25: 2 | M25: 纯净之水 | N25: 珊瑚
A26: 毛皮斗篷 | B26: 衣 | D26: 2 | E26: 魔兽皮毛 | F26: 羊毛 | J26: 水母 | K26: 和风海岸 | L26: 1 | M26: 纯净之水
A27: 铁铠甲 | B27: 铠 | D27: 2 | E27: 皮铠 | F27: 废铁 | J27: 蛇女 | K27: 和风海岸 | L27: 6 | M27: 蛇皮 | N27: 石化之眼
A28: 红莲之铠 | B28: 铠 | D28: 5 | E28: 锁子甲 | F28: 蝎尾 | J28: 鱼人 | K28: 和风海岸 | L28: 3 | M28: 鱼胶 | N28: 鱼饵
A29: 华丽背心 | B29: 衣 | D29: 3 | E29: 布衣 | F29: 彩色羽毛 | J29: 飞鲨 | K29: 和风海岸 | L29: 4 | M29: 珊瑚
A30: 鳞铠 | B30: 铠 | D30: 3 | E30: 蛇皮 | F30: 鱼胶 | J30: 盗贼 | K30: 秋风之谷 | L30: 2 | M30: 布片 | N30: 银块
A31: 暗之袍 | B31: 衣 | D31: 8 | E31: 布衣 | F31: 黑暗结晶 | G31: 亡者之土 | H31: 幽魂 | J31: 狮魔 | K31: 秋风之谷 | L31: 7 | M31: 奇美拉之翼 | N31: 魔兽皮毛
A32: 疾风背心 | B32: 衣 | D32: 6 | E32: 布衣 | F32: 风元素结晶 | G32: 奇美拉之翼 | J32: 家楼罗 | K32: 秋风之谷 | L32: 6 | M32: 奇美拉之翼
A33: 魔法铠甲 | B33: 铠 | D33: 7 | E33: 皮铠 | F33: 水晶球 | G33: 金块 | J33: 牛头人 | K33: 秋风之谷 | L33: 5 | M33: 牛角 | N33: 魔兽皮毛
A34: 钢刃锁甲 | B34: 铠 | D34: 6 | E34: 皮铠 | F34: 刀刃 | G34: 钢 | J34: 毒蝎 | K34: 秋风之谷 | L34: 1 | M34: 虫皮
A35: 丝织长袍 | B35: 衣 | D35: 5 | E35: 布片 | F35: 蛛丝 | G35: 蛛丝 | H35: 银块 | J35: 杀手 | K35: 秋风之谷 | L35: 3 | M35: 刀刃 | N35: 金块
A36: 兔女郎装 | B36: 衣 | D36: 7 | E36: 华丽背心 | F36: 兔耳朵 | G36: 羊毛 | H36: 奇美拉之翼 | J36: 狂战 | K36: 秋风之谷 | L36: 4 | M36: 废铁 | N36: 钢
A37: 水之羽衣 | B37: 衣 | D37: 4 | E37: 布衣 | F37: 水元素结晶 | G37: 毛皮斗篷 | H37: 蛛丝 | J37: 空鼠 | K37: 废墟 | L37: 2 | M37: 头巾
J38: 老鼠 | K38: 废墟 | L38: 1 | M38: 头巾 | N38: 银块
J39: 黑衣 | K39: 废墟 | L39: 4 | M39: 布片
J40: 盔甲 | K40: 废墟 | L40: 5 | M40: 废铁
...

Sheet 配方
A2: 饭团 | C2: 米饭 | H2: 卷心菜 | J2: 纯净之水 | N2: 竹笋
A3: 海鲜饭 | C3: 米饭 | D3: 金枪鱼 | E3: 比目鱼 | F3: 辣椒 | H3: 南瓜 | J3: 阿莫尔之水 | N3: 樱桃
A4: 煎蛋 | C4: 鸡蛋 | H4: 黄瓜 | J4: 蜂蜜
A5: 蛋包饭 | C5: 米饭 | D5: 鸡蛋 | E5: 大葱 | H5: 玉米 | J5: 猪肉 | N5: 苹果
A6: 腌芜菁 | C6: 芜菁 | D6: 盐 | H6: 番茄 | J6: 牛奶
A7: 竹笋饭 | C7: 米饭 | D7: 竹笋 | H7: 茄子 | J7: 米饭
A8: 腌黄瓜 | C8: 黄瓜 | D8: 盐 | H8: 马铃薯 | J8: 小麦粉
A9: 鲑鱼饭团 | C9: 米饭 | D9: 烤鲑鱼 | H9: 胡萝卜 | J9: 发酵粉
A10: 奶酪 | C10: 牛奶 | D10: 发酵剂 | H10: 芜菁 | J10: 盐
A11: 三明治 | C11: 面包 | D11: 卷心菜 | E11: 奶酪 | F11: 煎蛋 | H11: 萝卜 | J11: 失败的料理
A12: 蔬菜沙拉 | C12: 黄瓜 | D12: 紫甘蓝 | E12: 萝卜 | F12: 蜂蜜 | H12: 大葱 | J12: 失败的酒水
A13: 鲑鱼刺身 | C13: 鲑鱼 | H13: 紫甘蓝 | J13: 鱿鱼
A14: 鳗鱼饭 | C14: 烤鳗鱼 | D14: 米饭 | H14: 葡萄 | J14: 鳗鱼
A15: 鲱鱼罐头 | C15: 罐头盒 | D15: 鲱鱼 | E15: 阿莫尔之水 | H15: 蓝莓 | J15: 沙丁鱼
A16: 沙丁鱼罐头 | C16: 罐头盒 | D16: 沙丁鱼 | E16: 阿莫尔之水 | H16: 辣椒 | J16: 河蚌
A17: 汉堡 | C17: 面包 | D17: 卷心菜 | E17: 肉饼 | H17: 大蒜 | J17: 金枪鱼
A18: 烤鳗鱼 | C18: 鳗鱼 | D18: 盐 | H18: 草莓 | J18: 龙虾
A19: 鱼子酱 | C19: 鲟鱼 | D19: 罐头盒 | E19: 阿莫尔之水 | H19: 饭团 | J19: 鲱鱼
A20: 烤面包 | C20: 小麦粉 | D20: 发酵剂 | E20: 盐 | H20: 海鲜饭 | J20: 海参
A21: 烤鱿鱼 | C21: 鱿鱼 | D21: 盐 | E21: 大蒜 | H21: 煎蛋 | J21: 鲟鱼
A22: 河豚汤 | C22: 河豚 | D22: 大葱 | E22: 盐 | H22: 蛋包饭 | J22: 比目鱼
A23: 烤龙虾 | C23: 龙虾 | D23: 大蒜 | E23: 盐 | H23: 腌芜菁 | J23: 鲑鱼
A24: 烤蟹肉 | C24: 螃蟹 | D24: 大蒜 | E24: 盐 | H24: 竹笋饭 | J24: 鲶鱼
A25: 烤土豆 | C25: 马铃薯 | H25: 腌黄瓜 | J25: 鳟鱼
A26: 炸肉饼 | C26: 猪肉 | D26: 大蒜 | H26: 鲑鱼饭团 | J26: 河豚
A27: 爆玉米花 | C27: 玉米 | H27: 奶酪 | J27: 螃蟹
A28: 河蚌汤 | C28: 河蚌 | D28: 纯净之水 | E28: 大蒜 | F28: 大葱 | H28: 三明治 | J28: 空罐头盒
A29: 海鲜浓汤 | C29: 鳟鱼 | D29: 海参 | E29: 大蒜 | F29: 辣椒 | H29: 沙拉
A30: 肉丸子 | C30: 猪肉 | D30: 大蒜 | H30: 鳗鱼饭
A31: 葡萄酒 | C31: 葡萄 | D31: 发酵剂 | H31: 鲱鱼罐头
A32: 苹果酒 | C32: 苹果 | D32: 发酵剂 | H32: 沙丁鱼罐头
A33: 蓝莓酒 | C33: 蓝莓 | D33: 发酵剂 | H33: 汉堡
A34: 混合果蔬汁 | C34: 番茄 | D34: 苹果 | E34: 葡萄 | F34: 胡萝卜 | H34: 烤鳗鱼
A35: 绯红之吻 | C35: 草莓 | D35: 番茄 | E35: 樱桃 | F35: 蜂蜜 | H35: 鱼子酱
A36: 格瓦斯 | C36: 面包 | D36: 发酵剂 | E36: 纯净之水 | H36: 烤面包
A37: 酸奶 | C37: 牛奶 | D37: 发酵剂 | E37: 阿莫尔之水 | H37: 烤鱿鱼
A38: 椰奶 | C38: 牛奶 | D38: 椰子 | E38: 蜂蜜 | H38: 河豚汤
H39: 烤龙虾
H40: 烤蟹肉
B41: 纯净之水 | H41: 烤土豆
...

Sheet Sheet4
A1: 动物 | B1: 产出 | C1: 类别 | D1: 产出价值 | F1: 攻击力 | G1: 防御力 | I1: 鱼 | N1: 怪物 | O1: 地图 | P1: 难度系数 | Q1: 掉落物1 | R1: 掉落物2 | S1: 掉落金币 | T1: 掉落经验
A2: 鸡 | B2: 鸡蛋 | C2: 食材 | D2: 1 | F2: 3 | G2: 3 | M2: 1 | N2: 史莱姆 | O2: 春之山脉 | P2: 1 | Q2: 粘液球
A3: 兔 | B3: 兔耳 | C3: 防具材料 | D3: 2 | F3: 4 | G3: 4 | I3: 鱿鱼 | J3: 春、夏 | M3: 1 | N3: 进化史莱姆 | O3: 春之山脉 | P3: 2 | Q3: 粘液球 | R3: 阿莫尔之水
A4: 羊 | B4: 羊毛 | C4: 防具材料 | D4: 2 | F4: 5 | G4: 6 | I4: 鳗鱼 | J4: 春、夏 | M4: 1 | N4: 蝙蝠 | O4: 春之山脉 | P4: 3 | Q4: 恶魔之翼
A5: 猪 | B5: 猪肉 | C5: 食材 | D5: 3 | F5: 5 | G5: 7 | I5: 沙丁鱼 | J5: 春、夏 | M5: 1 | N5: 狼蝠 | O5: 春之山脉 | P5: 4 | Q5: 恶魔之翼 | R5: 狼牙
A6: 松鼠 | B6: 松子 | C6: 防具材料 | D6: 3 | F6: 8 | G6: 5 | I6: 河蚌 | J6: 春、夏 | M6: 1 | N6: 蛮兽 | O6: 春之山脉 | P6: 5 | Q6: 兽角
A7: 马 | B7: 马尾 | C7: 防具材料 | D7: 3 | F7: 6 | G7: 8 | I7: 金枪鱼 | J7: 春、夏 | M7: 1 | N7: 雷霆蛮兽 | O7: 春之山脉 | P7: 6 | Q7: 兽角 | R7: 兽皮
A8: 牛 | B8: 牛奶 | C8: 食材 | D8: 2 | F8: 6 | G8: 9 | I8: 龙虾 | J8: 冬、春 | M8: 1 | N8: 风精灵 | O8: 春之山脉 | P8: 7 | Q8: 风元素结晶
A9: 蘑菇怪 | B9: 蘑菇 | C9: 武器材料 | D9: 4 | F9: 7 | G9: 7 | I9: 鲱鱼 | J9: 冬、春 | M9: 7 | N9: 骷髅兵 | O9: 冬之雪原 | P9: 1 | Q9: 骨粉
A10: 狗 | B10: 犬齿 | C10: 武器材料 | D10: 3 | F10: 9 | G10: 6 | I10: 海参 | J10: 冬、春 | M10: 7 | N10: 浮游 | O10: 冬之雪原 | P10: 2 | Q10: 幽魂
I11: 鲟鱼 | J11: 冬、春 | M11: 7 | N11: 僵尸 | O11: 冬之雪原 | P11: 3 | Q11: 腐肉
A12: 植物 | B12: 季节 | C12: 生长期 | D12: 循环数 | E12: 循环间隔 | F12: 产出物价值 | I12: 比目鱼 | J12: 冬、春 | M12: 7 | N12: 亡灵法师 | O12: 冬之雪原 | P12: 4 | Q12: 亡灵之书
A13: 卷心菜 | B13: 春、夏 | C13: 4 | D13: 1 | F13: 2 | G13: 2 | I13: 鲑鱼 | J13: 夏、秋 | M13: 7 | N13: 地狱犬 | O13: 冬之雪原 | P13: 5 | Q13: 狂暴止血
A14: 南瓜 | B14: 夏、秋 | C14: 9 | D14: 1 | F14: 7 | G14: 2 | I14: 鲶鱼 | J14: 夏、秋 | M14: 7 | N14: 幽灵盔甲 | O14: 冬之雪原 | P14: 6 | Q14: 幽魂 | R14: 废铁
A15: 黄瓜 | B15: 春、夏 | C15: 10 | D15: 2 | E15: 5 | F15: 6 | G15: 2 | I15: 鳟鱼 | J15: 夏、秋 | M15: 7 | N15: 白龙 | O15: 冬之雪原 | P15: 7 | Q15: 龙鳞 | R15: 冰之结晶
A16: 玉米 | B16: 春、夏 | C16: 20 | D16: 1 | F16: 10 | G16: 2 | I16: 河豚 | J16: 夏、秋 | M16: 7 | N16: 死神 | O16: 冬之雪原 | P16: 8 | Q16: 黑暗结晶
A17: 番茄 | B17: 夏 | C17: 10 | D17: 2 | E17: 5 | F17: 6 | G17: 2 | I17: 螃蟹 | J17: 夏、秋 | M17: 6 | N17: 老鼠 | O17: 废墟 | P17: 1 | Q17: 鼠尾
A18: 茄子 | B18: 秋 | C18: 8 | D18: 1 | F18: 7 | G18: 2 | I18: 空罐头盒 | M18: 6 | N18: 空鼠 | O18: 废墟 | P18: 2 | Q18: 鼠尾
A19: 马铃薯 | B19: 夏、秋 | C19: 15 | D19: 1 | F19: 9 | G19: 2 | M19: 6 | N19: 傀儡 | O19: 废墟 | P19: 3 | Q19: 机关
A20: 胡萝卜 | B20: 秋 | C20: 9 | D20: 1 | F20: 8 | G20: 2 | M20: 6 | N20: 黑衣 | O20: 废墟 | P20: 4 | Q20: 布片
A21: 芜菁 | B21: 春 | C21: 4 | D21: 1 | F21: 2 | G21: 2 | M21: 6 | N21: 盔甲 | O21: 废墟 | P21: 5 | Q21: 废铁
A22: 萝卜 | B22: 秋 | C22: 7 | D22: 1 | F22: 5 | G22: 2 | M22: 6 | N22: 宝箱怪 | O22: 废墟 | P22: 6
A23: 大葱 | B23: 夏、秋 | C23: 5 | D23: 1 | F23: 3 | G23: 2 | M23: 6 | N23: 暴徒 | O23: 废墟 | P23: 7 | Q23: 刀刃 | R23: 头巾
A24: 甘蓝 | B24: 春 | C24: 5 | D24: 1 | F24: 3 | G24: 2 | M24: 6 | N24: 恶法师 | O24: 废墟 | P24: 8 | Q24: 水晶球
A25: 葡萄 | B25: 春、夏 | C25: 30 | D25: 6 | E25: 15 | F25: 9 | G25: 2 | M25: 4 | N25: 水母 | O25: 和风海岸 | P25: 1 | Q25: 纯净之水
A26: 蓝莓 | B26: 冬、春 | C26: 30 | D26: 3 | E26: 10 | F26: 9 | G26: 2 | M26: 4 | N26: 水螅 | O26: 和风海岸 | P26: 2 | Q26: 纯净之水 | R26: 珊瑚
A27: 辣椒 | B27: 夏 | C27: 7 | D27: 1 | F27: 5 | G27: 2 | M27: 4 | N27: 鱼人 | O27: 和风海岸 | P27: 3 | Q27: 鱼胶 | R27: 鱼饵
A28: 大蒜 | B28: 夏、秋 | C28: 6 | D28: 1 | F28: 4 | G28: 2 | M28: 4 | N28: 飞鲨 | O28: 和风海岸 | P28: 4 | Q28: 鱼鳍
A29: 草莓 | B29: 春、夏 | C29: 30 | D29: 3 | E29: 10 | F29: 9 | G29: 2 | M29: 4 | N29: 水元素 | O29: 和风海岸 | P29: 5 | Q29: 水元素结晶
A30: 小麦 | B30: 冬、春 | C30: 30 | D30: 1 | F30: 11 | G30: 2 | I30: 采集物 | M30: 4 | N30: 蛇女 | O30: 和风海岸 | P30: 6 | Q30: 蛇皮 | R30: 石化之眼
A31: 牧草 | B31: 春、夏、秋 | C31: 4 | D31: 1 | F31: 1 | G31: 2 | I31: 野草 | M31: 4 | N31: 蓝龙 | O31: 和风海岸 | P31: 7 | Q31: 龙鳞 | R31: 蓝水晶球
I32: 香菇 | M32: 8 | N32: 小恶魔 | O32: 极寒冰隙 | P32: 1 | Q32: 恶魔之翼
A33: 装备 | E33: 药剂 | I33: 蘑菇 | M33: 8 | N33: 恶魔犬 | O33: 极寒冰隙 | P33: 2 | Q33: 铁链
A34: 长剑 | E34: 回春丸 | I34: 竹笋 | M34: 8 | N34: 羊角恶魔 | O34: 极寒冰隙 | P34: 3 | Q34: 恶魔之角
A35: 诅咒之剑 | E35: 治愈药剂 | I35: 四叶草 | M35: 8 | N35: 魅魔 | O35: 极寒冰隙 | P35: 4 | Q35: 魅惑之心
A36: 恶魔之矛 | E36: 万能之药 | I36: 野玫瑰 | M36: 8 | N36: 魔族大将 | O36: 极寒冰隙 | P36: 5 | Q36: 魔族之血
A37: 冰之刃 | E37: 魔法圣水 | I37: 石材 | M37: 8 | N37: 血族伯爵 | O37: 极寒冰隙 | P37: 6 | Q37: 血族徽章
A38: 大地之剑 | E38: 精灵药水 | I38: 枯木 | M38: 8 | N38: 千手天使 | O38: 极寒冰隙 | P38: 7 | Q38: 邪恶圣光
A39: 铁枪 | E39: 异化之药 | I39: 铁矿 | M39: 2 | N39: 鬼脸蜘蛛 | O39: 瀑布洞穴 | P39: 1 | Q39: 蛛丝
A40: 骑士长枪 | E40: 魅惑香水 | I40: 蜗牛 | M40: 2 | N40: 利刃蜘蛛 | O40: 瀑布洞穴 | P40: 2 | Q40: 蜘蛛腿 | R40: 蛛丝
...

Sheet Sheet6
A1: 哥布林战士 | C1: 哥布林战士 | D1: =VLOOKUP(C1,Sheet3!$E$1:$F$58,2,FALSE) -> 7000000 | E1: 500 | F1: 哥布林战士 | G1: =VLOOKUP(F1,Sheet3!$E$1:$F$58,2,FALSE) -> 7000000 | H1: 500 | I1: 史莱姆 | J1: =VLOOKUP(I1,Sheet3!$E$1:$F$58,2,FALSE) -> 7000001 | K1: 250 | L1: 利刃蜘蛛 | M1: =VLOOKUP(L1,Sheet3!$E$1:$F$58,2,FALSE) -> 7000002 | N1: 250 | O1: 蛮兽 | P1: =VLOOKUP(O1,Sheet3!$E$1:$F$58,2,FALSE) -> 7000003 | Q1: 125 | R1: 风精灵 | S1: =VLOOKUP(R1,Sheet3!$E$1:$F$58,2,FALSE) -> 7000005 | T1: 125
A2: 史莱姆 | F2: 史莱姆 | G2: =VLOOKUP(F2,Sheet3!$E$1:$F$58,2,FALSE) -> 7000001 | H2: 500 | I2: 利刃蜘蛛 | J2: =VLOOKUP(I2,Sheet3!$E$1:$F$58,2,FALSE) -> 7000002 | K2: 250 | L2: 蛮兽 | M2: =VLOOKUP(L2,Sheet3!$E$1:$F$58,2,FALSE) -> 7000003 | N2: 250 | O2: 雷霆蛮兽 | P2: =VLOOKUP(O2,Sheet3!$E$1:$F$58,2,FALSE) -> 7000004 | Q2: 125
A3: 利刃蜘蛛
A4: 蛮兽
A5: 雷霆蛮兽
A6: 风精灵
C10: 0 | F10: 20 | I10: 40 | L10: 60 | O10: 80 | R10: 100
D11: =D1&IF(D2<>0,","&D2,"")&IF(D3<>0,","&D3,"")&IF(D4<>0,","&D4,"")&IF(D5<>0,","&D5,"")&IF(D6<>0,","&D6,"")&IF(D7<>0,","&D7,"")&IF(D8<>0,","&D8,"") -> 7000000 | E11: =E1&IF(E2<>0,","&E2,"")&IF(E3<>0,","&E3,"")&IF(E4<>0,","&E4,"")&IF(E5<>0,","&E5,"")&IF(E6<>0,","&E6,"")&IF(E7<>0,","&E7,"")&IF(E8<>0,","&E8,"") -> 500 | G11: =G1&IF(G2<>0,","&G2,"")&IF(G3<>0,","&G3,"")&IF(G4<>0,","&G4,"")&IF(G5<>0,","&G5,"")&IF(G6<>0,","&G6,"")&IF(G7<>0,","&G7,"")&IF(G8<>0,","&G8,"") -> 7000000,7000001 | H11: =H1&IF(H2<>0,","&H2,"")&IF(H3<>0,","&H3,"")&IF(H4<>0,","&H4,"")&IF(H5<>0,","&H5,"")&IF(H6<>0,","&H6,"")&IF(H7<>0,","&H7,"")&IF(H8<>0,","&H8,"") -> 500,500 | J11: =J1&IF(J2<>0,","&J2,"")&IF(J3<>0,","&J3,"")&IF(J4<>0,","&J4,"")&IF(J5<>0,","&J5,"")&IF(J6<>0,","&J6,"")&IF(J7<>0,","&J7,"")&IF(J8<>0,","&J8,"") -> 7000001,7000002 | K11: =K1&IF(K2<>0,","&K2,"")&IF(K3<>0,","&K3,"")&IF(K4<>0,","&K4,"")&IF(K5<>0,","&K5,"")&IF(K6<>0,","&K6,"")&IF(K7<>0,","&K7,"")&IF(K8<>0,","&K8,"") -> 250,250 | M11: =M1&IF(M2<>0,","&M2,"")&IF(M3<>0,","&M3,"")&IF(M4<>0,","&M4,"")&IF(M5<>0,","&M5,"")&IF(M6<>0,","&M6,"")&IF(M7<>0,","&M7,"")&IF(M8<>0,","&M8,"") -> 7000002,7000003 | N11: =N1&IF(N2<>0,","&N2,"")&IF(N3<>0,","&N3,"")&IF(N4<>0,","&N4,"")&IF(N5<>0,","&N5,"")&IF(N6<>0,","&N6,"")&IF(N7<>0,","&N7,"")&IF(N8<>0,","&N8,"") -> 250,250 | P11: =P1&IF(P2<>0,","&P2,"")&IF(P3<>0,","&P3,"")&IF(P4<>0,","&P4,"")&IF(P5<>0,","&P5,"")&IF(P6<>0,","&P6,"")&IF(P7<>0,","&P7,"")&IF(P8<>0,","&P8,"") -> 7000003,7000004 | Q11: =Q1&IF(Q2<>0,","&Q2,"")&IF(Q3<>0,","&Q3,"")&IF(Q4<>0,","&Q4,"")&IF(Q5<>0,","&Q5,"")&IF(Q6<>0,","&Q6,"")&IF(Q7<>0,","&Q7,"")&IF(Q8<>0,","&Q8,"") -> 125,125 | S11: =S1&IF(S2<>0,","&S2,"")&IF(S3<>0,","&S3,"")&IF(S4<>0,","&S4,"")&IF(S5<>0,","&S5,"")&IF(S6<>0,","&S6,"")&IF(S7<>0,","&S7,"")&IF(S8<>0,","&S8,"") -> 7000005 | T11: =T1&IF(T2<>0,","&T2,"")&IF(T3<>0,","&T3,"")&IF(T4<>0,","&T4,"")&IF(T5<>0,","&T5,"")&IF(T6<>0,","&T6,"")&IF(T7<>0,","&T7,"")&IF(T8<>0,","&T8,"") -> 125
A12: =C12&"|"&F12&"|"&I12&"|"&L12&"|"&O12&"|"&R12&"|"&U12 -> 0;7000000;500|20;7000000,7000001;500,500|40;7000001,7000002;250,250|60;7000002,7000003;250,250|80;7000003,7000004;125,125|100;7000005;125| | C12: =C10&";"&D11&";"&E11 -> 0;7000000;500 | F12: =F10&";"&G11&";"&H11 -> 20;7000000,7000001;500,500 | I12: =I10&";"&J11&";"&K11 -> 40;7000001,7000002;250,250 | L12: =L10&";"&M11&";"&N11 -> 60;7000002,7000003;250,250 | O12: =O10&";"&P11&";"&Q11 -> 80;7000003,7000004;125,125 | R12: =R10&";"&S11&";"&T11 -> 100;7000005;125
A15: 巨魔 | C15: 巨魔 | D15: =VLOOKUP(C15,Sheet3!$E$1:$F$58,2,FALSE) -> 7000006 | E15: 500 | F15: 巨魔 | G15: =VLOOKUP(F15,Sheet3!$E$1:$F$58,2,FALSE) -> 7000006 | H15: 500 | I15: 进化史莱姆 | J15: =VLOOKUP(I15,Sheet3!$E$1:$F$58,2,FALSE) -> 7000007 | K15: 250 | L15: 蜘蛛 | M15: =VLOOKUP(L15,Sheet3!$E$1:$F$58,2,FALSE) -> 7000008 | N15: 250 | O15: 狼蝠 | P15: =VLOOKUP(O15,Sheet3!$E$1:$F$58,2,FALSE) -> 7000009 | Q15: 125 | R15: 守护者 | S15: =VLOOKUP(R15,Sheet3!$E$1:$F$58,2,FALSE) -> 7000011 | T15: 125
A16: 进化史莱姆 | F16: 进化史莱姆 | G16: =VLOOKUP(F16,Sheet3!$E$1:$F$58,2,FALSE) -> 7000007 | H16: 500 | I16: 蜘蛛 | J16: =VLOOKUP(I16,Sheet3!$E$1:$F$58,2,FALSE) -> 7000008 | K16: 250 | L16: 狼蝠 | M16: =VLOOKUP(L16,Sheet3!$E$1:$F$58,2,FALSE) -> 7000009 | N16: 250 | O16: 魔狼 | P16: =VLOOKUP(O16,Sheet3!$E$1:$F$58,2,FALSE) -> 7000010 | Q16: 125
A17: 蜘蛛
A18: 狼蝠
A19: 魔狼
A20: 守护者
C24: 0 | F24: 20 | I24: 40 | L24: 60 | O24: 80 | R24: 100
D25: =D15&IF(D16<>0,","&D16,"")&IF(D17<>0,","&D17,"")&IF(D18<>0,","&D18,"")&IF(D19<>0,","&D19,"")&IF(D20<>0,","&D20,"")&IF(D21<>0,","&D21,"")&IF(D22<>0,","&D22,"") -> 7000006 | E25: =E15&IF(E16<>0,","&E16,"")&IF(E17<>0,","&E17,"")&IF(E18<>0,","&E18,"")&IF(E19<>0,","&E19,"")&IF(E20<>0,","&E20,"")&IF(E21<>0,","&E21,"")&IF(E22<>0,","&E22,"") -> 500 | G25: =G15&IF(G16<>0,","&G16,"")&IF(G17<>0,","&G17,"")&IF(G18<>0,","&G18,"")&IF(G19<>0,","&G19,"")&IF(G20<>0,","&G20,"")&IF(G21<>0,","&G21,"")&IF(G22<>0,","&G22,"") -> 7000006,7000007 | H25: =H15&IF(H16<>0,","&H16,"")&IF(H17<>0,","&H17,"")&IF(H18<>0,","&H18,"")&IF(H19<>0,","&H19,"")&IF(H20<>0,","&H20,"")&IF(H21<>0,","&H21,"")&IF(H22<>0,","&H22,"") -> 500,500 | J25: =J15&IF(J16<>0,","&J16,"")&IF(J17<>0,","&J17,"")&IF(J18<>0,","&J18,"")&IF(J19<>0,","&J19,"")&IF(J20<>0,","&J20,"")&IF(J21<>0,","&J21,"")&IF(J22<>0,","&J22,"") -> 7000007,7000008 | K25: =K15&IF(K16<>0,","&K16,"")&IF(K17<>0,","&K17,"")&IF(K18<>0,","&K18,"")&IF(K19<>0,","&K19,"")&IF(K20<>0,","&K20,"")&IF(K21<>0,","&K21,"")&IF(K22<>0,","&K22,"") -> 250,250 | M25: =M15&IF(M16<>0,","&M16,"")&IF(M17<>0,","&M17,"")&IF(M18<>0,","&M18,"")&IF(M19<>0,","&M19,"")&IF(M20<>0,","&M20,"")&IF(M21<>0,","&M21,"")&IF(M22<>0,","&M22,"") -> 7000008,7000009 | N25: =N15&IF(N16<>0,","&N16,"")&IF(N17<>0,","&N17,"")&IF(N18<>0,","&N18,"")&IF(N19<>0,","&N19,"")&IF(N20<>0,","&N20,"")&IF(N21<>0,","&N21,"")&IF(N22<>0,","&N22,"") -> 250,250 | P25: =P15&IF(P16<>0,","&P16,"")&IF(P17<>0,","&P17,"")&IF(P18<>0,","&P18,"")&IF(P19<>0,","&P19,"")&IF(P20<>0,","&P20,"")&IF(P21<>0,","&P21,"")&IF(P22<>0,","&P22,"") -> 7000009,7000010 | Q25: =Q15&IF(Q16<>0,","&Q16,"")&IF(Q17<>0,","&Q17,"")&IF(Q18<>0,","&Q18,"")&IF(Q19<>0,","&Q19,"")&IF(Q20<>0,","&Q20,"")&IF(Q21<>0,","&Q21,"")&IF(Q22<>0,","&Q22,"") -> 125,125 | S25: =S15&IF(S16<>0,","&S16,"")&IF(S17<>0,","&S17,"")&IF(S18<>0,","&S18,"")&IF(S19<>0,","&S19,"")&IF(S20<>0,","&S20,"")&IF(S21<>0,","&S21,"")&IF(S22<>0,","&S22,"") -> 7000011 | T25: =T15&IF(T16<>0,","&T16,"")&IF(T17<>0,","&T17,"")&IF(T18<>0,","&T18,"")&IF(T19<>0,","&T19,"")&IF(T20<>0,","&T20,"")&IF(T21<>0,","&T21,"")&IF(T22<>0,","&T22,"") -> 125
A26: =C26&"|"&F26&"|"&I26&"|"&L26&"|"&O26&"|"&R26&"|"&U26 -> 0;7000006;500|20;7000006,7000007;500,500|40;7000007,7000008;250,250|60;7000008,7000009;250,250|80;7000009,7000010;125,125|100;7000011;125| | C26: =C24&";"&D25&";"&E25 -> 0;7000006;500 | F26: =F24&";"&G25&";"&H25 -> 20;7000006,7000007;500,500 | I26: =I24&";"&J25&";"&K25 -> 40;7000007,7000008;250,250 | L26: =L24&";"&M25&";"&N25 -> 60;7000008,7000009;250,250 | O26: =O24&";"&P25&";"&Q25 -> 80;7000009,7000010;125,125 | R26: =R24&";"&S25&";"&T25 -> 100;7000011;125
A29: 蜜蜂 | C29: 蜜蜂 | D29: =VLOOKUP(C29,Sheet3!$E$1:$F$58,2,FALSE) -> 7000012 | E29: 500 | F29: 蜜蜂 | G29: =VLOOKUP(F29,Sheet3!$E$1:$F$58,2,FALSE) -> 7000012 | H29: 500 | I29: 巨蟒 | J29: =VLOOKUP(I29,Sheet3!$E$1:$F$58,2,FALSE) -> 7000013 | K29: 250 | L29: 毒蜂 | M29: =VLOOKUP(L29,Sheet3!$E$1:$F$58,2,FALSE) -> 7000014 | N29: 250 | O29: 邪眼 | P29: =VLOOKUP(O29,Sheet3!$E$1:$F$58,2,FALSE) -> 7000015 | Q29: 125 | R29: 蓝龙 | S29: =VLOOKUP(R29,Sheet3!$E$1:$F$58,2,FALSE) -> 7000017 | T29: 125
A30: 巨蟒 | F30: 巨蟒 | G30: =VLOOKUP(F30,Sheet3!$E$1:$F$58,2,FALSE) -> 7000013 | H30: 500 | I30: 毒蜂 | J30: =VLOOKUP(I30,Sheet3!$E$1:$F$58,2,FALSE) -> 7000014 | K30: 250 | L30: 邪眼 | M30: =VLOOKUP(L30,Sheet3!$E$1:$F$58,2,FALSE) -> 7000015 | N30: 250 | O30: 彩虹鸟 | P30: =VLOOKUP(O30,Sheet3!$E$1:$F$58,2,FALSE) -> 7000016 | Q30: 125
A31: 毒蜂
A32: 邪眼
A33: 彩虹鸟
A34: 蓝龙
C38: 0 | F38: 20 | I38: 40 | L38: 60 | O38: 80 | R38: 100
D39: =D29&IF(D30<>0,","&D30,"")&IF(D31<>0,","&D31,"")&IF(D32<>0,","&D32,"")&IF(D33<>0,","&D33,"")&IF(D34<>0,","&D34,"")&IF(D35<>0,","&D35,"")&IF(D36<>0,","&D36,"") -> 7000012 | E39: =E29&IF(E30<>0,","&E30,"")&IF(E31<>0,","&E31,"")&IF(E32<>0,","&E32,"")&IF(E33<>0,","&E33,"")&IF(E34<>0,","&E34,"")&IF(E35<>0,","&E35,"")&IF(E36<>0,","&E36,"") -> 500 | G39: =G29&IF(G30<>0,","&G30,"")&IF(G31<>0,","&G31,"")&IF(G32<>0,","&G32,"")&IF(G33<>0,","&G33,"")&IF(G34<>0,","&G34,"")&IF(G35<>0,","&G35,"")&IF(G36<>0,","&G36,"") -> 7000012,7000013 | H39: =H29&IF(H30<>0,","&H30,"")&IF(H31<>0,","&H31,"")&IF(H32<>0,","&H32,"")&IF(H33<>0,","&H33,"")&IF(H34<>0,","&H34,"")&IF(H35<>0,","&H35,"")&IF(H36<>0,","&H36,"") -> 500,500 | J39: =J29&IF(J30<>0,","&J30,"")&IF(J31<>0,","&J31,"")&IF(J32<>0,","&J32,"")&IF(J33<>0,","&J33,"")&IF(J34<>0,","&J34,"")&IF(J35<>0,","&J35,"")&IF(J36<>0,","&J36,"") -> 7000013,7000014 | K39: =K29&IF(K30<>0,","&K30,"")&IF(K31<>0,","&K31,"")&IF(K32<>0,","&K32,"")&IF(K33<>0,","&K33,"")&IF(K34<>0,","&K34,"")&IF(K35<>0,","&K35,"")&IF(K36<>0,","&K36,"") -> 250,250 | M39: =M29&IF(M30<>0,","&M30,"")&IF(M31<>0,","&M31,"")&IF(M32<>0,","&M32,"")&IF(M33<>0,","&M33,"")&IF(M34<>0,","&M34,"")&IF(M35<>0,","&M35,"")&IF(M36<>0,","&M36,"") -> 7000014,7000015 | N39: =N29&IF(N30<>0,","&N30,"")&IF(N31<>0,","&N31,"")&IF(N32<>0,","&N32,"")&IF(N33<>0,","&N33,"")&IF(N34<>0,","&N34,"")&IF(N35<>0,","&N35,"")&IF(N36<>0,","&N36,"") -> 250,250 | P39: =P29&IF(P30<>0,","&P30,"")&IF(P31<>0,","&P31,"")&IF(P32<>0,","&P32,"")&IF(P33<>0,","&P33,"")&IF(P34<>0,","&P34,"")&IF(P35<>0,","&P35,"")&IF(P36<>0,","&P36,"") -> 7000015,7000016 | Q39: =Q29&IF(Q30<>0,","&Q30,"")&IF(Q31<>0,","&Q31,"")&IF(Q32<>0,","&Q32,"")&IF(Q33<>0,","&Q33,"")&IF(Q34<>0,","&Q34,"")&IF(Q35<>0,","&Q35,"")&IF(Q36<>0,","&Q36,"") -> 125,125 | S39: =S29&IF(S30<>0,","&S30,"")&IF(S31<>0,","&S31,"")&IF(S32<>0,","&S32,"")&IF(S33<>0,","&S33,"")&IF(S34<>0,","&S34,"")&IF(S35<>0,","&S35,"")&IF(S36<>0,","&S36,"") -> 7000017 | T39: =T29&IF(T30<>0,","&T30,"")&IF(T31<>0,","&T31,"")&IF(T32<>0,","&T32,"")&IF(T33<>0,","&T33,"")&IF(T34<>0,","&T34,"")&IF(T35<>0,","&T35,"")&IF(T36<>0,","&T36,"") -> 125
A40: =C40&"|"&F40&"|"&I40&"|"&L40&"|"&O40&"|"&R40&"|"&U40 -> 0;7000012;500|20;7000012,7000013;500,500|40;7000013,7000014;250,250|60;7000014,7000015;250,250|80;7000015,7000016;125,125|100;7000017;125| | C40: =C38&";"&D39&";"&E39 -> 0;7000012;500 | F40: =F38&";"&G39&";"&H39 -> 20;7000012,7000013;500,500 | I40: =I38&";"&J39&";"&K39 -> 40;7000013,7000014;250,250 | L40: =L38&";"&M39&";"&N39 -> 60;7000014,7000015;250,250 | O40: =O38&";"&P39&";"&Q39 -> 80;7000015,7000016;125,125 | R40: =R38&";"&S39&";"&T39 -> 100;7000017;125
A43: 水螅 | C43: 水螅 | D43: =VLOOKUP(C43,Sheet3!$E$1:$F$58,2,FALSE) -> 7000018 | E43: 500 | F43: 水螅 | G43: =VLOOKUP(F43,Sheet3!$E$1:$F$58,2,FALSE) -> 7000018 | H43: 500 | I43: 水母 | J43: =VLOOKUP(I43,Sheet3!$E$1:$F$58,2,FALSE) -> 7000019 | K43: 250 | L43: 鱼人 | M43: =VLOOKUP(L43,Sheet3!$E$1:$F$58,2,FALSE) -> 7000020 | N43: 250 | O43: 蛇女 | P43: =VLOOKUP(O43,Sheet3!$E$1:$F$58,2,FALSE) -> 7000021 | Q43: 125 | R43: 飞鲨 | S43: =VLOOKUP(R43,Sheet3!$E$1:$F$58,2,FALSE) -> 7000023 | T43: 125
A44: 水母 | F44: 水母 | G44: =VLOOKUP(F44,Sheet3!$E$1:$F$58,2,FALSE) -> 7000019 | H44: 500 | I44: 鱼人 | J44: =VLOOKUP(I44,Sheet3!$E$1:$F$58,2,FALSE) -> 7000020 | K44: 250 | L44: 蛇女 | M44: =VLOOKUP(L44,Sheet3!$E$1:$F$58,2,FALSE) -> 7000021 | N44: 250 | O44: 水元素 | P44: =VLOOKUP(O44,Sheet3!$E$1:$F$58,2,FALSE) -> 7000022 | Q44: 125
A45: 鱼人
A46: 蛇女
A47: 水元素
A48: 飞鲨
C52: 0 | F52: 20 | I52: 40 | L52: 60 | O52: 80 | R52: 100
D53: =D43&IF(D44<>0,","&D44,"")&IF(D45<>0,","&D45,"")&IF(D46<>0,","&D46,"")&IF(D47<>0,","&D47,"")&IF(D48<>0,","&D48,"")&IF(D49<>0,","&D49,"")&IF(D50<>0,","&D50,"") -> 7000018 | E53: =E43&IF(E44<>0,","&E44,"")&IF(E45<>0,","&E45,"")&IF(E46<>0,","&E46,"")&IF(E47<>0,","&E47,"")&IF(E48<>0,","&E48,"")&IF(E49<>0,","&E49,"")&IF(E50<>0,","&E50,"") -> 500 | G53: =G43&IF(G44<>0,","&G44,"")&IF(G45<>0,","&G45,"")&IF(G46<>0,","&G46,"")&IF(G47<>0,","&G47,"")&IF(G48<>0,","&G48,"")&IF(G49<>0,","&G49,"")&IF(G50<>0,","&G50,"") -> 7000018,7000019 | H53: =H43&IF(H44<>0,","&H44,"")&IF(H45<>0,","&H45,"")&IF(H46<>0,","&H46,"")&IF(H47<>0,","&H47,"")&IF(H48<>0,","&H48,"")&IF(H49<>0,","&H49,"")&IF(H50<>0,","&H50,"") -> 500,500 | J53: =J43&IF(J44<>0,","&J44,"")&IF(J45<>0,","&J45,"")&IF(J46<>0,","&J46,"")&IF(J47<>0,","&J47,"")&IF(J48<>0,","&J48,"")&IF(J49<>0,","&J49,"")&IF(J50<>0,","&J50,"") -> 7000019,7000020 | K53: =K43&IF(K44<>0,","&K44,"")&IF(K45<>0,","&K45,"")&IF(K46<>0,","&K46,"")&IF(K47<>0,","&K47,"")&IF(K48<>0,","&K48,"")&IF(K49<>0,","&K49,"")&IF(K50<>0,","&K50,"") -> 250,250 | M53: =M43&IF(M44<>0,","&M44,"")&IF(M45<>0,","&M45,"")&IF(M46<>0,","&M46,"")&IF(M47<>0,","&M47,"")&IF(M48<>0,","&M48,"")&IF(M49<>0,","&M49,"")&IF(M50<>0,","&M50,"") -> 7000020,7000021 | N53: =N43&IF(N44<>0,","&N44,"")&IF(N45<>0,","&N45,"")&IF(N46<>0,","&N46,"")&IF(N47<>0,","&N47,"")&IF(N48<>0,","&N48,"")&IF(N49<>0,","&N49,"")&IF(N50<>0,","&N50,"") -> 250,250 | P53: =P43&IF(P44<>0,","&P44,"")&IF(P45<>0,","&P45,"")&IF(P46<>0,","&P46,"")&IF(P47<>0,","&P47,"")&IF(P48<>0,","&P48,"")&IF(P49<>0,","&P49,"")&IF(P50<>0,","&P50,"") -> 7000021,7000022 | Q53: =Q43&IF(Q44<>0,","&Q44,"")&IF(Q45<>0,","&Q45,"")&IF(Q46<>0,","&Q46,"")&IF(Q47<>0,","&Q47,"")&IF(Q48<>0,","&Q48,"")&IF(Q49<>0,","&Q49,"")&IF(Q50<>0,","&Q50,"") -> 125,125 | S53: =S43&IF(S44<>0,","&S44,"")&IF(S45<>0,","&S45,"")&IF(S46<>0,","&S46,"")&IF(S47<>0,","&S47,"")&IF(S48<>0,","&S48,"")&IF(S49<>0,","&S49,"")&IF(S50<>0,","&S50,"") -> 7000023 | T53: =T43&IF(T44<>0,","&T44,"")&IF(T45<>0,","&T45,"")&IF(T46<>0,","&T46,"")&IF(T47<>0,","&T47,"")&IF(T48<>0,","&T48,"")&IF(T49<>0,","&T49,"")&IF(T50<>0,","&T50,"") -> 125
A54: =C54&"|"&F54&"|"&I54&"|"&L54&"|"&O54&"|"&R54&"|"&U54 -> 0;7000018;500|20;7000018,7000019;500,500|40;7000019,7000020;250,250|60;7000020,7000021;250,250|80;7000021,7000022;125,125|100;7000023;125| | C54: =C52&";"&D53&";"&E53 -> 0;7000018;500 | F54: =F52&";"&G53&";"&H53 -> 20;7000018,7000019;500,500 | I54: =I52&";"&J53&";"&K53 -> 40;7000019,7000020;250,250 | L54: =L52&";"&M53&";"&N53 -> 60;7000020,7000021;250,250 | O54: =O52&";"&P53&";"&Q53 -> 80;7000021,7000022;125,125 | R54: =R52&";"&S53&";"&T53 -> 100;7000023;125
A57: 老鼠 | C57: 老鼠 | D57: =VLOOKUP(C57,Sheet3!$E$1:$F$58,2,FALSE) -> 7000024 | E57: 500 | F57: 老鼠 | G57: =VLOOKUP(F57,Sheet3!$E$1:$F$58,2,FALSE) -> 7000024 | H57: 500 | I57: 盗贼 | J57: =VLOOKUP(I57,Sheet3!$E$1:$F$58,2,FALSE) -> 7000025 | K57: 250 | L57: 牛头人 | M57: =VLOOKUP(L57,Sheet3!$E$1:$F$58,2,FALSE) -> 7000026 | N57: 250 | O57: 毒蝎 | P57: =VLOOKUP(O57,Sheet3!$E$1:$F$58,2,FALSE) -> 7000027 | Q57: 125 | R57: 迦楼罗 | S57: =VLOOKUP(R57,Sheet3!$E$1:$F$58,2,FALSE) -> 7000029 | T57: 125
A58: 盗贼 | F58: 盗贼 | G58: =VLOOKUP(F58,Sheet3!$E$1:$F$58,2,FALSE) -> 7000025 | H58: 500 | I58: 牛头人 | J58: =VLOOKUP(I58,Sheet3!$E$1:$F$58,2,FALSE) -> 7000026 | K58: 250 | L58: 毒蝎 | M58: =VLOOKUP(L58,Sheet3!$E$1:$F$58,2,FALSE) -> 7000027 | N58: 250 | O58: 狂战 | P58: =VLOOKUP(O58,Sheet3!$E$1:$F$58,2,FALSE) -> 7000028 | Q58: 125
A59: 牛头人
A60: 毒蝎
...

Sheet Sheet5
A1: 史莱姆 | B1: 春之山脉 | C1: 1 | D1: 粘液球 | F1: 5000 | H1: 1 | J1: 1116 | L1: 1116000 | N1: =L1&",1,"&F1 -> 1116000,1,5000 | O1: =IF(M1<>0,M1&",1,"&G1,"") | Q1: =N1&";"&O1 -> 1116000,1,5000;
A2: 进化史莱姆 | B2: 春之山脉 | C2: 2 | D2: 粘液球 | E2: 阿莫尔之水 | F2: 3000 | G2: 2000 | H2: 1 | I2: 1 | J2: 1116 | K2: 1152 | L2: 1116000 | M2: 1152000 | N2: =L2&",1,"&F2 -> 1116000,1,3000 | O2: =IF(M2<>0,M2&",1,"&G2,"") -> 1152000,1,2000 | Q2: =N2&";"&O2 -> 1116000,1,3000;1152000,1,2000
A3: 蝙蝠 | B3: 春之山脉 | C3: 3 | D3: 恶魔之翼 | F3: 5000 | H3: 1 | J3: 1117 | L3: 1117000 | N3: =L3&",1,"&F3 -> 1117000,1,5000 | O3: =IF(M3<>0,M3&",1,"&G3,"") | Q3: =N3&";"&O3 -> 1117000,1,5000;
A4: 狼蝠 | B4: 春之山脉 | C4: 4 | D4: 恶魔之翼 | E4: 狼牙 | F4: 3000 | G4: 2000 | H4: 1 | I4: 1 | J4: 1117 | K4: 1129 | L4: 1117000 | M4: 1129000 | N4: =L4&",1,"&F4 -> 1117000,1,3000 | O4: =IF(M4<>0,M4&",1,"&G4,"") -> 1129000,1,2000 | Q4: =N4&";"&O4 -> 1117000,1,3000;1129000,1,2000
A5: 蛮兽 | B5: 春之山脉 | C5: 5 | D5: 兽角 | F5: 5000 | H5: 1 | J5: 1118 | L5: 1118000 | N5: =L5&",1,"&F5 -> 1118000,1,5000 | O5: =IF(M5<>0,M5&",1,"&G5,"") | Q5: =N5&";"&O5 -> 1118000,1,5000;
A6: 雷霆蛮兽 | B6: 春之山脉 | C6: 6 | D6: 兽角 | E6: 兽皮 | F6: 3000 | G6: 2000 | H6: 1 | I6: 1 | J6: 1118 | K6: 1153 | L6: 1118000 | M6: 1153000 | N6: =L6&",1,"&F6 -> 1118000,1,3000 | O6: =IF(M6<>0,M6&",1,"&G6,"") -> 1153000,1,2000 | Q6: =N6&";"&O6 -> 1118000,1,3000;1153000,1,2000
A7: 风精灵 | B7: 春之山脉 | C7: 7 | D7: 风元素结晶 | F7: 5000 | H7: 1 | J7: 1119 | L7: 1119000 | N7: =L7&",1,"&F7 -> 1119000,1,5000 | O7: =IF(M7<>0,M7&",1,"&G7,"") | Q7: =N7&";"&O7 -> 1119000,1,5000;
A8: 利刃蜘蛛 | B8: 瀑布洞穴 | C8: 2 | D8: 蛛毒粉 | E8: 蛛丝 | F8: 3000 | G8: 2000 | H8: 1 | I8: 1 | J8: 1120 | K8: 1121 | L8: 1120000 | M8: 1121000 | N8: =L8&",1,"&F8 -> 1120000,1,3000 | O8: =IF(M8<>0,M8&",1,"&G8,"") -> 1121000,1,2000 | Q8: =N8&";"&O8 -> 1120000,1,3000;1121000,1,2000
A9: 鬼脸蜘蛛 | B9: 瀑布洞穴 | C9: 1 | D9: 蛛丝 | F9: 5000 | H9: 1 | J9: 1121 | L9: 1121000 | N9: =L9&",1,"&F9 -> 1121000,1,5000 | O9: =IF(M9<>0,M9&",1,"&G9,"") | Q9: =N9&";"&O9 -> 1121000,1,5000;
A10: 邪眼 | B10: 瀑布洞穴 | C10: 3 | D10: 眼球 | F10: 5000 | H10: 1 | J10: 1122 | L10: 1122000 | N10: =L10&",1,"&F10 -> 1122000,1,5000 | O10: =IF(M10<>0,M10&",1,"&G10,"") | Q10: =N10&";"&O10 -> 1122000,1,5000;
A11: 浮空斜眼 | B11: 瀑布洞穴 | C11: 4 | D11: 眼球 | F11: 5000 | H11: 1 | J11: 1122 | L11: 1122000 | N11: =L11&",1,"&F11 -> 1122000,1,5000 | O11: =IF(M11<>0,M11&",1,"&G11,"") | Q11: =N11&";"&O11 -> 1122000,1,5000;
A12: 巨魔 | B12: 瀑布洞穴 | C12: 6 | D12: 香菇 | E12: 木棒 | F12: 3000 | G12: 2000 | H12: 1 | I12: 1 | J12: 1090 | K12: 1154 | L12: 1090000 | M12: 1154000 | N12: =L12&",1,"&F12 -> 1090000,1,3000 | O12: =IF(M12<>0,M12&",1,"&G12,"") -> 1154000,1,2000 | Q12: =N12&";"&O12 -> 1090000,1,3000;1154000,1,2000
A13: 哥布林战士 | B13: 瀑布洞穴 | C13: 5 | D13: 布片 | F13: 5000 | H13: 1 | J13: 1123 | L13: 1123000 | N13: =L13&",1,"&F13 -> 1123000,1,5000 | O13: =IF(M13<>0,M13&",1,"&G13,"") | Q13: =N13&";"&O13 -> 1123000,1,5000;
A14: 守护者 | B14: 瀑布洞穴 | C14: 7 | D14: 废铁 | E14: 钢 | F14: 3000 | G14: 2000 | H14: 1 | I14: 1 | J14: 1109 | K14: 1155 | L14: 1109000 | M14: 1155000 | N14: =L14&",1,"&F14 -> 1109000,1,3000 | O14: =IF(M14<>0,M14&",1,"&G14,"") -> 1155000,1,2000 | Q14: =N14&";"&O14 -> 1109000,1,3000;1155000,1,2000
A15: 彩虹鸟 | B15: 夏之丛林 | C15: 3 | D15: 彩色羽毛 | F15: 5000 | H15: 1 | J15: 1124 | L15: 1124000 | N15: =L15&",1,"&F15 -> 1124000,1,5000 | O15: =IF(M15<>0,M15&",1,"&G15,"") | Q15: =N15&";"&O15 -> 1124000,1,5000;
A16: 青龙 | B16: 夏之丛林 | C16: 7 | D16: 龙鳞 | F16: 5000 | H16: 1 | J16: 1125 | L16: 1125000 | N16: =L16&",1,"&F16 -> 1125000,1,5000 | O16: =IF(M16<>0,M16&",1,"&G16,"") | Q16: =N16&";"&O16 -> 1125000,1,5000;
A17: 毒蜂 | B17: 夏之丛林 | C17: 1 | D17: 蜂刺 | E17: 蜂蜜 | F17: 3000 | G17: 2000 | H17: 1 | I17: 1 | J17: 1126 | K17: 1156 | L17: 1126000 | M17: 1156000 | N17: =L17&",1,"&F17 -> 1126000,1,3000 | O17: =IF(M17<>0,M17&",1,"&G17,"") -> 1156000,1,2000 | Q17: =N17&";"&O17 -> 1126000,1,3000;1156000,1,2000
A18: 食人花 | B18: 夏之丛林 | C18: 2 | D18: 番茄 | E18: 植物的茎 | F18: 3000 | G18: 2000 | H18: 1 | I18: 1 | J18: 1005 | K18: 1157 | L18: 1005000 | M18: 1157000 | N18: =L18&",1,"&F18 -> 1005000,1,3000 | O18: =IF(M18<>0,M18&",1,"&G18,"") -> 1157000,1,2000 | Q18: =N18&";"&O18 -> 1005000,1,3000;1157000,1,2000
A19: 速龙 | B19: 夏之丛林 | C19: 4 | D19: 亚龙之血 | F19: 5000 | H19: 1 | J19: 1127 | L19: 1127000 | N19: =L19&",1,"&F19 -> 1127000,1,5000 | O19: =IF(M19<>0,M19&",1,"&G19,"") | Q19: =N19&";"&O19 -> 1127000,1,5000;
A20: 巨蟒 | B20: 夏之丛林 | C20: 5 | D20: 蛇皮 | F20: 5000 | H20: 1 | J20: 1128 | L20: 1128000 | N20: =L20&",1,"&F20 -> 1128000,1,5000 | O20: =IF(M20<>0,M20&",1,"&G20,"") | Q20: =N20&";"&O20 -> 1128000,1,5000;
A21: 魔狼 | B21: 夏之丛林 | C21: 6 | D21: 狼牙 | E21: 魔兽皮毛 | F21: 3000 | G21: 2000 | H21: 1 | I21: 1 | J21: 1129 | K21: 1158 | L21: 1129000 | M21: 1158000 | N21: =L21&",1,"&F21 -> 1129000,1,3000 | O21: =IF(M21<>0,M21&",1,"&G21,"") -> 1158000,1,2000 | Q21: =N21&";"&O21 -> 1129000,1,3000;1158000,1,2000
A22: 蓝龙 | B22: 和风海岸 | C22: 7 | D22: 龙鳞 | E22: 蓝水晶球 | F22: 3000 | G22: 2000 | H22: 1 | I22: 1 | J22: 1125 | K22: 1159 | L22: 1125000 | M22: 1159000 | N22: =L22&",1,"&F22 -> 1125000,1,3000 | O22: =IF(M22<>0,M22&",1,"&G22,"") -> 1159000,1,2000 | Q22: =N22&";"&O22 -> 1125000,1,3000;1159000,1,2000
A23: 水元素 | B23: 和风海岸 | C23: 5 | D23: 水元素结晶 | F23: 5000 | H23: 1 | J23: 1130 | L23: 1130000 | N23: =L23&",1,"&F23 -> 1130000,1,5000 | O23: =IF(M23<>0,M23&",1,"&G23,"") | Q23: =N23&";"&O23 -> 1130000,1,5000;
A24: 水螅 | B24: 和风海岸 | C24: 2 | D24: 纯净之水 | E24: 珊瑚 | F24: 3000 | G24: 2000 | H24: 1 | I24: 1 | J24: 1131 | K24: 1103 | L24: 1131000 | M24: 1103000 | N24: =L24&",1,"&F24 -> 1131000,1,3000 | O24: =IF(M24<>0,M24&",1,"&G24,"") -> 1103000,1,2000 | Q24: =N24&";"&O24 -> 1131000,1,3000;1103000,1,2000
A25: 水母 | B25: 和风海岸 | C25: 1 | D25: 纯净之水 | F25: 5000 | H25: 1 | J25: 1131 | L25: 1131000 | N25: =L25&",1,"&F25 -> 1131000,1,5000 | O25: =IF(M25<>0,M25&",1,"&G25,"") | Q25: =N25&";"&O25 -> 1131000,1,5000;
A26: 蛇女 | B26: 和风海岸 | C26: 6 | D26: 蛇皮 | E26: 石化之眼 | F26: 3000 | G26: 2000 | H26: 1 | I26: 1 | J26: 1128 | K26: 1160 | L26: 1128000 | M26: 1160000 | N26: =L26&",1,"&F26 -> 1128000,1,3000 | O26: =IF(M26<>0,M26&",1,"&G26,"") -> 1160000,1,2000 | Q26: =N26&";"&O26 -> 1128000,1,3000;1160000,1,2000
A27: 鱼人 | B27: 和风海岸 | C27: 3 | D27: 鱼胶 | E27: 鱼饵 | F27: 2000 | G27: 3000 | H27: 1 | I27: 1 | J27: 1132 | K27: 1161 | L27: 1132000 | M27: 1161000 | N27: =L27&",1,"&F27 -> 1132000,1,2000 | O27: =IF(M27<>0,M27&",1,"&G27,"") -> 1161000,1,3000 | Q27: =N27&";"&O27 -> 1132000,1,2000;1161000,1,3000
A28: 飞鲨 | B28: 和风海岸 | C28: 4 | D28: 珊瑚 | F28: 5000 | H28: 1 | J28: 1103 | L28: 1103000 | N28: =L28&",1,"&F28 -> 1103000,1,5000 | O28: =IF(M28<>0,M28&",1,"&G28,"") | Q28: =N28&";"&O28 -> 1103000,1,5000;
A29: 盗贼 | B29: 秋风之谷 | C29: 2 | D29: 布片 | E29: 银块 | F29: 3000 | G29: 2000 | H29: 1 | I29: 1 | J29: 1123 | K29: 1162 | L29: 1123000 | M29: 1162000 | N29: =L29&",1,"&F29 -> 1123000,1,3000 | O29: =IF(M29<>0,M29&",1,"&G29,"") -> 1162000,1,2000 | Q29: =N29&";"&O29 -> 1123000,1,3000;1162000,1,2000
A30: 狮魔 | B30: 秋风之谷 | C30: 7 | D30: 奇美拉之翼 | E30: 魔兽皮毛 | F30: 2000 | G30: 3000 | H30: 1 | I30: 1 | J30: 1133 | K30: 1158 | L30: 1133000 | M30: 1158000 | N30: =L30&",1,"&F30 -> 1133000,1,2000 | O30: =IF(M30<>0,M30&",1,"&G30,"") -> 1158000,1,3000 | Q30: =N30&";"&O30 -> 1133000,1,2000;1158000,1,3000
A31: 家楼罗 | B31: 秋风之谷 | C31: 6 | D31: 奇美拉之翼 | F31: 4000 | H31: 1 | J31: 1133 | L31: 1133000 | N31: =L31&",1,"&F31 -> 1133000,1,4000 | O31: =IF(M31<>0,M31&",1,"&G31,"") | Q31: =N31&";"&O31 -> 1133000,1,4000;
A32: 牛头人 | B32: 秋风之谷 | C32: 5 | D32: 牛角 | E32: 魔兽皮毛 | F32: 2000 | G32: 3000 | H32: 1 | I32: 1 | J32: 1134 | K32: 1158 | L32: 1134000 | M32: 1158000 | N32: =L32&",1,"&F32 -> 1134000,1,2000 | O32: =IF(M32<>0,M32&",1,"&G32,"") -> 1158000,1,3000 | Q32: =N32&";"&O32 -> 1134000,1,2000;1158000,1,3000
A33: 毒蝎 | B33: 秋风之谷 | C33: 1 | D33: 虫皮 | F33: 4000 | H33: 1 | J33: 1135 | L33: 1135000 | N33: =L33&",1,"&F33 -> 1135000,1,4000 | O33: =IF(M33<>0,M33&",1,"&G33,"") | Q33: =N33&";"&O33 -> 1135000,1,4000;
A34: 杀手 | B34: 秋风之谷 | C34: 3 | D34: 刀刃 | E34: 金块 | F34: 3000 | G34: 2000 | H34: 1 | I34: 1 | J34: 1136 | K34: 1115 | L34: 1136000 | M34: 1115000 | N34: =L34&",1,"&F34 -> 1136000,1,3000 | O34: =IF(M34<>0,M34&",1,"&G34,"") -> 1115000,1,2000 | Q34: =N34&";"&O34 -> 1136000,1,3000;1115000,1,2000
A35: 狂战 | B35: 秋风之谷 | C35: 4 | D35: 废铁 | E35: 钢 | F35: 3000 | G35: 2000 | H35: 1 | I35: 1 | J35: 1109 | K35: 1155 | L35: 1109000 | M35: 1155000 | N35: =L35&",1,"&F35 -> 1109000,1,3000 | O35: =IF(M35<>0,M35&",1,"&G35,"") -> 1155000,1,2000 | Q35: =N35&";"&O35 -> 1109000,1,3000;1155000,1,2000
A36: 空鼠 | B36: 废墟 | C36: 2 | D36: 头巾 | F36: 4000 | H36: 1 | J36: 1137 | L36: 1137000 | N36: =L36&",1,"&F36 -> 1137000,1,4000 | O36: =IF(M36<>0,M36&",1,"&G36,"") | Q36: =N36&";"&O36 -> 1137000,1,4000;
A37: 老鼠 | B37: 废墟 | C37: 1 | D37: 头巾 | E37: 银块 | F37: 3000 | G37: 2000 | H37: 1 | I37: 1 | J37: 1137 | K37: 1162 | L37: 1137000 | M37: 1162000 | N37: =L37&",1,"&F37 -> 1137000,1,3000 | O37: =IF(M37<>0,M37&",1,"&G37,"") -> 1162000,1,2000 | Q37: =N37&";"&O37 -> 1137000,1,3000;1162000,1,2000
A38: 黑衣 | B38: 废墟 | C38: 4 | D38: 布片 | F38: 4000 | H38: 1 | J38: 1123 | L38: 1123000 | N38: =L38&",1,"&F38 -> 1123000,1,4000 | O38: =IF(M38<>0,M38&",1,"&G38,"") | Q38: =N38&";"&O38 -> 1123000,1,4000;
A39: 盔甲 | B39: 废墟 | C39: 5 | D39: 废铁 | F39: 4000 | H39: 1 | J39: 1109 | L39: 1109000 | N39: =L39&",1,"&F39 -> 1109000,1,4000 | O39: =IF(M39<>0,M39&",1,"&G39,"") | Q39: =N39&";"&O39 -> 1109000,1,4000;
A40: 宝箱怪 | B40: 废墟 | C40: 6 | D40: 金块 | F40: 4000 | H40: 1 | J40: 1115 | L40: 1115000 | N40: =L40&",1,"&F40 -> 1115000,1,4000 | O40: =IF(M40<>0,M40&",1,"&G40,"") | Q40: =N40&";"&O40 -> 1115000,1,4000;
...

Sheet Sheet8
J1: 剩余价值 | X1: 废铁 | Y1: 51 | Z1: 纯净之水 | AA1: 60 | AB1: 蛇皮 | AC1: 70 | AD1: 椰子 | AE1: 90 | AG1: 废铁
A2: 长剑 | B2: 废铁 | C2: 刀刃 | F2: =INT(G2-J2/2) -> 64 | G2: =VLOOKUP(K2,装备属性!$A$3:$H$32,6,FALSE) -> 17 | H2: =INT(G2/2) -> 8 | I2: =SUM(Q2:T2) -> 102 | J2: =H2-I2 -> -94 | K2: 长剑 | L2: 1 | M2: 废铁 | N2: 刀刃 | Q2: =IF(M2=0,"",VLOOKUP(M2,$A$34:$B$86,2,FALSE)) -> 51 | R2: =IF(N2=0,"",VLOOKUP(N2,$A$34:$B$86,2,FALSE)) -> 51 | S2: =IF(O2=0,"",VLOOKUP(O2,$A$34:$B$86,2,FALSE)) | T2: =IF(P2=0,"",VLOOKUP(P2,$A$34:$B$86,2,FALSE)) | U2: 哥布林战士 | V2: 进化史莱姆 | X2: 布片 | Y2: 44 | Z2: 木棒 | AA2: 75 | AB2: 蜂刺 | AC2: 70 | AD2: 珊瑚 | AE2: 75 | AG2: 木棒
A3: 铁枪 | B3: 木棒 | C3: 废铁 | D3: 刀刃 | E3: 刀刃 | F3: =INT(G3-J3/2) -> 49 | G3: =VLOOKUP(K3,装备属性!$A$3:$H$32,6,FALSE) -> 0 | H3: =INT(G3/2) -> 0 | I3: =SUM(Q3:T3) -> 99 | J3: =H3-I3 -> -99 | K3: 布衣 | L3: 1 | M3: 布片 | N3: 蛛丝 | Q3: =IF(M3=0,"",VLOOKUP(M3,$A$34:$B$86,2,FALSE)) -> 44 | R3: =IF(N3=0,"",VLOOKUP(N3,$A$34:$B$86,2,FALSE)) -> 55 | S3: =IF(O3=0,"",VLOOKUP(O3,$A$34:$B$86,2,FALSE)) | T3: =IF(P3=0,"",VLOOKUP(P3,$A$34:$B$86,2,FALSE)) | U3: 史莱姆 | V3: 巨魔 | X3: 竹笋 | Y3: 44 | Z3: 蛛丝 | AA3: 55 | AB3: 蜂蜜 | AC3: 72 | AD3: 石化之眼 | AE3: 82 | AG3: 布片
A4: 蛇皮鞭 | B4: 蛇皮 | C4: 马尾 | F4: =INT(G4-J4/2) -> 60 | G4: =VLOOKUP(K4,装备属性!$A$3:$H$32,6,FALSE) -> 0 | H4: =INT(G4/2) -> 0 | I4: =SUM(Q4:T4) -> 120 | J4: =H4-I4 -> -120 | K4: 皮铠 | L4: 1 | M4: 兽皮 | N4: 蛛丝 | Q4: =IF(M4=0,"",VLOOKUP(M4,$A$34:$B$86,2,FALSE)) -> 65 | R4: =IF(N4=0,"",VLOOKUP(N4,$A$34:$B$86,2,FALSE)) -> 55 | S4: =IF(O4=0,"",VLOOKUP(O4,$A$34:$B$86,2,FALSE)) | T4: =IF(P4=0,"",VLOOKUP(P4,$A$34:$B$86,2,FALSE)) | U4: 利刃蜘蛛 | V4: 蝙蝠 | X4: 刀刃 | Y4: 51 | Z4: 魔兽皮毛 | AA4: 70 | AB4: 眼球 | AC4: 65 | AD4: 鱼胶 | AE4: 90 | AG4: 兽皮
A5: 龙尾鞭 | B5: 蛇皮鞭 | C5: 龙鳞 | D5: 蜂刺 | F5: =INT(G5-J5/2) -> 105 | G5: =VLOOKUP(K5,装备属性!$A$3:$H$32,6,FALSE) -> 22 | H5: =INT(G5/2) -> 11 | I5: =SUM(Q5:T5) -> 177 | J5: =H5-I5 -> -166 | K5: 铁枪 | L5: 2 | M5: 木棒 | N5: 废铁 | O5: 刀刃 | Q5: =IF(M5=0,"",VLOOKUP(M5,$A$34:$B$86,2,FALSE)) -> 75 | R5: =IF(N5=0,"",VLOOKUP(N5,$A$34:$B$86,2,FALSE)) -> 51 | S5: =IF(O5=0,"",VLOOKUP(O5,$A$34:$B$86,2,FALSE)) -> 51 | T5: =IF(P5=0,"",VLOOKUP(P5,$A$34:$B$86,2,FALSE)) | U5: 蛮兽 | V5: 邪眼 | X5: 风元素结晶 | Y5: 60 | Z5: 兽皮 | AA5: 65 | AB5: 彩色羽毛 | AC5: 82 | AD5: 水元素结晶 | AE5: 110 | AG5: 刀刃
A6: 诅咒之剑 | B6: 长剑 | C6: 眼球 | D6: 石化之眼 | F6: =INT(G6-J6/2) -> 70 | G6: =VLOOKUP(K6,装备属性!$A$3:$H$32,6,FALSE) -> 0 | H6: =INT(G6/2) -> 0 | I6: =SUM(Q6:T6) -> 140 | J6: =H6-I6 -> -140 | K6: 毛皮斗篷 | L6: 2 | M6: 魔兽皮毛 | N6: 羊毛 | Q6: =IF(M6=0,"",VLOOKUP(M6,$A$34:$B$86,2,FALSE)) -> 70 | R6: =IF(N6=0,"",VLOOKUP(N6,$A$34:$B$86,2,FALSE)) -> 70 | S6: =IF(O6=0,"",VLOOKUP(O6,$A$34:$B$86,2,FALSE)) | T6: =IF(P6=0,"",VLOOKUP(P6,$A$34:$B$86,2,FALSE)) | U6: 雷霆蛮兽 | V6: 魔狼 | AG6: 水晶球
A7: 战斧 | B7: 钢 | C7: 钢 | D7: 刀刃 | F7: =INT(G7-J7/2) -> 69 | G7: =VLOOKUP(K7,装备属性!$A$3:$H$32,6,FALSE) -> 0 | H7: =INT(G7/2) -> 0 | I7: =SUM(Q7:T7) -> 138 | J7: =H7-I7 -> -138 | K7: 铁铠甲 | L7: 2 | M7: 皮铠 | N7: 废铁 | Q7: =IF(M7=0,"",VLOOKUP(M7,$A$34:$B$86,2,FALSE)) -> 87 | R7: =IF(N7=0,"",VLOOKUP(N7,$A$34:$B$86,2,FALSE)) -> 51 | S7: =IF(O7=0,"",VLOOKUP(O7,$A$34:$B$86,2,FALSE)) | T7: =IF(P7=0,"",VLOOKUP(P7,$A$34:$B$86,2,FALSE)) | U7: 风精灵 | V7: 守护者 | AG7: 蛛丝
A8: 三叉戟 | B8: 铁枪 | C8: 兽角 | D8: 兽角 | F8: =INT(G8-J8/2) -> 124 | G8: =VLOOKUP(K8,装备属性!$A$3:$H$32,6,FALSE) -> 29 | H8: =INT(G8/2) -> 14 | I8: =SUM(Q8:T8) -> 205 | J8: =H8-I8 -> -191 | K8: 蛇皮鞭 | L8: 3 | M8: 蛇皮 | N8: 马尾 | O8: 蛛丝 | Q8: =IF(M8=0,"",VLOOKUP(M8,$A$34:$B$86,2,FALSE)) -> 70 | R8: =IF(N8=0,"",VLOOKUP(N8,$A$34:$B$86,2,FALSE)) -> 80 | S8: =IF(O8=0,"",VLOOKUP(O8,$A$34:$B$86,2,FALSE)) -> 55 | T8: =IF(P8=0,"",VLOOKUP(P8,$A$34:$B$86,2,FALSE)) | AG8: 土元素结晶
A9: 毒蜥之牙 | B9: 战斧 | C9: 狼牙 | F9: =INT(G9-J9/2) -> 144 | G9: =VLOOKUP(K9,装备属性!$A$3:$H$32,6,FALSE) -> 32 | H9: =INT(G9/2) -> 16 | I9: =SUM(Q9:T9) -> 240 | J9: =H9-I9 -> -224 | K9: 蛇牙鞭 | L9: 3 | M9: 蛇皮 | N9: 狼牙 | O9: 蜂刺 | Q9: =IF(M9=0,"",VLOOKUP(M9,$A$34:$B$86,2,FALSE)) -> 70 | R9: =IF(N9=0,"",VLOOKUP(N9,$A$34:$B$86,2,FALSE)) -> 100 | S9: =IF(O9=0,"",VLOOKUP(O9,$A$34:$B$86,2,FALSE)) -> 70 | T9: =IF(P9=0,"",VLOOKUP(P9,$A$34:$B$86,2,FALSE)) | U9: 毒蜂 | V9: 水元素 | X9: 阿莫尔之水 | Y9: 110 | Z9: 钢 | AA9: 130 | AB9: 雪球 | AC9: 170 | AD9: 冰晶 | AE9: 200 | AG9: 龙鳞
A10: 大地之剑 | B10: 长剑 | C10: 土元素结晶 | F10: =INT(G10-J10/2) -> 151 | G10: =VLOOKUP(K10,装备属性!$A$3:$H$32,6,FALSE) -> 36 | H10: =INT(G10/2) -> 18 | I10: =SUM(Q10:T10) -> 249 | J10: =H10-I10 -> -231 | K10: 诅咒之剑 | L10: 3 | M10: 长剑 | N10: 眼球 | O10: 石化之眼 | Q10: =IF(M10=0,"",VLOOKUP(M10,$A$34:$B$86,2,FALSE)) -> 102 | R10: =IF(N10=0,"",VLOOKUP(N10,$A$34:$B$86,2,FALSE)) -> 65 | S10: =IF(O10=0,"",VLOOKUP(O10,$A$34:$B$86,2,FALSE)) -> 82 | T10: =IF(P10=0,"",VLOOKUP(P10,$A$34:$B$86,2,FALSE)) | U10: 巨蟒 | V10: 水螅 | X10: 蝎尾 | Y10: 100 | Z10: 植物的茎 | AA10: 130 | AB10: 水晶球 | AC10: 170 | AD10: 魔族之血 | AE10: 200 | AG10: 兽角
A11: 骑士长枪 | B11: 铁枪 | C11: 铁枪 | D11: 兽角 | F11: =INT(G11-J11/2) -> 98 | G11: =VLOOKUP(K11,装备属性!$A$3:$H$32,6,FALSE) -> 0 | H11: =INT(G11/2) -> 0 | I11: =SUM(Q11:T11) -> 196 | J11: =H11-I11 -> -196 | K11: 华丽背心 | L11: 3 | M11: 布衣 | N11: 彩色羽毛 | Q11: =IF(M11=0,"",VLOOKUP(M11,$A$34:$B$86,2,FALSE)) -> 114 | R11: =IF(N11=0,"",VLOOKUP(N11,$A$34:$B$86,2,FALSE)) -> 82 | S11: =IF(O11=0,"",VLOOKUP(O11,$A$34:$B$86,2,FALSE)) | T11: =IF(P11=0,"",VLOOKUP(P11,$A$34:$B$86,2,FALSE)) | U11: 速龙 | V11: 水母 | X11: 银块 | Y11: 110 | Z11: 苹果 | AA11: 120 | AB11: 金块 | AC11: 170 | AD11: 暗元素结晶 | AE11: 210 | AG11: 奇美拉之翼
A12: 藤鞭 | B12: 植物的茎 | C12: 马尾 | F12: =INT(G12-J12/2) -> 102 | G12: =VLOOKUP(K12,装备属性!$A$3:$H$32,6,FALSE) -> 0 | H12: =INT(G12/2) -> 0 | I12: =SUM(Q12:T12) -> 204 | J12: =H12-I12 -> -204 | K12: 鳞铠 | L12: 4 | M12: 蛇皮 | N12: 鱼胶 | O12: 布片 | Q12: =IF(M12=0,"",VLOOKUP(M12,$A$34:$B$86,2,FALSE)) -> 70 | R12: =IF(N12=0,"",VLOOKUP(N12,$A$34:$B$86,2,FALSE)) -> 90 | S12: =IF(O12=0,"",VLOOKUP(O12,$A$34:$B$86,2,FALSE)) -> 44 | T12: =IF(P12=0,"",VLOOKUP(P12,$A$34:$B$86,2,FALSE)) | U12: 浮空 | V12: 蛇女 | X12: 兽角 | Y12: 120 | Z12: 樱桃 | AA12: 120 | AB12: 幽魂 | AC12: 200 | AD12: 亡者之土 | AE12: 232 | AG12: 银块
A13: 女王鞭 | B13: 藤鞭 | C13: 刀刃 | F13: =INT(G13-J13/2) -> 153 | G13: =VLOOKUP(K13,装备属性!$A$3:$H$32,6,FALSE) -> 36 | H13: =INT(G13/2) -> 18 | I13: =SUM(Q13:T13) -> 252 | J13: =H13-I13 -> -234 | K13: 三叉戟 | L13: 4 | M13: 铁枪 | N13: 珊瑚 | Q13: =IF(M13=0,"",VLOOKUP(M13,$A$34:$B$86,2,FALSE)) -> 177 | R13: =IF(N13=0,"",VLOOKUP(N13,$A$34:$B$86,2,FALSE)) -> 75 | S13: =IF(O13=0,"",VLOOKUP(O13,$A$34:$B$86,2,FALSE)) | T13: =IF(P13=0,"",VLOOKUP(P13,$A$34:$B$86,2,FALSE)) | U13: 彩虹鸟 | V13: 鱼人 | X13: 奇美拉之翼 | Y13: 134 | Z13: 土元素结晶 | AA13: 160 | AG13: 风元素结晶
A14: 暴雪斧 | B14: 战斧 | C14: 雪球 | F14: =INT(G14-J14/2) -> 106 | G14: =VLOOKUP(K14,装备属性!$A$3:$H$32,6,FALSE) -> 0 | H14: =INT(G14/2) -> 0 | I14: =SUM(Q14:T14) -> 213 | J14: =H14-I14 -> -213 | K14: 锁子甲 | L14: 4 | M14: 皮铠 | N14: 珊瑚 | O14: 废铁 | Q14: =IF(M14=0,"",VLOOKUP(M14,$A$34:$B$86,2,FALSE)) -> 87 | R14: =IF(N14=0,"",VLOOKUP(N14,$A$34:$B$86,2,FALSE)) -> 75 | S14: =IF(O14=0,"",VLOOKUP(O14,$A$34:$B$86,2,FALSE)) -> 51 | T14: =IF(P14=0,"",VLOOKUP(P14,$A$34:$B$86,2,FALSE)) | U14: 蓝龙 | V14: 飞鲨 | AG14: 魔兽皮毛
A15: 冰之刃 | B15: 长剑 | C15: 冰晶 | D15: 冰晶 | E15: 雪球 | F15: =INT(G15-J15/2) -> 139 | G15: =VLOOKUP(K15,装备属性!$A$3:$H$32,6,FALSE) -> 0 | H15: =INT(G15/2) -> 0 | I15: =SUM(Q15:T15) -> 279 | J15: =H15-I15 -> -279 | K15: 水之羽衣 | L15: 4 | M15: 布衣 | N15: 水元素结晶 | P15: 蛛丝 | Q15: =IF(M15=0,"",VLOOKUP(M15,$A$34:$B$86,2,FALSE)) -> 114 | R15: =IF(N15=0,"",VLOOKUP(N15,$A$34:$B$86,2,FALSE)) -> 110 | S15: =IF(O15=0,"",VLOOKUP(O15,$A$34:$B$86,2,FALSE)) | T15: =IF(P15=0,"",VLOOKUP(P15,$A$34:$B$86,2,FALSE)) -> 55 | AG15: 植物的茎
A16: 恶魔之斧 | B16: 战斧 | C16: 魔族之血 | D16: 暗元素结晶 | F16: =INT(G16-J16/2) -> 154 | G16: =VLOOKUP(K16,装备属性!$A$3:$H$32,6,FALSE) -> 0 | H16: =INT(G16/2) -> 0 | I16: =SUM(Q16:T16) -> 308 | J16: =H16-I16 -> -308 | K16: 疾风背心 | L16: 5 | M16: 布衣 | N16: 风元素结晶 | O16: 奇美拉之翼 | Q16: =IF(M16=0,"",VLOOKUP(M16,$A$34:$B$86,2,FALSE)) -> 114 | R16: =IF(N16=0,"",VLOOKUP(N16,$A$34:$B$86,2,FALSE)) -> 60 | S16: =IF(O16=0,"",VLOOKUP(O16,$A$34:$B$86,2,FALSE)) -> 134 | T16: =IF(P16=0,"",VLOOKUP(P16,$A$34:$B$86,2,FALSE)) | U16: 老鼠 | V16: 空鼠 | AG16: 暗元素结晶
F17: =INT(G17-J17/2) -> 206 | G17: =VLOOKUP(K17,装备属性!$A$3:$H$32,6,FALSE) -> 43 | H17: =INT(G17/2) -> 21 | I17: =SUM(Q17:T17) -> 348 | J17: =H17-I17 -> -327 | K17: 骑士长枪 | L17: 5 | M17: 铁枪 | N17: 兽角 | O17: 刀刃 | Q17: =IF(M17=0,"",VLOOKUP(M17,$A$34:$B$86,2,FALSE)) -> 177 | R17: =IF(N17=0,"",VLOOKUP(N17,$A$34:$B$86,2,FALSE)) -> 120 | S17: =IF(O17=0,"",VLOOKUP(O17,$A$34:$B$86,2,FALSE)) -> 51 | T17: =IF(P17=0,"",VLOOKUP(P17,$A$34:$B$86,2,FALSE)) | U17: 盗贼 | V17: 食人花 | AG17: 钢
A18: 布衣 | B18: 布片 | C18: 蛛丝 | F18: =INT(G18-J18/2) -> 132 | G18: =VLOOKUP(K18,装备属性!$A$3:$H$32,6,FALSE) -> 0 | H18: =INT(G18/2) -> 0 | I18: =SUM(Q18:T18) -> 264 | J18: =H18-I18 -> -264 | K18: 丝织长袍 | L18: 5 | M18: 布片 | N18: 蛛丝 | O18: 蛛丝 | P18: 银块 | Q18: =IF(M18=0,"",VLOOKUP(M18,$A$34:$B$86,2,FALSE)) -> 44 | R18: =IF(N18=0,"",VLOOKUP(N18,$A$34:$B$86,2,FALSE)) -> 55 | S18: =IF(O18=0,"",VLOOKUP(O18,$A$34:$B$86,2,FALSE)) -> 55 | T18: =IF(P18=0,"",VLOOKUP(P18,$A$34:$B$86,2,FALSE)) -> 110 | U18: 牛头人 | V18: 宝箱怪 | AG18: 蛇皮
A19: 皮铠 | B19: 兽皮 | C19: 蛛丝 | F19: =INT(G19-J19/2) -> 119 | G19: =VLOOKUP(K19,装备属性!$A$3:$H$32,6,FALSE) -> 0 | H19: =INT(G19/2) -> 0 | I19: =SUM(Q19:T19) -> 238 | J19: =H19-I19 -> -238 | K19: 红莲之铠 | L19: 5 | M19: 铁铠甲 | N19: 蝎尾 | Q19: =IF(M19=0,"",VLOOKUP(M19,$A$34:$B$86,2,FALSE)) -> 138 | R19: =IF(N19=0,"",VLOOKUP(N19,$A$34:$B$86,2,FALSE)) -> 100 | S19: =IF(O19=0,"",VLOOKUP(O19,$A$34:$B$86,2,FALSE)) | T19: =IF(P19=0,"",VLOOKUP(P19,$A$34:$B$86,2,FALSE)) | U19: 毒蝎 | V19: 傀儡 | AG19: 眼球
A20: 锁子甲 | B20: 皮铠 | C20: 珊瑚 | D20: 废铁 | F20: =INT(G20-J20/2) -> 193 | G20: =VLOOKUP(K20,装备属性!$A$3:$H$32,6,FALSE) -> 50 | H20: =INT(G20/2) -> 25 | I20: =SUM(Q20:T20) -> 311 | J20: =H20-I20 -> -286 | K20: 战斧 | L20: 6 | M20: 钢 | N20: 钢 | O20: 刀刃 | Q20: =IF(M20=0,"",VLOOKUP(M20,$A$34:$B$86,2,FALSE)) -> 130 | R20: =IF(N20=0,"",VLOOKUP(N20,$A$34:$B$86,2,FALSE)) -> 130 | S20: =IF(O20=0,"",VLOOKUP(O20,$A$34:$B$86,2,FALSE)) -> 51 | T20: =IF(P20=0,"",VLOOKUP(P20,$A$34:$B$86,2,FALSE)) | U20: 狂战 | V20: 盔甲 | AG20: 彩色羽毛
A21: 毛皮斗篷 | B21: 魔兽皮毛 | C21: 羊毛 | F21: =INT(G21-J21/2) -> 220 | G21: =VLOOKUP(K21,装备属性!$A$3:$H$32,6,FALSE) -> 54 | H21: =INT(G21/2) -> 27 | I21: =SUM(Q21:T21) -> 360 | J21: =H21-I21 -> -333 | K21: 毒蜥之牙 | L21: 6 | M21: 钢 | N21: 钢 | O21: 狼牙 | Q21: =IF(M21=0,"",VLOOKUP(M21,$A$34:$B$86,2,FALSE)) -> 130 | R21: =IF(N21=0,"",VLOOKUP(N21,$A$34:$B$86,2,FALSE)) -> 130 | S21: =IF(O21=0,"",VLOOKUP(O21,$A$34:$B$86,2,FALSE)) -> 100 | T21: =IF(P21=0,"",VLOOKUP(P21,$A$34:$B$86,2,FALSE)) | U21: 家楼罗 | V21: 恶法师 | AG21: 鱼胶
A22: 铁铠甲 | B22: 皮铠 | C22: 废铁 | F22: =INT(G22-J22/2) -> 243 | G22: =VLOOKUP(K22,装备属性!$A$3:$H$32,6,FALSE) -> 63 | H22: =INT(G22/2) -> 31 | I22: =SUM(Q22:T22) -> 392 | J22: =H22-I22 -> -361 | K22: 大地之剑 | L22: 6 | M22: 长剑 | N22: 土元素结晶 | O22: 钢 | Q22: =IF(M22=0,"",VLOOKUP(M22,$A$34:$B$86,2,FALSE)) -> 102 | R22: =IF(N22=0,"",VLOOKUP(N22,$A$34:$B$86,2,FALSE)) -> 160 | S22: =IF(O22=0,"",VLOOKUP(O22,$A$34:$B$86,2,FALSE)) -> 130 | T22: =IF(P22=0,"",VLOOKUP(P22,$A$34:$B$86,2,FALSE)) | X22: 纯净之水 | AG22: 蜂刺
A23: 红莲之铠 | B23: 锁子甲 | C23: 蝎尾 | F23: =INT(G23-J23/2) -> 134 | G23: =VLOOKUP(K23,装备属性!$A$3:$H$32,6,FALSE) -> 0 | H23: =INT(G23/2) -> 0 | I23: =SUM(Q23:T23) -> 268 | J23: =H23-I23 -> -268 | K23: 钢刃锁甲 | L23: 6 | M23: 皮铠 | N23: 刀刃 | O23: 钢 | Q23: =IF(M23=0,"",VLOOKUP(M23,$A$34:$B$86,2,FALSE)) -> 87 | R23: =IF(N23=0,"",VLOOKUP(N23,$A$34:$B$86,2,FALSE)) -> 51 | S23: =IF(O23=0,"",VLOOKUP(O23,$A$34:$B$86,2,FALSE)) -> 130 | T23: =IF(P23=0,"",VLOOKUP(P23,$A$34:$B$86,2,FALSE)) | U23: 僵尸 | V23: 小恶魔 | X23: 阿莫尔之水 | AG23: 雪球
A24: 华丽背心 | B24: 布衣 | C24: 彩色羽毛 | F24: =INT(G24-J24/2) -> 208 | G24: =VLOOKUP(K24,装备属性!$A$3:$H$32,6,FALSE) -> 51 | H24: =INT(G24/2) -> 25 | I24: =SUM(Q24:T24) -> 340 | J24: =H24-I24 -> -315 | K24: 藤鞭 | L24: 6 | M24: 植物的茎 | N24: 植物的茎 | O24: 马尾 | Q24: =IF(M24=0,"",VLOOKUP(M24,$A$34:$B$86,2,FALSE)) -> 130 | R24: =IF(N24=0,"",VLOOKUP(N24,$A$34:$B$86,2,FALSE)) -> 130 | S24: =IF(O24=0,"",VLOOKUP(O24,$A$34:$B$86,2,FALSE)) -> 80 | T24: =IF(P24=0,"",VLOOKUP(P24,$A$34:$B$86,2,FALSE)) | U24: 骷髅兵 | V24: 魔族大将 | X24: 樱桃 | AG24: 冰晶
A25: 鳞铠 | B25: 蛇皮 | C25: 鱼胶 | F25: =INT(G25-J25/2) -> 283 | G25: =VLOOKUP(K25,装备属性!$A$3:$H$32,6,FALSE) -> 58 | H25: =INT(G25/2) -> 29 | I25: =SUM(Q25:T25) -> 479 | J25: =H25-I25 -> -450 | K25: 女王鞭 | L25: 7 | M25: 藤鞭 | N25: 刀刃 | O25: 幽魂 | Q25: =IF(M25=0,"",VLOOKUP(M25,$A$34:$B$86,2,FALSE)) -> 228 | R25: =IF(N25=0,"",VLOOKUP(N25,$A$34:$B$86,2,FALSE)) -> 51 | S25: =IF(O25=0,"",VLOOKUP(O25,$A$34:$B$86,2,FALSE)) -> 200 | T25: =IF(P25=0,"",VLOOKUP(P25,$A$34:$B$86,2,FALSE)) | U25: 浮游 | V25: 魅魔 | X25: 蜂蜜 | AG25: 亡者之土
A26: 暗之袍 | B26: 布衣 | C26: 黑暗结晶 | D26: 亡者之土 | E26: 幽魂 | F26: =INT(G26-J26/2) -> 327 | G26: =VLOOKUP(K26,装备属性!$A$3:$H$32,6,FALSE) -> 0 | H26: =INT(G26/2) -> 0 | I26: =SUM(Q26:T26) -> 654 | J26: =H26-I26 -> -654 | K26: 兔女郎装 | L26: 7 | M26: 华丽背心 | N26: 兔耳朵 | O26: 羊毛 | P26: 金块 | Q26: =IF(M26=0,"",VLOOKUP(M26,$A$34:$B$86,2,FALSE)) -> 354 | R26: =IF(N26=0,"",VLOOKUP(N26,$A$34:$B$86,2,FALSE)) -> 60 | S26: =IF(O26=0,"",VLOOKUP(O26,$A$34:$B$86,2,FALSE)) -> 70 | T26: =IF(P26=0,"",VLOOKUP(P26,$A$34:$B$86,2,FALSE)) -> 170 | U26: 白龙 | V26: 羊角恶魔 | X26: 苹果 | AG26: 石化之眼
A27: 疾风背心 | B27: 布衣 | C27: 风元素结晶 | D27: 奇美拉之翼 | F27: =INT(G27-J27/2) -> 377 | G27: =VLOOKUP(K27,装备属性!$A$3:$H$32,6,FALSE) -> 58 | H27: =INT(G27/2) -> 29 | I27: =SUM(Q27:T27) -> 668 | J27: =H27-I27 -> -639 | K27: 暴雪斧 | L27: 7 | M27: 战斧 | N27: 雪球 | O27: 雪球 | P27: 冰晶 | Q27: =IF(M27=0,"",VLOOKUP(M27,$A$34:$B$86,2,FALSE)) -> 128 | R27: =IF(N27=0,"",VLOOKUP(N27,$A$34:$B$86,2,FALSE)) -> 170 | S27: =IF(O27=0,"",VLOOKUP(O27,$A$34:$B$86,2,FALSE)) -> 170 | T27: =IF(P27=0,"",VLOOKUP(P27,$A$34:$B$86,2,FALSE)) -> 200 | U27: 地狱犬 | V27: 血族伯爵 | X27: 竹笋 | AG27: 金块
A28: 魔法铠甲 | B28: 皮铠 | C28: 水晶球 | D28: 金块 | F28: =INT(G28-J28/2) -> 390 | G28: =VLOOKUP(K28,装备属性!$A$3:$H$32,6,FALSE) -> 72 | H28: =INT(G28/2) -> 36 | I28: =SUM(Q28:T28) -> 672 | J28: =H28-I28 -> -636 | K28: 冰之刃 | L28: 7 | M28: 长剑 | N28: 冰晶 | O28: 冰晶 | P28: 雪球 | Q28: =IF(M28=0,"",VLOOKUP(M28,$A$34:$B$86,2,FALSE)) -> 102 | R28: =IF(N28=0,"",VLOOKUP(N28,$A$34:$B$86,2,FALSE)) -> 200 | S28: =IF(O28=0,"",VLOOKUP(O28,$A$34:$B$86,2,FALSE)) -> 200 | T28: =IF(P28=0,"",VLOOKUP(P28,$A$34:$B$86,2,FALSE)) -> 170 | U28: 死神 | V28: 千手天使 | AG28: 幽魂
A29: 钢刃锁甲 | B29: 皮铠 | C29: 刀刃 | D29: 钢 | F29: =INT(G29-J29/2) -> 213 | G29: =VLOOKUP(K29,装备属性!$A$3:$H$32,6,FALSE) -> 0 | H29: =INT(G29/2) -> 0 | I29: =SUM(Q29:T29) -> 427 | J29: =H29-I29 -> -427 | K29: 魔法铠甲 | L29: 7 | M29: 皮铠 | N29: 水晶球 | O29: 金块 | Q29: =IF(M29=0,"",VLOOKUP(M29,$A$34:$B$86,2,FALSE)) -> 87 | R29: =IF(N29=0,"",VLOOKUP(N29,$A$34:$B$86,2,FALSE)) -> 170 | S29: =IF(O29=0,"",VLOOKUP(O29,$A$34:$B$86,2,FALSE)) -> 170 | T29: =IF(P29=0,"",VLOOKUP(P29,$A$34:$B$86,2,FALSE)) | AG29: 魔族之血
A30: 丝织长袍 | B30: 布片 | C30: 蛛丝 | D30: 蛛丝 | E30: 银块 | F30: =INT(G30-J30/2) -> 318 | G30: =VLOOKUP(K30,装备属性!$A$3:$H$32,6,FALSE) -> 65 | H30: =INT(G30/2) -> 32 | I30: =SUM(Q30:T30) -> 538 | J30: =H30-I30 -> -506 | K30: 恶魔之斧 | L30: 8 | M30: 战斧 | N30: 魔族之血 | O30: 暗元素结晶 | Q30: =IF(M30=0,"",VLOOKUP(M30,$A$34:$B$86,2,FALSE)) -> 128 | R30: =IF(N30=0,"",VLOOKUP(N30,$A$34:$B$86,2,FALSE)) -> 200 | S30: =IF(O30=0,"",VLOOKUP(O30,$A$34:$B$86,2,FALSE)) -> 210 | T30: =IF(P30=0,"",VLOOKUP(P30,$A$34:$B$86,2,FALSE)) | AG30: 水元素结晶
A31: 兔女郎装 | B31: 华丽背心 | C31: 兔耳朵 | D31: 羊毛 | E31: 奇美拉之翼 | F31: =INT(G31-J31/2) -> 378 | G31: =VLOOKUP(K31,装备属性!$A$3:$H$32,6,FALSE) -> 0 | H31: =INT(G31/2) -> 0 | I31: =SUM(Q31:T31) -> 756 | J31: =H31-I31 -> -756 | K31: 暗之袍 | L31: 8 | M31: 布衣 | N31: 暗元素结晶 | O31: 亡者之土 | P31: 幽魂 | Q31: =IF(M31=0,"",VLOOKUP(M31,$A$34:$B$86,2,FALSE)) -> 114 | R31: =IF(N31=0,"",VLOOKUP(N31,$A$34:$B$86,2,FALSE)) -> 210 | S31: =IF(O31=0,"",VLOOKUP(O31,$A$34:$B$86,2,FALSE)) -> 232 | T31: =IF(P31=0,"",VLOOKUP(P31,$A$34:$B$86,2,FALSE)) -> 200 | AG31: 珊瑚
A32: 水之羽衣 | B32: 布衣 | C32: 水元素结晶 | D32: 毛皮斗篷 | E32: 蛛丝 | F32: =INT(G32-J32/2) -> 0 | H32: =INT(G32/2) -> 0 | I32: =SUM(Q32:T32) -> 0 | J32: =H32-I32 -> 0 | AG32: 纯净之水
AG33: 阿莫尔之水
A34: 废铁 | B34: 51 | AG34: 樱桃
A35: 布片 | B35: 44 | AG35: 蜂蜜
A36: 竹笋 | B36: 44 | AG36: 苹果
A37: 刀刃 | B37: 51 | AG37: 竹笋
A38: 风元素结晶 | B38: 60 | AG38: 椰子
A39: 纯净之水 | B39: 60
A40: 木棒 | B40: 75
...

Sheet Sheet3
A1: 卷心菜 | C1: 1001 | E1: 哥布林战士 | F1: 7000000
A2: 南瓜 | C2: 1002 | E2: 史莱姆 | F2: 7000001 | J2: 废铁
A3: 黄瓜 | C3: 1003 | E3: 利刃蜘蛛 | F3: 7000002 | J3: 木棒
A4: 玉米 | C4: 1004 | E4: 蛮兽 | F4: 7000003 | J4: 布片
A5: 番茄 | C5: 1005 | E5: 雷霆蛮兽 | F5: 7000004 | J5: 兽皮
A6: 茄子 | C6: 1006 | E6: 风精灵 | F6: 7000005 | J6: 刀刃
A7: 马铃薯 | C7: 1007 | E7: 巨魔 | F7: 7000006 | J7: 水晶球
A8: 胡萝卜 | C8: 1008 | E8: 进化史莱姆 | F8: 7000007 | J8: 蛛丝
A9: 芜菁 | C9: 1009 | E9: 蜘蛛 | F9: 7000008 | J9: 土元素结晶
A10: 萝卜 | C10: 1010 | E10: 狼蝠 | F10: 7000009 | J10: 龙鳞
A11: 大葱 | C11: 1011 | E11: 魔狼 | F11: 7000010 | J11: 兽角
A12: 紫甘蓝 | C12: 1012 | E12: 守护者 | F12: 7000011 | J12: 奇美拉之翼
A13: 葡萄 | C13: 1013 | E13: 蜜蜂 | F13: 7000012 | J13: 银块
... A41: 锁子甲 | C41: 1041 | E41: 地狱犬 | F41: 7000040 | J41: 椰子
A42: 毛皮斗篷 | C42: 1042 | E42: 死神 | F42: 7000041
A43: 铁铠甲 | C43: 1043 | E43: 小恶魔 | F43: 7000042
A44: 龙之铠 | C44: 1044 | E44: 魔族大将 | F44: 7000043
A45: 华丽背心 | C45: 1045 | E45: 魅魔 | F45: 7000044
A46: 鳞铠 | C46: 1046 | E46: 羊角恶魔 | F46: 7000045
A47: 暗之袍 | C47: 1047 | E47: 血族伯爵 | F47: 7000046
A48: 疾风背心 | C48: 1048 | E48: 千手天使 | F48: 7000047
A49: 魔法铠甲 | C49: 1049
A50: 刀刃锁甲 | C50: 1050
A51: 丝织长袍 | C51: 1051
A52: 兔女郎装 | C52: 1052
A53: 咒术师衣 | C53: 1053
A54: 水之羽衣 | C54: 1054
A55: 饭团 | C55: 1055
A56: 海鲜饭 | C56: 1056
A57: 煎蛋 | C57: 1057
A58: 蛋包饭 | C58: 1058
A59: 腌芜菁 | C59: 1059
A60: 竹笋饭 | C60: 1060
... A300: 热餐台 | C300: 1300

Sheet 装备属性
I1: 1 | J1: 2 | K1: 8 | L1: 9 | Y1: at | Z1: df | AA1: c | AB1: d | AE1: 8 | AF1: 6
I2: 攻击 | J2: 防御 | K2: 灵巧 | L2: 暴烈 | W2: 10 | X2: 1 | Y2: =$AE$1+W2*$AF$1 -> 68 | Z2: =$AE$2+$AF$2*W2 -> 58 | AA2: =INT($AE$4+$W2*$AF$4) -> 39 | AB2: =INT($AE$5+$W2*$AF$4) -> 39 | AE2: 8 | AF2: 5
A3: 长剑 | B3: 1 | C3: 武器 | D3: 剑 | E3: 攻击+34 | F3: =INT(I3/2) -> 17 | H3: =I3*6+J3*6+K3*9+L3*9 -> 204 | I3: 34 | M3: =IF(I3<>0,I$1&","&F3,"") -> 1,17 | N3: =IF(J3<>0,J$1&","&J3,"") | O3: =IF(K3<>0,K$1&","&K3,"") | P3: =IF(L3<>0,L$1&","&L3,"") | Q3: =IF(M3="","",M3)&IF(N3="","",";"&N3)&IF(O3="","",";"&O3)&IF(P3="","",";"&P3) -> 1,17 | R3: =IF(I3<>0,I$2&"+"&F3,"") -> 攻击+17 | S3: =IF(J3<>0,J$2&"+"&J3,"") | T3: =IF(K3<>0,K$2&"+"&K3,"") | U3: =IF(L3<>0,L$2&"+"&L3,"") | V3: =IF(R3="","",R3)&IF(S3="","",IF(R17="",""," ")&S3)&IF(T3="",""," "&T3)&IF(U3="",""," "&U3) -> 攻击+17 | W3: 17 | X3: 2 | Y3: =$AE$1+W3*$AF$1 -> 110 | Z3: =$AE$2+$AF$2*W3 -> 93 | AA3: =INT($AE$4+$W3*$AF$4) -> 41 | AB3: =INT($AE$5+$W3*$AF$4) -> 41
A4: 铁枪 | B4: 2 | C4: 武器 | D4: 枪 | E4: 攻击+44 灵巧+10 | F4: =INT(I4/2) -> 22 | H4: =I4*6+J4*6+K4*9+L4*9 -> 354 | I4: 44 | K4: 10 | M4: =IF(I4<>0,I$1&","&F4,"") -> 1,22 | O4: =IF(K4<>0,K$1&","&K4,"") -> 8,10 | P4: =IF(L4<>0,L$1&","&L4,"") | Q4: =IF(M4="","",M4)&IF(N4="","",";"&N4)&IF(O4="","",";"&O4)&IF(P4="","",";"&P4) -> 1,22;8,10 | R4: =IF(I4<>0,I$2&"+"&F4,"") -> 攻击+22 | S4: =IF(J4<>0,J$2&"+"&J4,"") | T4: =IF(K4<>0,K$2&"+"&K4,"") -> 灵巧+10 | U4: =IF(L4<>0,L$2&"+"&L4,"") | V4: =IF(R4="","",R4)&IF(S4="","",IF(R18="",""," ")&S4)&IF(T4="",""," "&T4)&IF(U4="",""," "&U4) -> 攻击+22 灵巧+10 | W4: 23 | X4: 3 | Y4: =$AE$1+W4*$AF$1 -> 146 | Z4: =$AE$2+$AF$2*W4 -> 123 | AA4: =INT($AE$4+$W4*$AF$4) -> 43 | AB4: =INT($AE$5+$W4*$AF$4) -> 43 | AE4: 36 | AF4: 0.33
A5: 蛇皮鞭 | B5: 3 | C5: 武器 | D5: 鞭 | E5: 攻击+58 灵巧+4 暴烈+6 | F5: =INT(I5/2) -> 29 | H5: =I5*6+J5*6+K5*9+L5*9 -> 438 | I5: 58 | K5: 4 | L5: 6 | M5: =IF(I5<>0,I$1&","&F5,"") -> 1,29 | O5: =IF(K5<>0,K$1&","&K5,"") -> 8,4 | P5: =IF(L5<>0,L$1&","&L5,"") -> 9,6 | Q5: =IF(M5="","",M5)&IF(N5="","",";"&N5)&IF(O5="","",";"&O5)&IF(P5="","",";"&P5) -> 1,29;8,4;9,6 | R5: =IF(I5<>0,I$2&"+"&F5,"") -> 攻击+29 | S5: =IF(J5<>0,J$2&"+"&J5,"") | T5: =IF(K5<>0,K$2&"+"&K5,"") -> 灵巧+4 | U5: =IF(L5<>0,L$2&"+"&L5,"") -> 暴烈+6 | V5: =IF(R5="","",R5)&IF(S5="","",IF(R19="",""," ")&S5)&IF(T5="",""," "&T5)&IF(U5="",""," "&U5) -> 攻击+29 灵巧+4 暴烈+6 | W5: 29 | X5: 4 | Y5: =$AE$1+W5*$AF$1 -> 182 | Z5: =$AE$2+$AF$2*W5 -> 153 | AA5: =INT($AE$4+$W5*$AF$4) -> 45 | AB5: =INT($AE$5+$W5*$AF$4) -> 45 | AE5: 36 | AF5: 0.33
A6: 蛇牙鞭 | B6: 3 | C6: 武器 | D6: 鞭 | E6: 攻击+65 灵巧+4 暴烈+6 | F6: =INT(I6/2) -> 32 | H6: =I6*6+J6*6+K6*9+L6*9 -> 480 | I6: 65 | K6: 4 | L6: 6 | M6: =IF(I6<>0,I$1&","&F6,"") -> 1,32 | O6: =IF(K6<>0,K$1&","&K6,"") -> 8,4 | P6: =IF(L6<>0,L$1&","&L6,"") -> 9,6 | Q6: =IF(M6="","",M6)&IF(N6="","",";"&N6)&IF(O6="","",";"&O6)&IF(P6="","",";"&P6) -> 1,32;8,4;9,6 | R6: =IF(I6<>0,I$2&"+"&F6,"") -> 攻击+32 | S6: =IF(J6<>0,J$2&"+"&J6,"") | T6: =IF(K6<>0,K$2&"+"&K6,"") -> 灵巧+4 | U6: =IF(L6<>0,L$2&"+"&L6,"") -> 暴烈+6 | V6: =IF(R6="","",R6)&IF(S6="","",IF(R20="",""," ")&S6)&IF(T6="",""," "&T6)&IF(U6="",""," "&U6) -> 攻击+32 灵巧+4 暴烈+6 | W6: 35 | X6: 5 | Y6: =$AE$1+W6*$AF$1 -> 218 | Z6: =$AE$2+$AF$2*W6 -> 183 | AA6: =INT($AE$4+$W6*$AF$4) -> 47 | AB6: =INT($AE$5+$W6*$AF$4) -> 47
A7: 诅咒之剑 | B7: 3 | C7: 武器 | D7: 剑 | E7: 攻击+73 | F7: =INT(I7/2) -> 36 | H7: =I7*6+J7*6+K7*9+L7*9 -> 438 | I7: 73 | M7: =IF(I7<>0,I$1&","&F7,"") -> 1,36 | O7: =IF(K7<>0,K$1&","&K7,"") | P7: =IF(L7<>0,L$1&","&L7,"") | Q7: =IF(M7="","",M7)&IF(N7="","",";"&N7)&IF(O7="","",";"&O7)&IF(P7="","",";"&P7) -> 1,36 | R7: =IF(I7<>0,I$2&"+"&F7,"") -> 攻击+36 | S7: =IF(J7<>0,J$2&"+"&J7,"") | T7: =IF(K7<>0,K$2&"+"&K7,"") | U7: =IF(L7<>0,L$2&"+"&L7,"") | V7: =IF(R7="","",R7)&IF(S7="","",IF(R21="",""," ")&S7)&IF(T7="",""," "&T7)&IF(U7="",""," "&U7) -> 攻击+36 | W7: 41 | X7: 6 | Y7: =$AE$1+W7*$AF$1 -> 254 | Z7: =$AE$2+$AF$2*W7 -> 213 | AA7: =INT($AE$4+$W7*$AF$4) -> 49 | AB7: =INT($AE$5+$W7*$AF$4) -> 49
A8: 三叉戟 | B8: 4 | C8: 武器 | D8: 枪 | E8: 攻击+72 灵巧+12 | F8: =INT(I8/2) -> 36 | H8: =I8*6+J8*6+K8*9+L8*9 -> 540 | I8: 72 | K8: 12 | M8: =IF(I8<>0,I$1&","&F8,"") -> 1,36 | O8: =IF(K8<>0,K$1&","&K8,"") -> 8,12 | P8: =IF(L8<>0,L$1&","&L8,"") | Q8: =IF(M8="","",M8)&IF(N8="","",";"&N8)&IF(O8="","",";"&O8)&IF(P8="","",";"&P8) -> 1,36;8,12 | R8: =IF(I8<>0,I$2&"+"&F8,"") -> 攻击+36 | S8: =IF(J8<>0,J$2&"+"&J8,"") | T8: =IF(K8<>0,K$2&"+"&K8,"") -> 灵巧+12 | U8: =IF(L8<>0,L$2&"+"&L8,"") | V8: =IF(R8="","",R8)&IF(S8="","",IF(R22="",""," ")&S8)&IF(T8="",""," "&T8)&IF(U8="",""," "&U8) -> 攻击+36 灵巧+12 | W8: 47 | X8: 7 | Y8: =$AE$1+W8*$AF$1 -> 290 | Z8: =$AE$2+$AF$2*W8 -> 243 | AA8: =INT($AE$4+$W8*$AF$4) -> 51 | AB8: =INT($AE$5+$W8*$AF$4) -> 51
A9: 骑士长枪 | B9: 5 | C9: 武器 | D9: 枪 | E9: 攻击+87 灵巧+12 | F9: =INT(I9/2) -> 43 | H9: =I9*6+J9*6+K9*9+L9*9 -> 630 | I9: 87 | K9: 12 | M9: =IF(I9<>0,I$1&","&F9,"") -> 1,43 | O9: =IF(K9<>0,K$1&","&K9,"") -> 8,12 | P9: =IF(L9<>0,L$1&","&L9,"") | Q9: =IF(M9="","",M9)&IF(N9="","",";"&N9)&IF(O9="","",";"&O9)&IF(P9="","",";"&P9) -> 1,43;8,12 | R9: =IF(I9<>0,I$2&"+"&F9,"") -> 攻击+43 | S9: =IF(J9<>0,J$2&"+"&J9,"") | T9: =IF(K9<>0,K$2&"+"&K9,"") -> 灵巧+12 | U9: =IF(L9<>0,L$2&"+"&L9,"") | V9: =IF(R9="","",R9)&IF(S9="","",IF(R23="",""," ")&S9)&IF(T9="",""," "&T9)&IF(U9="",""," "&U9) -> 攻击+43 灵巧+12 | W9: 53 | X9: 8 | Y9: =$AE$1+W9*$AF$1 -> 326 | Z9: =$AE$2+$AF$2*W9 -> 273 | AA9: =INT($AE$4+$W9*$AF$4) -> 53 | AB9: =INT($AE$5+$W9*$AF$4) -> 53
