Workbook

Sheet ItemData
A2: string | B2: int | C2: string | D2: int | E2: int | F2: int | G2: bool | H2: bool | I2: int | J2: int | K2: int | L2: int | M2: int | N2: int | O2: List<int> | P2: List<int> | Q2: int | R2: int | S2: int | T2: List<int> | U2: bool | V2: int | W2: int | X2: int | Y2: int | Z2: int | AA2: int | AB2: int | AC2: int | AD2: int | AE2: int | AF2: int | AG2: string
A3: itemName | B3: id | C3: iconName | D3: type | E3: typeValue | F3: otherType | G3: isFresh | H3: itemValue | I3: attributeType | J3: equipLevel | K3: groupCount | L3: shopMoneyType | M3: shopPrice | N3: sellPrice | O3: dropEventId | P3: checkEventId | Q3: sceneType | R3: useEventId | S3: fightUseSkill | T3: equipEventId | U3: showProperty | V3: HP | W3: MP | X3: Power | Y3: MaxHP | Z3: MaxMP | AA3: MaxPower | AB3: AT | AC3: DF | AD3: Lucky | AE3: Speed | AF3: Other | AG3: info
A4: 未知的物品 | B4: 1 | C4: default | D4: -1 | E4: 0 | F4: 0 | G4: 0 | H4: 0 | I4: 0 | J4: 0 | K4: 0 | L4: 1 | M4: 0 | N4: 0 | Q4: 0 | R4: 0 | S4: 0 | U4: false | V4: 0 | W4: 0 | X4: 0 | Y4: 0 | Z4: 0 | AA4: 0 | AB4: 0 | AC4: 0 | AD4: 0 | AE4: 0 | AF4: 0 | AG4: ????????
A5: 失败的徒手 | B5: 20 | C5: 失败的徒手 | D5: 4 | E5: 0 | F5: 0 | G5: 0 | H5: 0 | I5: 0 | J5: 0 | K5: 0 | L5: 1 | M5: 0 | N5: 0 | Q5: 0 | R5: 0 | S5: 0 | U5: false | V5: 0 | W5: 0 | X5: 0 | Y5: 0 | Z5: 0 | AA5: 0 | AB5: 0 | AC5: 0 | AD5: 0 | AE5: 0 | AF5: 0 | AG5: 看起来不像是能吃的样子
A6: 失败的搅拌 | B6: 21 | C6: 失败的搅拌 | D6: 4 | E6: 0 | F6: 0 | G6: 0 | H6: 0 | I6: 0 | J6: 0 | K6: 0 | L6: 1 | M6: 0 | N6: 0 | Q6: 0 | R6: 0 | S6: 0 | U6: false | V6: 0 | W6: 0 | X6: 0 | Y6: 0 | Z6: 0 | AA6: 0 | AB6: 0 | AC6: 0 | AD6: 0 | AE6: 0 | AF6: 0 | AG6: 看起来不像是能吃的样子
A7: 失败的烘烤 | B7: 22 | C7: 失败的烘烤 | D7: 4 | E7: 0 | F7: 0 | G7: 0 | H7: 0 | I7: 0 | J7: 0 | K7: 0 | L7: 1 | M7: 0 | N7: 0 | Q7: 0 | R7: 0 | S7: 0 | U7: false | V7: 0 | W7: 0 | X7: 0 | Y7: 0 | Z7: 0 | AA7: 0 | AB7: 0 | AC7: 0 | AD7: 0 | AE7: 0 | AF7: 0 | AG7: 看起来不像是能吃的样子
A8: 失败的蒸煮 | B8: 23 | C8: 失败的蒸煮 | D8: 4 | E8: 0 | F8: 0 | G8: 0 | H8: 0 | I8: 0 | J8: 0 | K8: 0 | L8: 1 | M8: 0 | N8: 0 | Q8: 0 | R8: 0 | S8: 0 | U8: false | V8: 0 | W8: 0 | X8: 0 | Y8: 0 | Z8: 0 | AA8: 0 | AB8: 0 | AC8: 0 | AD8: 0 | AE8: 0 | AF8: 0 | AG8: 看起来不像是能吃的样子
A9: 失败的酿造 | B9: 24 | C9: 失败的酿造 | D9: 4 | E9: 0 | F9: 0 | G9: 0 | H9: 0 | I9: 0 | J9: 0 | K9: 0 | L9: 1 | M9: 0 | N9: 0 | Q9: 0 | R9: 0 | S9: 0 | U9: false | V9: 0 | W9: 0 | X9: 0 | Y9: 0 | Z9: 0 | AA9: 0 | AB9: 0 | AC9: 0 | AD9: 0 | AE9: 0 | AF9: 0 | AG9: 看起来不像是能吃的样子
A10: 失败的铸造 | B10: 25 | C10: 失败的铸造 | D10: 4 | E10: 0 | F10: 0 | G10: 0 | H10: 0 | I10: 0 | J10: 0 | K10: 0 | L10: 1 | M10: 0 | N10: 0 | Q10: 0 | R10: 0 | S10: 0 | U10: false | V10: 0 | W10: 0 | X10: 0 | Y10: 0 | Z10: 0 | AA10: 0 | AB10: 0 | AC10: 0 | AD10: 0 | AE10: 0 | AF10: 0 | AG10: 一团杂乱的物体
A11: 失败的缝纫 | B11: 26 | C11: 失败的缝纫 | D11: 4 | E11: 0 | F11: 0 | G11: 0 | H11: 0 | I11: 0 | J11: 0 | K11: 0 | L11: 1 | M11: 0 | N11: 0 | Q11: 0 | R11: 0 | S11: 0 | U11: false | V11: 0 | W11: 0 | X11: 0 | Y11: 0 | Z11: 0 | AA11: 0 | AB11: 0 | AC11: 0 | AD11: 0 | AE11: 0 | AF11: 0 | AG11: 一团杂乱的物体
A12: 失败的绘写 | B12: 27 | C12: 失败的绘写 | D12: 4 | E12: 0 | F12: 0 | G12: 0 | H12: 0 | I12: 0 | J12: 0 | K12: 0 | L12: 1 | M12: 0 | N12: 0 | Q12: 0 | R12: 0 | S12: 0 | U12: false | V12: 0 | W12: 0 | X12: 0 | Y12: 0 | Z12: 0 | AA12: 0 | AB12: 0 | AC12: 0 | AD12: 0 | AE12: 0 | AF12: 0 | AG12: 一团杂乱的物体
A13: 传送卷轴 | B13: 11 | C13: 卷轴 | D13: 5 | E13: 0 | F13: 0 | G13: 0 | H13: 0 | I13: 0 | J13: 0 | K13: 9 | L13: 1 | M13: 0 | N13: 0 | Q13: 2 | R13: 7000 | S13: 0 | U13: false | V13: 0 | W13: 0 | X13: 0 | Y13: 0 | Z13: 0 | AA13: 0 | AB13: 0 | AC13: 0 | AD13: 0 | AE13: 0 | AF13: 0 | AG13: 快速在城镇中移动
A14: 鱼饵 | B14: 12 | C14: 鱼饵 | D14: 5 | E14: 0 | F14: 0 | G14: 0 | H14: 0 | I14: 0 | J14: 0 | K14: 19 | L14: 1 | M14: 0 | N14: 0 | Q14: 2 | R14: 0 | S14: 0 | U14: false | V14: 0 | W14: 0 | X14: 0 | Y14: 0 | Z14: 0 | AA14: 0 | AB14: 0 | AC14: 0 | AD14: 0 | AE14: 0 | AF14: 0 | AG14: 用来引诱鱼类的饵料
A15: 食物配方 | B15: 20 | C15: 食物配方 | D15: 5 | E15: 0 | F15: 0 | G15: 0 | H15: 0 | I15: 0 | J15: 0 | K15: 9 | L15: 1 | M15: 0 | N15: 0 | Q15: 2 | R15: 0 | S15: 0 | U15: false | V15: 0 | W15: 0 | X15: 0 | Y15: 0 | Z15: 0 | AA15: 0 | AB15: 0 | AC15: 0 | AD15: 0 | AE15: 0 | AF15: 0
A16: 酒水配方 | B16: 21 | C16: 酒水配方 | D16: 5 | E16: 0 | F16: 0 | G16: 0 | H16: 0 | I16: 0 | J16: 0 | K16: 9 | L16: 1 | M16: 0 | N16: 0 | Q16: 2 | R16: 0 | S16: 0 | U16: false | V16: 0 | W16: 0 | X16: 0 | Y16: 0 | Z16: 0 | AA16: 0 | AB16: 0 | AC16: 0 | AD16: 0 | AE16: 0 | AF16: 0
A17: 铸造配方 | B17: 22 | C17: 铸造配方 | D17: 5 | E17: 0 | F17: 0 | G17: 0 | H17: 0 | I17: 0 | J17: 0 | K17: 9 | L17: 1 | M17: 0 | N17: 0 | Q17: 2 | R17: 0 | S17: 0 | U17: false | V17: 0 | W17: 0 | X17: 0 | Y17: 0 | Z17: 0 | AA17: 0 | AB17: 0 | AC17: 0 | AD17: 0 | AE17: 0 | AF17: 0
A18: 缝纫配方 | B18: 23 | C18: 缝纫配方 | D18: 5 | E18: 0 | F18: 0 | G18: 0 | H18: 0 | I18: 0 | J18: 0 | K18: 9 | L18: 1 | M18: 0 | N18: 0 | Q18: 2 | R18: 0 | S18: 0 | U18: false | V18: 0 | W18: 0 | X18: 0 | Y18: 0 | Z18: 0 | AA18: 0 | AB18: 0 | AC18: 0 | AD18: 0 | AE18: 0 | AF18: 0
A19: 书写配方 | B19: 24 | C19: 书写配方 | D19: 5 | E19: 0 | F19: 0 | G19: 0 | H19: 0 | I19: 0 | J19: 0 | K19: 9 | L19: 1 | M19: 0 | N19: 0 | Q19: 2 | R19: 0 | S19: 0 | U19: false | V19: 0 | W19: 0 | X19: 0 | Y19: 0 | Z19: 0 | AA19: 0 | AB19: 0 | AC19: 0 | AD19: 0 | AE19: 0 | AF19: 0
A20: 牧草 | B20: 100 | C20: 牧草 | D20: -1 | E20: 0 | F20: 0 | G20: 0 | H20: 0 | I20: 0 | J20: 0 | K20: 29 | L20: 1 | M20: 0 | N20: 0 | Q20: 0 | R20: 0 | S20: 0 | U20: false | V20: 0 | W20: 0 | X20: 0 | Y20: 0 | Z20: 0 | AA20: 0 | AB20: 0 | AC20: 0 | AD20: 0 | AE20: 0 | AF20: 0 | AG20: 未成熟的植物制成的鲜嫩可口的饲料
A21: 木材 | B21: 101 | C21: 木材 | D21: 5 | E21: 0 | F21: 0 | G21: 0 | H21: 0 | I21: 0 | J21: 0 | K21: 29 | L21: 1 | M21: 0 | N21: 0 | Q21: 0 | R21: 0 | S21: 0 | U21: false | V21: 0 | W21: 0 | X21: 0 | Y21: 0 | Z21: 0 | AA21: 0 | AB21: 0 | AC21: 0 | AD21: 0 | AE21: 0 | AF21: 0 | AG21: 木材
A22: 原木 | B22: 102 | C22: 原木 | D22: 5 | E22: 0 | F22: 0 | G22: 0 | H22: 0 | I22: 0 | J22: 0 | K22: 9 | L22: 1 | M22: 0 | N22: 0 | Q22: 0 | R22: 0 | S22: 0 | U22: false | V22: 0 | W22: 0 | X22: 0 | Y22: 0 | Z22: 0 | AA22: 0 | AB22: 0 | AC22: 0 | AD22: 0 | AE22: 0 | AF22: 0 | AG22: 原木
A23: 木柴 | B23: 103 | C23: 木柴 | D23: 5 | E23: 0 | F23: 0 | G23: 0 | H23: 0 | I23: 0 | J23: 0 | K23: 49 | L23: 1 | M23: 0 | N23: 0 | Q23: 0 | R23: 0 | S23: 0 | U23: false | V23: 0 | W23: 0 | X23: 0 | Y23: 0 | Z23: 0 | AA23: 0 | AB23: 0 | AC23: 0 | AD23: 0 | AE23: 0 | AF23: 0 | AG23: 木柴
A24: 木棒 | B24: 104 | C24: 木棒 | D24: 5 | E24: 0 | F24: 0 | G24: 0 | H24: 0 | I24: 0 | J24: 0 | K24: 39 | L24: 1 | M24: 0 | N24: 0 | Q24: 0 | R24: 0 | S24: 0 | U24: false | V24: 0 | W24: 0 | X24: 0 | Y24: 0 | Z24: 0 | AA24: 0 | AB24: 0 | AC24: 0 | AD24: 0 | AE24: 0 | AF24: 0 | AG24: 木棒
A25: 干草 | B25: 105 | C25: 干草 | D25: 5 | E25: 0 | F25: 0 | G25: 0 | H25: 0 | I25: 0 | J25: 0 | K25: 39 | L25: 1 | M25: 0 | N25: 0 | Q25: 0 | R25: 0 | S25: 0 | U25: false | V25: 0 | W25: 0 | X25: 0 | Y25: 0 | Z25: 0 | AA25: 0 | AB25: 0 | AC25: 0 | AD25: 0 | AE25: 0 | AF25: 0 | AG25: 干草
A26: 纯净水 | B26: 200 | C26: 纯净水 | D26: 5 | E26: 0 | F26: 0 | G26: 0 | H26: 0 | I26: 0 | J26: 0 | K26: 49 | L26: 1 | M26: 0 | N26: 0 | Q26: 0 | R26: 0 | S26: 0 | U26: false | V26: 0 | W26: 0 | X26: 0 | Y26: 0 | Z26: 0 | AA26: 0 | AB26: 0 | AC26: 0 | AD26: 0 | AE26: 0 | AF26: 0
A27: 石块 | B27: 201 | C27: 石块 | D27: 5 | E27: 0 | F27: 0 | G27: 0 | H27: 0 | I27: 0 | J27: 0 | K27: 49 | L27: 1 | M27: 0 | N27: 0 | Q27: 0 | R27: 0 | S27: 0 | U27: false | V27: 0 | W27: 0 | X27: 0 | Y27: 0 | Z27: 0 | AA27: 0 | AB27: 0 | AC27: 0 | AD27: 0 | AE27: 0 | AF27: 0
A28: 龟壳 | B28: 202 | C28: 龟壳 | D28: 5 | E28: 0 | F28: 0 | G28: 0 | H28: 0 | I28: 0 | J28: 0 | K28: 49 | L28: 1 | M28: 0 | N28: 0 | Q28: 0 | R28: 0 | S28: 0 | U28: false | V28: 0 | W28: 0 | X28: 0 | Y28: 0 | Z28: 0 | AA28: 0 | AB28: 0 | AC28: 0 | AD28: 0 | AE28: 0 | AF28: 0
A29: 兽皮 | B29: 203 | C29: 兽皮 | D29: 5 | E29: 0 | F29: 0 | G29: 0 | H29: 0 | I29: 0 | J29: 0 | K29: 49 | L29: 1 | M29: 0 | N29: 0 | Q29: 0 | R29: 0 | S29: 0 | U29: false | V29: 0 | W29: 0 | X29: 0 | Y29: 0 | Z29: 0 | AA29: 0 | AB29: 0 | AC29: 0 | AD29: 0 | AE29: 0 | AF29: 0
A30: 布片 | B30: 204 | C30: 布片 | D30: 5 | E30: 0 | F30: 0 | G30: 0 | H30: 0 | I30: 0 | J30: 0 | K30: 49 | L30: 1 | M30: 0 | N30: 0 | Q30: 0 | R30: 0 | S30: 0 | U30: false | V30: 0 | W30: 0 | X30: 0 | Y30: 0 | Z30: 0 | AA30: 0 | AB30: 0 | AC30: 0 | AD30: 0 | AE30: 0 | AF30: 0
A31: 石英砂 | B31: 205 | C31: 石英砂 | D31: 5 | E31: 0 | F31: 0 | G31: 0 | H31: 0 | I31: 0 | J31: 0 | K31: 49 | L31: 1 | M31: 0 | N31: 0 | Q31: 0 | R31: 0 | S31: 0 | U31: false | V31: 0 | W31: 0 | X31: 0 | Y31: 0 | Z31: 0 | AA31: 0 | AB31: 0 | AC31: 0 | AD31: 0 | AE31: 0 | AF31: 0
A32: 草药茶 | B32: 207 | C32: 草药茶 | D32: 5 | E32: 0 | F32: 0 | G32: 0 | H32: 0 | I32: 0 | J32: 0 | K32: 49 | L32: 1 | M32: 0 | N32: 0 | Q32: 0 | R32: 0 | S32: 0 | U32: false | V32: 0 | W32: 0 | X32: 0 | Y32: 0 | Z32: 0 | AA32: 0 | AB32: 0 | AC32: 0 | AD32: 0 | AE32: 0 | AF32: 0
A33: 风晶石 | B33: 208 | C33: 风晶石 | D33: 5 | E33: 0 | F33: 0 | G33: 0 | H33: 0 | I33: 0 | J33: 0 | K33: 49 | L33: 1 | M33: 0 | N33: 0 | Q33: 0 | R33: 0 | S33: 0 | U33: false | V33: 0 | W33: 0 | X33: 0 | Y33: 0 | Z33: 0 | AA33: 0 | AB33: 0 | AC33: 0 | AD33: 0 | AE33: 0 | AF33: 0
A34: 琥珀 | B34: 210 | C34: 琥珀 | D34: 5 | E34: 0 | F34: 0 | G34: 0 | H34: 0 | I34: 0 | J34: 0 | K34: 49 | L34: 1 | M34: 0 | N34: 0 | Q34: 0 | R34: 0 | S34: 0 | U34: false | V34: 0 | W34: 0 | X34: 0 | Y34: 0 | Z34: 0 | AA34: 0 | AB34: 0 | AC34: 0 | AD34: 0 | AE34: 0 | AF34: 0
A35: 狼牙 | B35: 211 | C35: 狼牙 | D35: 5 | E35: 0 | F35: 0 | G35: 0 | H35: 0 | I35: 0 | J35: 0 | K35: 49 | L35: 1 | M35: 0 | N35: 0 | Q35: 0 | R35: 0 | S35: 0 | U35: false | V35: 0 | W35: 0 | X35: 0 | Y35: 0 | Z35: 0 | AA35: 0 | AB35: 0 | AC35: 0 | AD35: 0 | AE35: 0 | AF35: 0
A36: 粘土 | B36: 212 | C36: 粘土 | D36: 5 | E36: 0 | F36: 0 | G36: 0 | H36: 0 | I36: 0 | J36: 0 | K36: 49 | L36: 1 | M36: 0 | N36: 0 | Q36: 0 | R36: 0 | S36: 0 | U36: false | V36: 0 | W36: 0 | X36: 0 | Y36: 0 | Z36: 0 | AA36: 0 | AB36: 0 | AC36: 0 | AD36: 0 | AE36: 0 | AF36: 0
A37: 尖刺 | B37: 213 | C37: 尖刺 | D37: 5 | E37: 0 | F37: 0 | G37: 0 | H37: 0 | I37: 0 | J37: 0 | K37: 49 | L37: 1 | M37: 0 | N37: 0 | Q37: 0 | R37: 0 | S37: 0 | U37: false | V37: 0 | W37: 0 | X37: 0 | Y37: 0 | Z37: 0 | AA37: 0 | AB37: 0 | AC37: 0 | AD37: 0 | AE37: 0 | AF37: 0
... A122: 兔子脚 | B122: 302 | C122: 兔子脚 | D122: 5 | E122: 0 | F122: 0 | G122: 0 | H122: 0 | I122: 0 | J122: 0 | K122: 49 | L122: 1 | M122: 0 | N122: 0 | Q122: 0 | R122: 0 | S122: 0 | U122: false | V122: 0 | W122: 0 | X122: 0 | Y122: 0 | Z122: 0 | AA122: 0 | AB122: 0 | AC122: 0 | AD122: 0 | AE122: 0 | AF122: 0
A123: 芜菁 | B123: 1001 | C123: =A123&"_01" -> 芜菁_01 | D123: 5 | E123: 1 | F123: 0 | G123: 1 | H123: 0 | I123: 0 | J123: 0 | K123: 29 | L123: 1 | M123: 100 | N123: 100 | Q123: 0 | R123: 0 | S123: 0 | U123: false | V123: 0 | W123: 0 | X123: 0 | Y123: 0 | Z123: 0 | AA123: 0 | AB123: 0 | AC123: 0 | AD123: 0 | AE123: 0 | AF123: 0
A124: 卷心菜 | B124: 1002 | C124: =A124&"_01" -> 卷心菜_01 | D124: 5 | E124: 1 | F124: 0 | G124: 1 | H124: 0 | I124: 0 | J124: 0 | K124: 29 | L124: 1 | M124: 100 | N124: 100 | Q124: 0 | R124: 0 | S124: 0 | U124: false | V124: 0 | W124: 0 | X124: 0 | Y124: 0 | Z124: 0 | AA124: 0 | AB124: 0 | AC124: 0 | AD124: 0 | AE124: 0 | AF124: 0
A125: 葱 | B125: 1003 | C125: =A125&"_01" -> 葱_01 | D125: 5 | E125: 1 | F125: 0 | G125: 1 | H125: 0 | I125: 0 | J125: 0 | K125: 29 | L125: 1 | M125: 100 | N125: 100 | Q125: 0 | R125: 0 | S125: 0 | U125: false | V125: 0 | W125: 0 | X125: 0 | Y125: 0 | Z125: 0 | AA125: 0 | AB125: 0 | AC125: 0 | AD125: 0 | AE125: 0 | AF125: 0
...

Sheet Sheet2
D5: 322
B6: 1600 | C6: 长剑 | E6: 木材 | F6: 铸造 | H6: 长剑 | J6: 铁块 | K6: 刀刃 | N6: =VLOOKUP(J6,ItemData!$A$4:$B$394,2,FALSE) -> 298 | O6: =VLOOKUP(K6,ItemData!$A$4:$B$394,2,FALSE) -> 274 | S6: =N6&","&O6&IF(P6<>"",","&P6,"")&IF(Q6<>"",","&Q6,"") -> 298,274
B7: 1601 | C7: 诅咒之剑 | E7: 原木 | F7: 铸造 | G7: 诅咒猎杀 | H7: 诅咒之剑 | J7: 长剑 | K7: 眼球 | L7: 诅咒宝珠 | N7: =VLOOKUP(J7,ItemData!$A$4:$B$394,2,FALSE) -> 1600 | O7: =VLOOKUP(K7,ItemData!$A$4:$B$394,2,FALSE) -> 220 | P7: =VLOOKUP(L7,ItemData!$A$4:$B$394,2,FALSE) -> 257 | S7: =N7&","&O7&IF(P7<>"",","&P7,"")&IF(Q7<>"",","&Q7,"") -> 1600,220,257
B8: 1602 | C8: 烈焰之刃 | E8: 木柴 | F8: 铸造 | G8: 烈焰斩 | H8: 烈焰之刃 | J8: 长剑 | K8: 火晶石 | L8: 石英砂 | M8: 白磷粉末 | N8: =VLOOKUP(J8,ItemData!$A$4:$B$394,2,FALSE) -> 1600 | O8: =VLOOKUP(K8,ItemData!$A$4:$B$394,2,FALSE) -> 229 | P8: =VLOOKUP(L8,ItemData!$A$4:$B$394,2,FALSE) -> 205 | Q8: =VLOOKUP(M8,ItemData!$A$4:$B$394,2,FALSE) -> 284 | S8: =N8&","&O8&IF(P8<>"",","&P8,"")&IF(Q8<>"",","&Q8,"") -> 1600,229,205,284
B9: 1603 | C9: 大地之剑 | E9: 木棒 | F9: 铸造 | G9: 地刺 | H9: 大地之剑 | J9: 长剑 | K9: 土晶石 | L9: 钢 | M9: 粘土 | N9: =VLOOKUP(J9,ItemData!$A$4:$B$394,2,FALSE) -> 1600 | O9: =VLOOKUP(K9,ItemData!$A$4:$B$394,2,FALSE) -> 218 | P9: =VLOOKUP(L9,ItemData!$A$4:$B$394,2,FALSE) -> 299 | Q9: =VLOOKUP(M9,ItemData!$A$4:$B$394,2,FALSE) -> 212 | S9: =N9&","&O9&IF(P9<>"",","&P9,"")&IF(Q9<>"",","&Q9,"") -> 1600,218,299,212
B10: 1604 | C10: 冰之刃 | F10: 铸造 | G10: 寒冰斩 | H10: 冰之刃 | J10: 长剑 | K10: 冰晶石 | L10: 冰的结晶 | M10: 雪球 | N10: =VLOOKUP(J10,ItemData!$A$4:$B$394,2,FALSE) -> 1600 | O10: =VLOOKUP(K10,ItemData!$A$4:$B$394,2,FALSE) -> 260 | P10: =VLOOKUP(L10,ItemData!$A$4:$B$394,2,FALSE) -> 261 | Q10: =VLOOKUP(M10,ItemData!$A$4:$B$394,2,FALSE) -> 253 | S10: =N10&","&O10&IF(P10<>"",","&P10,"")&IF(Q10<>"",","&Q10,"") -> 1600,260,261,253
B11: 1605 | C11: 铁枪 | F11: 铸造 | H11: 铁枪 | J11: 木棒 | K11: 鹿角 | L11: 刀刃 | N11: =VLOOKUP(J11,ItemData!$A$4:$B$394,2,FALSE) -> 104 | O11: =VLOOKUP(K11,ItemData!$A$4:$B$394,2,FALSE) -> 222 | P11: =VLOOKUP(L11,ItemData!$A$4:$B$394,2,FALSE) -> 274 | S11: =N11&","&O11&IF(P11<>"",","&P11,"")&IF(Q11<>"",","&Q11,"") -> 104,222,274
B12: 1606 | C12: 骑士长枪 | F12: 铸造 | G12: 血腥囚笼 | H12: 血腥之枪 | J12: 铁枪 | K12: 魔族之血 | L12: 银块 | M12: 蜂刺 | N12: =VLOOKUP(J12,ItemData!$A$4:$B$394,2,FALSE) -> 1605 | O12: =VLOOKUP(K12,ItemData!$A$4:$B$394,2,FALSE) -> 259 | P12: =VLOOKUP(L12,ItemData!$A$4:$B$394,2,FALSE) -> 237 | Q12: =VLOOKUP(M12,ItemData!$A$4:$B$394,2,FALSE) -> 239 | S12: =N12&","&O12&IF(P12<>"",","&P12,"")&IF(Q12<>"",","&Q12,"") -> 1605,259,237,239
B13: 1607 | C13: 血腥之枪 | F13: 铸造 | G13: 骑士冲击 | H13: 骑士长枪 | J13: 铁枪 | K13: 骑士之证 | L13: 钢 | N13: =VLOOKUP(J13,ItemData!$A$4:$B$394,2,FALSE) -> 1605 | O13: =VLOOKUP(K13,ItemData!$A$4:$B$394,2,FALSE) -> 275 | P13: =VLOOKUP(L13,ItemData!$A$4:$B$394,2,FALSE) -> 299 | S13: =N13&","&O13&IF(P13<>"",","&P13,"")&IF(Q13<>"",","&Q13,"") -> 1605,275,299
B14: 1608 | C14: 三叉戟 | F14: 铸造 | G14: 龙卷风 | H14: 三叉戟 | J14: 铁枪 | K14: 珊瑚 | L14: 象牙 | M14: 水晶石 | N14: =VLOOKUP(J14,ItemData!$A$4:$B$394,2,FALSE) -> 1605 | O14: =VLOOKUP(K14,ItemData!$A$4:$B$394,2,FALSE) -> 227 | P14: =VLOOKUP(L14,ItemData!$A$4:$B$394,2,FALSE) -> 240 | Q14: =VLOOKUP(M14,ItemData!$A$4:$B$394,2,FALSE) -> 232 | S14: =N14&","&O14&IF(P14<>"",","&P14,"")&IF(Q14<>"",","&Q14,"") -> 1605,227,240,232
B15: 1609 | C15: 战斧 | F15: 铸造 | G15: 奇迹斩 | H15: 秘银长剑 | J15: 银块 | K15: 刀刃 | L15: 咒术药水 | M15: 暮光结晶 | N15: =VLOOKUP(J15,ItemData!$A$4:$B$394,2,FALSE) -> 237 | O15: =VLOOKUP(K15,ItemData!$A$4:$B$394,2,FALSE) -> 274 | P15: =VLOOKUP(L15,ItemData!$A$4:$B$394,2,FALSE) -> 256 | Q15: =VLOOKUP(M15,ItemData!$A$4:$B$394,2,FALSE) -> 285 | S15: =N15&","&O15&IF(P15<>"",","&P15,"")&IF(Q15<>"",","&Q15,"") -> 237,274,256,285
B16: 1610 | C16: 毒蜥之牙 | F16: 铸造 | G16: 幻影突刺 | H16: 幻影长枪 | J16: 幻影水晶 | K16: 铁枪 | L16: 夜之幕 | M16: 风晶石 | N16: =VLOOKUP(J16,ItemData!$A$4:$B$394,2,FALSE) -> 269 | O16: =VLOOKUP(K16,ItemData!$A$4:$B$394,2,FALSE) -> 1605 | P16: =VLOOKUP(L16,ItemData!$A$4:$B$394,2,FALSE) -> 264 | Q16: =VLOOKUP(M16,ItemData!$A$4:$B$394,2,FALSE) -> 208 | S16: =N16&","&O16&IF(P16<>"",","&P16,"")&IF(Q16<>"",","&Q16,"") -> 269,1605,264,208
B17: 1611 | C17: 恶魔之斧 | F17: 铸造 | H17: 战斧 | J17: 钢 | K17: 刀刃 | L17: 兽角 | N17: =VLOOKUP(J17,ItemData!$A$4:$B$394,2,FALSE) -> 299 | O17: =VLOOKUP(K17,ItemData!$A$4:$B$394,2,FALSE) -> 274 | P17: =VLOOKUP(L17,ItemData!$A$4:$B$394,2,FALSE) -> 241 | S17: =N17&","&O17&IF(P17<>"",","&P17,"")&IF(Q17<>"",","&Q17,"") -> 299,274,241
B18: 1612 | C18: 蛇皮鞭 | F18: 铸造 | G18: 剧毒风暴 | H18: 毒蜥之牙 | J18: 战斧 | K18: 毒淤泥 | L18: 狼牙 | N18: =VLOOKUP(J18,ItemData!$A$4:$B$394,2,FALSE) -> 1609 | O18: =VLOOKUP(K18,ItemData!$A$4:$B$394,2,FALSE) -> 254 | P18: =VLOOKUP(L18,ItemData!$A$4:$B$394,2,FALSE) -> 211 | S18: =N18&","&O18&IF(P18<>"",","&P18,"")&IF(Q18<>"",","&Q18,"") -> 1609,254,211
B19: 1613 | C19: 藤鞭 | F19: 铸造 | G19: 恶魔幻影 | H19: 恶魔之斧 | J19: 战斧 | K19: 魔族之血 | L19: 人狼之证 | M19: 石化之眼 | N19: =VLOOKUP(J19,ItemData!$A$4:$B$394,2,FALSE) -> 1609 | O19: =VLOOKUP(K19,ItemData!$A$4:$B$394,2,FALSE) -> 259 | P19: =VLOOKUP(L19,ItemData!$A$4:$B$394,2,FALSE) -> 258 | Q19: =VLOOKUP(M19,ItemData!$A$4:$B$394,2,FALSE) -> 263 | S19: =N19&","&O19&IF(P19<>"",","&P19,"")&IF(Q19<>"",","&Q19,"") -> 1609,259,258,263
B20: 1614 | C20: 女王鞭 | F20: 铸造 | G20: 暴风雪 | H20: 暴雪斧 | J20: 战斧 | K20: 雪球 | L20: 冰晶石 | M20: 寒冰气息 | N20: =VLOOKUP(J20,ItemData!$A$4:$B$394,2,FALSE) -> 1609 | O20: =VLOOKUP(K20,ItemData!$A$4:$B$394,2,FALSE) -> 253 | P20: =VLOOKUP(L20,ItemData!$A$4:$B$394,2,FALSE) -> 260 | Q20: =VLOOKUP(M20,ItemData!$A$4:$B$394,2,FALSE) -> 267 | S20: =N20&","&O20&IF(P20<>"",","&P20,"")&IF(Q20<>"",","&Q20,"") -> 1609,253,260,267
B21: 1615 | C21: 蛇牙鞭 | F21: 缝纫 | H21: 蛇皮鞭 | J21: 蛇皮 | K21: 马尾 | L21: 蛛丝 | N21: =VLOOKUP(J21,ItemData!$A$4:$B$394,2,FALSE) -> 238 | O21: =VLOOKUP(K21,ItemData!$A$4:$B$394,2,FALSE) -> 276 | P21: =VLOOKUP(L21,ItemData!$A$4:$B$394,2,FALSE) -> 214 | S21: =N21&","&O21&IF(P21<>"",","&P21,"")&IF(Q21<>"",","&Q21,"") -> 238,276,214
B22: 1616 | C22: 暴雪斧 | F22: 缝纫 | H22: 藤鞭 | J22: 植物的藤 | K22: 马尾 | L22: 蛛丝 | N22: =VLOOKUP(J22,ItemData!$A$4:$B$394,2,FALSE) -> 221 | O22: =VLOOKUP(K22,ItemData!$A$4:$B$394,2,FALSE) -> 276 | P22: =VLOOKUP(L22,ItemData!$A$4:$B$394,2,FALSE) -> 214 | S22: =N22&","&O22&IF(P22<>"",","&P22,"")&IF(Q22<>"",","&Q22,"") -> 221,276,214
B23: 1617 | C23: 秘银长剑 | F23: 缝纫 | G23: 女王之春 | H23: 女王鞭 | J23: 藤鞭 | K23: 尖刺 | L23: 幽魂 | N23: =VLOOKUP(J23,ItemData!$A$4:$B$394,2,FALSE) -> #N/A | O23: =VLOOKUP(K23,ItemData!$A$4:$B$394,2,FALSE) -> 213 | P23: =VLOOKUP(L23,ItemData!$A$4:$B$394,2,FALSE) -> 246 | S23: =N23&","&O23&IF(P23<>"",","&P23,"")&IF(Q23<>"",","&Q23,"") -> #N/A
B24: 1618 | C24: 幻影长枪 | F24: 缝纫 | G24: 刺颈鞭挞 | H24: 蛇牙鞭 | J24: 蛇皮鞭 | K24: 狼牙 | L24: 蛇皮鞭 | N24: =VLOOKUP(J24,ItemData!$A$4:$B$394,2,FALSE) -> 1612 | O24: =VLOOKUP(K24,ItemData!$A$4:$B$394,2,FALSE) -> 211 | P24: =VLOOKUP(L24,ItemData!$A$4:$B$394,2,FALSE) -> 1612 | S24: =N24&","&O24&IF(P24<>"",","&P24,"")&IF(Q24<>"",","&Q24,"") -> 1612,211,1612
B25: 1619 | C25: 雷神之鞭 | F25: 铸造 | G25: 雷暴 | H25: 雷神之鞭 | J25: 雷鸣宝珠 | K25: 电偶瓶 | L25: 蜂刺 | M25: 女王鞭 | N25: =VLOOKUP(J25,ItemData!$A$4:$B$394,2,FALSE) -> 270 | O25: =VLOOKUP(K25,ItemData!$A$4:$B$394,2,FALSE) -> 225 | P25: =VLOOKUP(L25,ItemData!$A$4:$B$394,2,FALSE) -> 239 | Q25: =VLOOKUP(M25,ItemData!$A$4:$B$394,2,FALSE) -> #N/A | S25: =N25&","&O25&IF(P25<>"",","&P25,"")&IF(Q25<>"",","&Q25,"") -> #N/A
B26: 1620 | C26: 死亡之鞭 | F26: 铸造 | G26: 幽冥黑洞 | H26: 死亡之鞭 | J26: 脏绷带 | K26: 亡者之土 | L26: 寒冰火种 | M26: 蛇牙鞭 | N26: =VLOOKUP(J26,ItemData!$A$4:$B$394,2,FALSE) -> 245 | O26: =VLOOKUP(K26,ItemData!$A$4:$B$394,2,FALSE) -> 255 | P26: =VLOOKUP(L26,ItemData!$A$4:$B$394,2,FALSE) -> 268 | Q26: =VLOOKUP(M26,ItemData!$A$4:$B$394,2,FALSE) -> 1615 | S26: =N26&","&O26&IF(P26<>"",","&P26,"")&IF(Q26<>"",","&Q26,"") -> 245,255,268,1615
B27: 1650 | C27: 布衣 | F27: 缝纫 | H27: 布衣 | J27: 布片 | K27: 毛线 | N27: =VLOOKUP(J27,ItemData!$A$4:$B$394,2,FALSE) -> 204 | O27: =VLOOKUP(K27,ItemData!$A$4:$B$394,2,FALSE) -> 277 | S27: =N27&","&O27&IF(P27<>"",","&P27,"")&IF(Q27<>"",","&Q27,"") -> 204,277
B28: 1651 | C28: 皮铠 | F28: 缝纫 | H28: 皮铠 | J28: 皮革 | K28: 粘液 | L28: 蛛丝 | N28: =VLOOKUP(J28,ItemData!$A$4:$B$394,2,FALSE) -> 271 | O28: =VLOOKUP(K28,ItemData!$A$4:$B$394,2,FALSE) -> 278 | P28: =VLOOKUP(L28,ItemData!$A$4:$B$394,2,FALSE) -> 214 | S28: =N28&","&O28&IF(P28<>"",","&P28,"")&IF(Q28<>"",","&Q28,"") -> 271,278,214
B29: 1652 | C29: 锁子甲 | F29: 缝纫 | H29: 锁子甲 | J29: 皮铠 | K29: 珊瑚 | L29: 钢 | N29: =VLOOKUP(J29,ItemData!$A$4:$B$394,2,FALSE) -> 1651 | O29: =VLOOKUP(K29,ItemData!$A$4:$B$394,2,FALSE) -> 227 | P29: =VLOOKUP(L29,ItemData!$A$4:$B$394,2,FALSE) -> 299 | S29: =N29&","&O29&IF(P29<>"",","&P29,"")&IF(Q29<>"",","&Q29,"") -> 1651,227,299
B30: 1653 | C30: 毛皮斗篷 | F30: 缝纫 | H30: 毛皮斗篷 | J30: 皮铠 | K30: 魔兽皮毛 | L30: 鸭绒 | N30: =VLOOKUP(J30,ItemData!$A$4:$B$394,2,FALSE) -> 1651 | O30: =VLOOKUP(K30,ItemData!$A$4:$B$394,2,FALSE) -> 223 | P30: =VLOOKUP(L30,ItemData!$A$4:$B$394,2,FALSE) -> 301 | S30: =N30&","&O30&IF(P30<>"",","&P30,"")&IF(Q30<>"",","&Q30,"") -> 1651,223,301
B31: 1654 | C31: 铁铠甲 | F31: 铸造 | H31: 铁铠甲 | J31: 铁块 | K31: 石英砂 | N31: =VLOOKUP(J31,ItemData!$A$4:$B$394,2,FALSE) -> 298 | O31: =VLOOKUP(K31,ItemData!$A$4:$B$394,2,FALSE) -> 205 | S31: =N31&","&O31&IF(P31<>"",","&P31,"")&IF(Q31<>"",","&Q31,"") -> 298,205
B32: 1655 | C32: 红莲之铠 | F32: 铸造 | H32: 红莲之铠 | J32: 铁铠甲 | K32: 遗骨 | L32: 火晶石 | M32: 魔力之土 | N32: =VLOOKUP(J32,ItemData!$A$4:$B$394,2,FALSE) -> 1654 | O32: =VLOOKUP(K32,ItemData!$A$4:$B$394,2,FALSE) -> 250 | P32: =VLOOKUP(L32,ItemData!$A$4:$B$394,2,FALSE) -> 229 | Q32: =VLOOKUP(M32,ItemData!$A$4:$B$394,2,FALSE) -> 286 | S32: =N32&","&O32&IF(P32<>"",","&P32,"")&IF(Q32<>"",","&Q32,"") -> 1654,250,229,286
B33: 1656 | C33: 铁龟铠 | F33: 铸造 | H33: 铁龟铠 | J33: 龟壳 | K33: 铁铠甲 | L33: 琥珀 | N33: =VLOOKUP(J33,ItemData!$A$4:$B$394,2,FALSE) -> 202 | O33: =VLOOKUP(K33,ItemData!$A$4:$B$394,2,FALSE) -> 1654 | P33: =VLOOKUP(L33,ItemData!$A$4:$B$394,2,FALSE) -> 210 | S33: =N33&","&O33&IF(P33<>"",","&P33,"")&IF(Q33<>"",","&Q33,"") -> 202,1654,210
B34: 1657 | C34: 华丽背心 | F34: 缝纫 | H34: 华丽背心 | J34: 彩色的布 | K34: 彩色羽毛 | L34: 毛线 | M34: 鸭绒 | N34: =VLOOKUP(J34,ItemData!$A$4:$B$394,2,FALSE) -> 272 | O34: =VLOOKUP(K34,ItemData!$A$4:$B$394,2,FALSE) -> 228 | P34: =VLOOKUP(L34,ItemData!$A$4:$B$394,2,FALSE) -> 277 | S34: =N34&","&O34&IF(P34<>"",","&P34,"")&IF(Q34<>"",","&Q34,"") -> 272,228,277
B35: 1658 | C35: 鳞铠 | F35: 缝纫 | H35: 鳞铠 | J35: 鳞片 | K35: 粘液 | L35: 皮革 | N35: =VLOOKUP(J35,ItemData!$A$4:$B$394,2,FALSE) -> 273 | O35: =VLOOKUP(K35,ItemData!$A$4:$B$394,2,FALSE) -> 278 | P35: =VLOOKUP(L35,ItemData!$A$4:$B$394,2,FALSE) -> 271 | S35: =N35&","&O35&IF(P35<>"",","&P35,"")&IF(Q35<>"",","&Q35,"") -> 273,278,271
B36: 1659 | C36: 暗之袍 | F36: 缝纫 | H36: 暗之袍 | J36: 夜之幕 | K36: 毛线 | L36: 亡者之土 | M36: 幽魂 | N36: =VLOOKUP(J36,ItemData!$A$4:$B$394,2,FALSE) -> 264 | O36: =VLOOKUP(K36,ItemData!$A$4:$B$394,2,FALSE) -> 277 | P36: =VLOOKUP(L36,ItemData!$A$4:$B$394,2,FALSE) -> 255 | Q36: =VLOOKUP(M36,ItemData!$A$4:$B$394,2,FALSE) -> 246 | S36: =N36&","&O36&IF(P36<>"",","&P36,"")&IF(Q36<>"",","&Q36,"") -> 264,277,255,246
B37: 1660 | C37: 疾风背心 | F37: 缝纫 | H37: 疾风背心 | J37: 布衣 | K37: 风晶石 | L37: 奇美拉之翼 | N37: =VLOOKUP(J37,ItemData!$A$4:$B$394,2,FALSE) -> 1650 | O37: =VLOOKUP(K37,ItemData!$A$4:$B$394,2,FALSE) -> 208 | P37: =VLOOKUP(L37,ItemData!$A$4:$B$394,2,FALSE) -> 224 | S37: =N37&","&O37&IF(P37<>"",","&P37,"")&IF(Q37<>"",","&Q37,"") -> 1650,208,224
B38: 1661 | C38: 魔法铠甲 | F38: 缝纫 | H38: 魔法铠甲 | J38: 皮铠 | K38: 水晶球 | L38: 金块 | M38: 兽角 | N38: =VLOOKUP(J38,ItemData!$A$4:$B$394,2,FALSE) -> 1651 | O38: =VLOOKUP(K38,ItemData!$A$4:$B$394,2,FALSE) -> 242 | P38: =VLOOKUP(L38,ItemData!$A$4:$B$394,2,FALSE) -> 247 | Q38: =VLOOKUP(M38,ItemData!$A$4:$B$394,2,FALSE) -> 241 | S38: =N38&","&O38&IF(P38<>"",","&P38,"")&IF(Q38<>"",","&Q38,"") -> 1651,242,247,241
B39: 1662 | C39: 钢刃锁甲 | F39: 铸造 | H39: 钢刃锁甲 | J39: 铁铠甲 | K39: 刀刃 | L39: 钢 | M39: 土晶石 | N39: =VLOOKUP(J39,ItemData!$A$4:$B$394,2,FALSE) -> 1654 | O39: =VLOOKUP(K39,ItemData!$A$4:$B$394,2,FALSE) -> 274 | P39: =VLOOKUP(L39,ItemData!$A$4:$B$394,2,FALSE) -> 299 | Q39: =VLOOKUP(M39,ItemData!$A$4:$B$394,2,FALSE) -> 218 | S39: =N39&","&O39&IF(P39<>"",","&P39,"")&IF(Q39<>"",","&Q39,"") -> 1654,274,299,218
B40: 1663 | C40: 丝织长袍 | F40: 缝纫 | H40: 丝织长袍 | J40: 布片 | K40: 蛛丝 | L40: 彩色羽毛 | N40: =VLOOKUP(J40,ItemData!$A$4:$B$394,2,FALSE) -> 204 | O40: =VLOOKUP(K40,ItemData!$A$4:$B$394,2,FALSE) -> 214 | P40: =VLOOKUP(L40,ItemData!$A$4:$B$394,2,FALSE) -> 228 | S40: =N40&","&O40&IF(P40<>"",","&P40,"")&IF(Q40<>"",","&Q40,"") -> 204,214,228
B41: 1664 | C41: 水之羽衣 | F41: 缝纫 | H41: 水之羽衣 | J41: 布衣 | K41: 水晶石 | L41: 防水皮革 | N41: =VLOOKUP(J41,ItemData!$A$4:$B$394,2,FALSE) -> 1650 | O41: =VLOOKUP(K41,ItemData!$A$4:$B$394,2,FALSE) -> 232 | P41: =VLOOKUP(L41,ItemData!$A$4:$B$394,2,FALSE) -> 282 | S41: =N41&","&O41&IF(P41<>"",","&P41,"")&IF(Q41<>"",","&Q41,"") -> 1650,232,282
B42: 1665 | C42: 贵族长裙 | F42: 缝纫 | H42: 贵族长裙 | J42: 华丽背心 | K42: 贵族徽章 | L42: 珍珠 | M42: 金块 | N42: =VLOOKUP(J42,ItemData!$A$4:$B$394,2,FALSE) -> 1657 | O42: =VLOOKUP(K42,ItemData!$A$4:$B$394,2,FALSE) -> 279 | P42: =VLOOKUP(L42,ItemData!$A$4:$B$394,2,FALSE) -> 234 | Q42: =VLOOKUP(M42,ItemData!$A$4:$B$394,2,FALSE) -> 247 | S42: =N42&","&O42&IF(P42<>"",","&P42,"")&IF(Q42<>"",","&Q42,"") -> 1657,279,234,247
B43: 1666 | C43: 幸运之衣 | F43: 缝纫 | H43: 幸运之衣 | J43: 远古的硬币 | K43: 布衣 | L43: 脏绷带 | M43: 暮光结晶 | N43: =VLOOKUP(J43,ItemData!$A$4:$B$394,2,FALSE) -> 248 | O43: =VLOOKUP(K43,ItemData!$A$4:$B$394,2,FALSE) -> 1650 | P43: =VLOOKUP(L43,ItemData!$A$4:$B$394,2,FALSE) -> 245 | Q43: =VLOOKUP(M43,ItemData!$A$4:$B$394,2,FALSE) -> 285 | S43: =N43&","&O43&IF(P43<>"",","&P43,"")&IF(Q43<>"",","&Q43,"") -> 248,1650,245,285
B44: 1700 | C44: 布鞋 | F44: 缝纫 | H44: 布鞋 | J44: 布片 | K44: 兔子脚 | L44: 粘液 | N44: =VLOOKUP(J44,ItemData!$A$4:$B$394,2,FALSE) -> 204 | O44: =VLOOKUP(K44,ItemData!$A$4:$B$394,2,FALSE) -> 302 | P44: =VLOOKUP(L44,ItemData!$A$4:$B$394,2,FALSE) -> 278 | S44: =N44&","&O44&IF(P44<>"",","&P44,"")&IF(Q44<>"",","&Q44,"") -> 204,302,278
...

Sheet Sheet3
E5: 长剑 | G5: =$I5&","&$J5&","&$K5&","&$L5 -> 铁块,刀刃,, | I5: 铁块 | J5: 刀刃 | N5: 铸造,废铁,焦炭, | T5: 铸造,废铁,焦炭, | U5: 刀刃 | Z5: =T5&","&U5&","&V5&","&W5 -> 铸造,废铁,焦炭,,刀刃,,
E6: 诅咒之剑 | G6: =$I6&","&$J6&","&$K6&","&$L6 -> 长剑,眼球,诅咒宝珠, | I6: 长剑 | J6: 眼球 | K6: 诅咒宝珠 | N6: 铁块,刀刃,, | T6: 铁块,刀刃,, | U6: 眼球 | V6: 诅咒宝珠 | Z6: =T6&","&U6&","&V6&","&W6 -> 铁块,刀刃,,,眼球,诅咒宝珠,
E7: 烈焰之刃 | G7: =$I7&","&$J7&","&$K7&","&$L7 -> 长剑,火晶石,石英砂,白磷粉末 | I7: 长剑 | J7: 火晶石 | K7: 石英砂 | L7: 白磷粉末 | N7: 铁块,刀刃,, | T7: 铁块,刀刃,, | U7: 火晶石 | V7: 石英砂 | W7: 白磷粉末 | Z7: =T7&","&U7&","&V7&","&W7 -> 铁块,刀刃,,,火晶石,石英砂,白磷粉末
E8: 大地之剑 | G8: =$I8&","&$J8&","&$K8&","&$L8 -> 长剑,土晶石,钢,粘土 | I8: 长剑 | J8: 土晶石 | K8: 钢 | L8: 粘土 | N8: 铁块,刀刃,, | P8: 铸造,铁块,焦炭, | T8: 铁块,刀刃,, | U8: 土晶石 | V8: 铸造,铁块,焦炭, | W8: 粘土 | Z8: =T8&","&U8&","&V8&","&W8 -> 铁块,刀刃,,,土晶石,铸造,铁块,焦炭,,粘土
E9: 冰之刃 | G9: =$I9&","&$J9&","&$K9&","&$L9 -> 长剑,冰晶石,冰的结晶,雪球 | I9: 长剑 | J9: 冰晶石 | K9: 冰的结晶 | L9: 雪球 | N9: 铁块,刀刃,, | T9: 铁块,刀刃,, | U9: 冰晶石 | V9: 冰的结晶 | W9: 雪球 | Z9: =T9&","&U9&","&V9&","&W9 -> 铁块,刀刃,,,冰晶石,冰的结晶,雪球
E10: 铁枪 | G10: =$I10&","&$J10&","&$K10&","&$L10 -> 木棒,铁块,刀刃, | I10: 木棒 | J10: 铁块 | K10: 刀刃 | O10: 铸造,废铁,焦炭, | T10: 木棒 | U10: 铸造,废铁,焦炭, | V10: 刀刃 | Z10: =T10&","&U10&","&V10&","&W10 -> 木棒,铸造,废铁,焦炭,,刀刃,
E11: 血腥之枪 | G11: =$I11&","&$J11&","&$K11&","&$L11 -> 铁枪,魔族之血,银块,蜂刺 | I11: 铁枪 | J11: 魔族之血 | K11: 银块 | L11: 蜂刺 | N11: 木棒,铁块,刀刃, | T11: 木棒,铁块,刀刃, | U11: 魔族之血 | V11: 银块 | W11: 蜂刺 | Z11: =T11&","&U11&","&V11&","&W11 -> 木棒,铁块,刀刃,,魔族之血,银块,蜂刺
E12: 骑士长枪 | G12: =$I12&","&$J12&","&$K12&","&$L12 -> 铁枪,骑士之证,钢, | I12: 铁枪 | J12: 骑士之证 | K12: 钢 | N12: 木棒,铁块,刀刃, | P12: 铸造,铁块,焦炭, | T12: 木棒,铁块,刀刃, | U12: 骑士之证 | V12: 铸造,铁块,焦炭, | Z12: =T12&","&U12&","&V12&","&W12 -> 木棒,铁块,刀刃,,骑士之证,铸造,铁块,焦炭,,
E13: 三叉戟 | G13: =$I13&","&$J13&","&$K13&","&$L13 -> 铁枪,珊瑚,象牙,水晶石 | I13: 铁枪 | J13: 珊瑚 | K13: 象牙 | L13: 水晶石 | N13: 木棒,铁块,刀刃, | T13: 木棒,铁块,刀刃, | U13: 珊瑚 | V13: 象牙 | W13: 水晶石 | Z13: =T13&","&U13&","&V13&","&W13 -> 木棒,铁块,刀刃,,珊瑚,象牙,水晶石
E14: 秘银长剑 | G14: =$I14&","&$J14&","&$K14&","&$L14 -> 银块,刀刃,咒术药水,暮光结晶 | I14: 银块 | J14: 刀刃 | K14: 咒术药水 | L14: 暮光结晶 | T14: 银块 | U14: 刀刃 | V14: 咒术药水 | W14: 暮光结晶 | Z14: =T14&","&U14&","&V14&","&W14 -> 银块,刀刃,咒术药水,暮光结晶
E15: 幻影长枪 | G15: =$I15&","&$J15&","&$K15&","&$L15 -> 幻影水晶,铁枪,夜之幕,风晶石 | I15: 幻影水晶 | J15: 铁枪 | K15: 夜之幕 | L15: 风晶石 | O15: 木棒,铁块,刀刃, | T15: 幻影水晶 | U15: 木棒,铁块,刀刃, | V15: 夜之幕 | W15: 风晶石 | Z15: =T15&","&U15&","&V15&","&W15 -> 幻影水晶,木棒,铁块,刀刃,,夜之幕,风晶石
E16: 战斧 | G16: =$I16&","&$J16&","&$K16&","&$L16 -> 钢,刀刃,兽角, | I16: 钢 | J16: 刀刃 | K16: 兽角 | N16: 铸造,铁块,焦炭, | T16: 铸造,铁块,焦炭, | U16: 刀刃 | V16: 兽角 | Z16: =T16&","&U16&","&V16&","&W16 -> 铸造,铁块,焦炭,,刀刃,兽角,
E17: 毒蜥之牙 | G17: =$I17&","&$J17&","&$K17&","&$L17 -> 战斧,毒淤泥,狼牙, | I17: 战斧 | J17: 毒淤泥 | K17: 狼牙 | N17: 钢,刀刃,兽角, | T17: 钢,刀刃,兽角, | U17: 毒淤泥 | V17: 狼牙 | Z17: =T17&","&U17&","&V17&","&W17 -> 钢,刀刃,兽角,,毒淤泥,狼牙,
E18: 恶魔之斧 | G18: =$I18&","&$J18&","&$K18&","&$L18 -> 战斧,魔族之血,人狼之证,石化之眼 | I18: 战斧 | J18: 魔族之血 | K18: 人狼之证 | L18: 石化之眼 | N18: 钢,刀刃,兽角, | T18: 钢,刀刃,兽角, | U18: 魔族之血 | V18: 人狼之证 | W18: 石化之眼 | Z18: =T18&","&U18&","&V18&","&W18 -> 钢,刀刃,兽角,,魔族之血,人狼之证,石化之眼
E19: 暴雪斧 | G19: =$I19&","&$J19&","&$K19&","&$L19 -> 战斧,雪球,冰晶石,寒冰气息 | I19: 战斧 | J19: 雪球 | K19: 冰晶石 | L19: 寒冰气息 | N19: 钢,刀刃,兽角, | T19: 钢,刀刃,兽角, | U19: 雪球 | V19: 冰晶石 | W19: 寒冰气息 | Z19: =T19&","&U19&","&V19&","&W19 -> 钢,刀刃,兽角,,雪球,冰晶石,寒冰气息
E20: 蛇皮鞭 | G20: =$I20&","&$J20&","&$K20&","&$L20 -> 蛇皮,马尾,蛛丝, | I20: 蛇皮 | J20: 马尾 | K20: 蛛丝 | T20: 蛇皮 | U20: 马尾 | V20: 蛛丝 | Z20: =T20&","&U20&","&V20&","&W20 -> 蛇皮,马尾,蛛丝,
E21: 藤鞭 | G21: =$I21&","&$J21&","&$K21&","&$L21 -> 植物的藤,马尾,蛛丝, | I21: 植物的藤 | J21: 马尾 | K21: 蛛丝 | T21: 植物的藤 | U21: 马尾 | V21: 蛛丝 | Z21: =T21&","&U21&","&V21&","&W21 -> 植物的藤,马尾,蛛丝,
E22: 女王鞭 | G22: =$I22&","&$J22&","&$K22&","&$L22 -> 藤鞭,尖刺,幽魂, | I22: 藤鞭 | J22: 尖刺 | K22: 幽魂 | N22: 植物的藤,马尾,蛛丝, | T22: 植物的藤,马尾,蛛丝, | U22: 尖刺 | V22: 幽魂 | Z22: =T22&","&U22&","&V22&","&W22 -> 植物的藤,马尾,蛛丝,,尖刺,幽魂,
E23: 蛇牙鞭 | G23: =$I23&","&$J23&","&$K23&","&$L23 -> 蛇皮鞭,狼牙,, | I23: 蛇皮鞭 | J23: 狼牙 | N23: 蛇皮,马尾,蛛丝, | P23: 蛇皮,马尾,蛛丝, | T23: 蛇皮,马尾,蛛丝, | U23: 狼牙 | V23: 蛇皮,马尾,蛛丝, | Z23: =T23&","&U23&","&V23&","&W23 -> 蛇皮,马尾,蛛丝,,狼牙,蛇皮,马尾,蛛丝,,
E24: 雷神之鞭 | G24: =$I24&","&$J24&","&$K24&","&$L24 -> 雷鸣宝珠,电偶瓶,蜂刺,女王鞭 | I24: 雷鸣宝珠 | J24: 电偶瓶 | K24: 蜂刺 | L24: 女王鞭 | Q24: 植物的藤,马尾,蛛丝,尖刺,幽魂, | T24: 雷鸣宝珠 | U24: 电偶瓶 | V24: 蜂刺 | W24: 植物的藤,马尾,蛛丝,尖刺,幽魂, | Z24: =T24&","&U24&","&V24&","&W24 -> 雷鸣宝珠,电偶瓶,蜂刺,植物的藤,马尾,蛛丝,尖刺,幽魂,
E25: 死亡之鞭 | G25: =$I25&","&$J25&","&$K25&","&$L25 -> 脏绷带,亡者之土,寒冰火种,蛇牙鞭 | I25: 脏绷带 | J25: 亡者之土 | K25: 寒冰火种 | L25: 蛇牙鞭 | Q25: 蛇皮,马尾,蛛丝,,狼牙, | T25: 脏绷带 | U25: 亡者之土 | V25: 寒冰火种 | W25: 蛇皮,马尾,蛛丝,,狼牙, | Z25: =T25&","&U25&","&V25&","&W25 -> 脏绷带,亡者之土,寒冰火种,蛇皮,马尾,蛛丝,,狼牙,
E26: 布衣 | G26: =$I26&","&$J26&","&$K26&","&$L26 -> 布片,毛线,, | I26: 布片 | J26: 毛线 | N26: 纺织,毛线,, | O26: 纺线,羊毛,, | T26: 纺织,毛线,, | U26: 纺线,羊毛,, | Z26: =T26&","&U26&","&V26&","&W26 -> 纺织,毛线,,,纺线,羊毛,,,,
E27: 皮铠 | G27: =$I27&","&$J27&","&$K27&","&$L27 -> 皮革,粘液,蛛丝, | I27: 皮革 | J27: 粘液 | K27: 蛛丝 | N27: 鞣制,兽皮,, | T27: 鞣制,兽皮,, | U27: 粘液 | V27: 蛛丝 | Z27: =T27&","&U27&","&V27&","&W27 -> 鞣制,兽皮,,,粘液,蛛丝,
E28: 锁子甲 | G28: =$I28&","&$J28&","&$K28&","&$L28 -> 皮铠,珊瑚,钢, | I28: 皮铠 | J28: 珊瑚 | K28: 钢 | N28: 皮革,粘液,蛛丝, | P28: 铸造,铁块,焦炭, | T28: 皮革,粘液,蛛丝, | U28: 珊瑚 | V28: 铸造,铁块,焦炭, | Z28: =T28&","&U28&","&V28&","&W28 -> 皮革,粘液,蛛丝,,珊瑚,铸造,铁块,焦炭,,
E29: 毛皮斗篷 | G29: =$I29&","&$J29&","&$K29&","&$L29 -> 皮铠,魔兽皮毛,羊毛, | I29: 皮铠 | J29: 魔兽皮毛 | K29: 羊毛 | N29: 皮革,粘液,蛛丝, | T29: 皮革,粘液,蛛丝, | U29: 魔兽皮毛 | V29: 羊毛 | Z29: =T29&","&U29&","&V29&","&W29 -> 皮革,粘液,蛛丝,,魔兽皮毛,羊毛,
E30: 铁铠甲 | G30: =$I30&","&$J30&","&$K30&","&$L30 -> 铁块,石英砂,, | I30: 铁块 | J30: 石英砂 | N30: 铸造,废铁,焦炭, | T30: 铸造,废铁,焦炭, | U30: 石英砂 | Z30: =T30&","&U30&","&V30&","&W30 -> 铸造,废铁,焦炭,,石英砂,,
E31: 红莲之铠 | G31: =$I31&","&$J31&","&$K31&","&$L31 -> 铁铠甲,遗骨,火晶石,魔力之土 | I31: 铁铠甲 | J31: 遗骨 | K31: 火晶石 | L31: 魔力之土 | N31: 铁块,石英砂,, | T31: 铁块,石英砂,, | U31: 遗骨 | V31: 火晶石 | W31: 魔力之土 | Z31: =T31&","&U31&","&V31&","&W31 -> 铁块,石英砂,,,遗骨,火晶石,魔力之土
E32: 铁龟铠 | G32: =$I32&","&$J32&","&$K32&","&$L32 -> 龟壳,铁铠甲,琥珀, | I32: 龟壳 | J32: 铁铠甲 | K32: 琥珀 | O32: 铁块,石英砂,, | T32: 龟壳 | U32: 铁块,石英砂,, | V32: 琥珀 | Z32: =T32&","&U32&","&V32&","&W32 -> 龟壳,铁块,石英砂,,,琥珀,
E33: 华丽背心 | G33: =$I33&","&$J33&","&$K33&","&$L33 -> 彩色的布,彩色羽毛,毛线, | I33: 彩色的布 | J33: 彩色羽毛 | K33: 毛线 | P33: 纺线,羊毛,, | T33: 彩色的布 | U33: 彩色羽毛 | V33: 纺线,羊毛,, | Z33: =T33&","&U33&","&V33&","&W33 -> 彩色的布,彩色羽毛,纺线,羊毛,,,
E34: 鳞铠 | G34: =$I34&","&$J34&","&$K34&","&$L34 -> 鳞片,粘液,皮革, | I34: 鳞片 | J34: 粘液 | K34: 皮革 | P34: 鞣制,兽皮,, | T34: 鳞片 | U34: 粘液 | V34: 鞣制,兽皮,, | Z34: =T34&","&U34&","&V34&","&W34 -> 鳞片,粘液,鞣制,兽皮,,,
E35: 暗之袍 | G35: =$I35&","&$J35&","&$K35&","&$L35 -> 夜之幕,毛线,亡者之土,幽魂 | I35: 夜之幕 | J35: 毛线 | K35: 亡者之土 | L35: 幽魂 | O35: 纺线,羊毛,, | T35: 夜之幕 | U35: 纺线,羊毛,, | V35: 亡者之土 | W35: 幽魂 | Z35: =T35&","&U35&","&V35&","&W35 -> 夜之幕,纺线,羊毛,,,亡者之土,幽魂
E36: 疾风背心 | G36: =$I36&","&$J36&","&$K36&","&$L36 -> 布衣,风晶石,奇美拉之翼, | I36: 布衣 | J36: 风晶石 | K36: 奇美拉之翼 | N36: 布片,毛线,, | T36: 布片,毛线,, | U36: 风晶石 | V36: 奇美拉之翼 | Z36: =T36&","&U36&","&V36&","&W36 -> 布片,毛线,,,风晶石,奇美拉之翼,
E37: 魔法铠甲 | G37: =$I37&","&$J37&","&$K37&","&$L37 -> 皮铠,水晶球,金块,兽角 | I37: 皮铠 | J37: 水晶球 | K37: 金块 | L37: 兽角 | N37: 皮革,粘液,蛛丝, | T37: 皮革,粘液,蛛丝, | U37: 水晶球 | V37: 金块 | W37: 兽角 | Z37: =T37&","&U37&","&V37&","&W37 -> 皮革,粘液,蛛丝,,水晶球,金块,兽角
E38: 钢刃锁甲 | G38: =$I38&","&$J38&","&$K38&","&$L38 -> 铁铠甲,刀刃,钢,土晶石 | I38: 铁铠甲 | J38: 刀刃 | K38: 钢 | L38: 土晶石 | N38: 铁块,石英砂,, | P38: 铸造,铁块,焦炭, | T38: 铁块,石英砂,, | U38: 刀刃 | V38: 铸造,铁块,焦炭, | W38: 土晶石 | Z38: =T38&","&U38&","&V38&","&W38 -> 铁块,石英砂,,,刀刃,铸造,铁块,焦炭,,土晶石
E39: 丝织长袍 | G39: =$I39&","&$J39&","&$K39&","&$L39 -> 布片,蛛丝,彩色羽毛, | I39: 布片 | J39: 蛛丝 | K39: 彩色羽毛 | N39: 纺织,毛线,, | T39: 纺织,毛线,, | U39: 蛛丝 | V39: 彩色羽毛 | Z39: =T39&","&U39&","&V39&","&W39 -> 纺织,毛线,,,蛛丝,彩色羽毛,
E40: 水之羽衣 | G40: =$I40&","&$J40&","&$K40&","&$L40 -> 布衣,水晶石,防水皮革, | I40: 布衣 | J40: 水晶石 | K40: 防水皮革 | N40: 布片,毛线,, | T40: 布片,毛线,, | U40: 水晶石 | V40: 防水皮革 | Z40: =T40&","&U40&","&V40&","&W40 -> 布片,毛线,,,水晶石,防水皮革,
E41: 贵族长裙 | G41: =$I41&","&$J41&","&$K41&","&$L41 -> 华丽背心,贵族徽章,珍珠,金块 | I41: 华丽背心 | J41: 贵族徽章 | K41: 珍珠 | L41: 金块 | N41: 彩色的布,彩色羽毛,毛线, | T41: 彩色的布,彩色羽毛,毛线, | U41: 贵族徽章 | V41: 珍珠 | W41: 金块 | Z41: =T41&","&U41&","&V41&","&W41 -> 彩色的布,彩色羽毛,毛线,,贵族徽章,珍珠,金块
E42: 幸运之衣 | G42: =$I42&","&$J42&","&$K42&","&$L42 -> 远古的硬币,布衣,脏绷带,暮光结晶 | I42: 远古的硬币 | J42: 布衣 | K42: 脏绷带 | L42: 暮光结晶 | O42: 布片,毛线,, | T42: 远古的硬币 | U42: 布片,毛线,, | V42: 脏绷带 | W42: 暮光结晶 | Z42: =T42&","&U42&","&V42&","&W42 -> 远古的硬币,布片,毛线,,,脏绷带,暮光结晶
E43: 布鞋 | G43: =$I43&","&$J43&","&$K43&","&$L43 -> 布片,鹿角,粘液, | I43: 布片 | J43: 鹿角 | K43: 粘液 | N43: 纺织,毛线,, | T43: 纺织,毛线,, | U43: 鹿角 | V43: 粘液 | Z43: =T43&","&U43&","&V43&","&W43 -> 纺织,毛线,,,鹿角,粘液,
E44: 皮鞋 | G44: =$I44&","&$J44&","&$K44&","&$L44 -> 皮革,鹿角,粘液, | I44: 皮革 | J44: 鹿角 | K44: 粘液 | N44: 鞣制,兽皮,, | T44: 鞣制,兽皮,, | U44: 鹿角 | V44: 粘液 | Z44: =T44&","&U44&","&V44&","&W44 -> 鞣制,兽皮,,,鹿角,粘液,
...

Sheet Sheet1
C3: 1 | D3: 2 | E3: 3 | F3: 4 | G3: 5 | H3: 6 | I3: 7 | J3: 8
D4: hp | E4: mp | F4: 体力 | G4: 攻击buff | H4: 防御buff | I4: 速度buff | J4: 幸运buff
C5: 腌芜菁 | D5: 15
C6: 蔬菜沙拉 | D6: 15
C7: 三明治 | F7: 10 | I7: 7
C8: 腌萝卜 | D8: 20
C9: 拉面 | F9: 20
C10: 蜂蜜蛋糕 | F10: 20
C11: 披萨 | F11: 30
C12: 腌黄瓜 | D12: 25
C13: 烤西兰花 | D13: 35
C14: 水煮蛋 | E14: 10
C15: 烤肉串 | H15: 10
C16: 饭团 | F16: 30
C17: 面包 | F17: 40
C18: 烤海苔 | I18: 10
C19: 烤肉饼 | H19: 15
C20: 汉堡 | F20: 60
C21: 辣蟹堡 | E21: 20
C22: 土豆泥 | D22: 40
C23: 海鲜饭 | F23: 80
C24: 烤玉米 | D24: 50
C25: 蔬菜汁 | I25: 15
C26: 西瓜果汁 | J26: 15
C27: 奇异果汁 | J27: 15
C28: 葡萄汁 | J28: 20
C29: 菠萝汁 | J29: 20
C30: 草莓汁 | J30: 20
C31: 蓝莓汁 | J31: 20
C32: 玉米汁 | I32: 15
C33: 烤蜜薯 | D33: 60
C34: 甜菜汁 | I34: 20
C35: 黄油
C36: 奶酪
C37: 烤茄子 | D37: 70
C38: 饺子 | D38: 80 | E38: 30 | F38: 70
C39: 炖菜 | D39: 100 | E39: 40
C40: 烤芦笋 | D40: 100
C41: 红菜汤 | E41: 50
C42: 豌豆汤 | E42: 60
...
