Workbook

Sheet ItemData
A2: string | B2: int | C2: string | D2: int | E2: int | F2: int | G2: List<int> | H2: List<int> | I2: bool | J2: bool | K2: int | L2: int | M2: int | N2: int | O2: int | P2: int | Q2: int2 | R2: List<int> | S2: List<int> | T2: int | U2: int | V2: int | W2: List<int> | X2: bool | Y2: int | Z2: int | AA2: int | AB2: int | AC2: int | AD2: int | AE2: int | AF2: int | AG2: int | AH2: int | AI2: int | AJ2: string | AK2: string
A3: itemName | B3: id | C3: iconName | D3: type | E3: typeValue | F3: otherType | G3: manufacture | H3: tag | I3: isFresh | J3: itemValue | K3: attributeType | L3: equipLevel | M3: groupCount | N3: shopMoneyType | O3: shopPrice | P3: sellPrice | Q3: range | R3: dropEventId | S3: checkEventId | T3: sceneType | U3: useEventId | V3: fightUseSkill | W3: equipEventId | X3: showProperty | Y3: HP | Z3: MP | AA3: Power | AB3: MaxHP | AC3: MaxMP | AD3: MaxPower | AE3: AT | AF3: DF | AG3: Lucky | AH3: Speed | AI3: Other | AJ3: info | AK3: useInfo
A4: 未知的物品 | B4: 1 | C4: default | D4: -1 | E4: 0 | F4: 0 | H4: 0 | I4: 0 | J4: 0 | K4: 0 | L4: 0 | M4: 0 | N4: 1 | O4: 0 | P4: 10 | T4: 0 | U4: 0 | V4: 0 | X4: false | Y4: 0 | Z4: 0 | AA4: 0 | AB4: 0 | AC4: 0 | AD4: 0 | AE4: 0 | AF4: 0 | AG4: 0 | AH4: 0 | AI4: 0 | AJ4: ????????
A5: 失败的徒手 | B5: 20 | C5: 失败的徒手 | D5: 4 | E5: 0 | F5: 0 | H5: 0 | I5: 0 | J5: 0 | K5: 0 | L5: 0 | M5: 0 | N5: 1 | O5: 0 | P5: 10 | T5: 0 | U5: 0 | V5: 0 | X5: false | Y5: 0 | Z5: 0 | AA5: 0 | AB5: 0 | AC5: 0 | AD5: 0 | AE5: 0 | AF5: 0 | AG5: 0 | AH5: 0 | AI5: 0 | AJ5: 看起来不像是能吃的样子
A6: 失败的搅拌 | B6: 21 | C6: 失败的搅拌 | D6: 4 | E6: 0 | F6: 0 | H6: 0 | I6: 0 | J6: 0 | K6: 0 | L6: 0 | M6: 0 | N6: 1 | O6: 0 | P6: 10 | T6: 0 | U6: 0 | V6: 0 | X6: false | Y6: 0 | Z6: 0 | AA6: 0 | AB6: 0 | AC6: 0 | AD6: 0 | AE6: 0 | AF6: 0 | AG6: 0 | AH6: 0 | AI6: 0 | AJ6: 看起来不像是能吃的样子
A7: 失败的烘烤 | B7: 22 | C7: 失败的烘烤 | D7: 4 | E7: 0 | F7: 0 | H7: 0 | I7: 0 | J7: 0 | K7: 0 | L7: 0 | M7: 0 | N7: 1 | O7: 0 | P7: 10 | T7: 0 | U7: 0 | V7: 0 | X7: false | Y7: 0 | Z7: 0 | AA7: 0 | AB7: 0 | AC7: 0 | AD7: 0 | AE7: 0 | AF7: 0 | AG7: 0 | AH7: 0 | AI7: 0 | AJ7: 看起来不像是能吃的样子
A8: 失败的蒸煮 | B8: 23 | C8: 失败的蒸煮 | D8: 4 | E8: 0 | F8: 0 | H8: 0 | I8: 0 | J8: 0 | K8: 0 | L8: 0 | M8: 0 | N8: 1 | O8: 0 | P8: 10 | T8: 0 | U8: 0 | V8: 0 | X8: false | Y8: 0 | Z8: 0 | AA8: 0 | AB8: 0 | AC8: 0 | AD8: 0 | AE8: 0 | AF8: 0 | AG8: 0 | AH8: 0 | AI8: 0 | AJ8: 看起来不像是能吃的样子
A9: 失败的酿造 | B9: 24 | C9: 失败的酿造 | D9: 4 | E9: 0 | F9: 0 | H9: 0 | I9: 0 | J9: 0 | K9: 0 | L9: 0 | M9: 0 | N9: 1 | O9: 0 | P9: 10 | T9: 0 | U9: 0 | V9: 0 | X9: false | Y9: 0 | Z9: 0 | AA9: 0 | AB9: 0 | AC9: 0 | AD9: 0 | AE9: 0 | AF9: 0 | AG9: 0 | AH9: 0 | AI9: 0 | AJ9: 看起来不像是能吃的样子
A10: 失败的铸造 | B10: 25 | C10: 失败的铸造 | D10: 4 | E10: 0 | F10: 0 | H10: 0 | I10: 0 | J10: 0 | K10: 0 | L10: 0 | M10: 0 | N10: 1 | O10: 0 | P10: 10 | T10: 0 | U10: 0 | V10: 0 | X10: false | Y10: 0 | Z10: 0 | AA10: 0 | AB10: 0 | AC10: 0 | AD10: 0 | AE10: 0 | AF10: 0 | AG10: 0 | AH10: 0 | AI10: 0 | AJ10: 一团杂乱的物体
A11: 失败的缝纫 | B11: 26 | C11: 失败的缝纫 | D11: 4 | E11: 0 | F11: 0 | H11: 0 | I11: 0 | J11: 0 | K11: 0 | L11: 0 | M11: 0 | N11: 1 | O11: 0 | P11: 10 | T11: 0 | U11: 0 | V11: 0 | X11: false | Y11: 0 | Z11: 0 | AA11: 0 | AB11: 0 | AC11: 0 | AD11: 0 | AE11: 0 | AF11: 0 | AG11: 0 | AH11: 0 | AI11: 0 | AJ11: 一团杂乱的物体
A12: 失败的绘写 | B12: 27 | C12: 失败的绘写 | D12: 4 | E12: 0 | F12: 0 | H12: 0 | I12: 0 | J12: 0 | K12: 0 | L12: 0 | M12: 0 | N12: 1 | O12: 0 | P12: 10 | T12: 0 | U12: 0 | V12: 0 | X12: false | Y12: 0 | Z12: 0 | AA12: 0 | AB12: 0 | AC12: 0 | AD12: 0 | AE12: 0 | AF12: 0 | AG12: 0 | AH12: 0 | AI12: 0 | AJ12: 一团杂乱的物体
A13: 传送卷轴 | B13: 11 | C13: 卷轴 | D13: 5 | E13: 0 | F13: 0 | H13: 0 | I13: 0 | J13: 0 | K13: 0 | L13: 0 | M13: 9 | N13: 1 | O13: 1000 | P13: =O13/2 -> 500 | T13: 2 | U13: 7000 | V13: 0 | X13: false | Y13: 0 | Z13: 0 | AA13: 0 | AB13: 0 | AC13: 0 | AD13: 0 | AE13: 0 | AF13: 0 | AG13: 0 | AH13: 0 | AI13: 0 | AJ13: 快速在城镇中移动
A14: 鱼饵 | B14: 12 | C14: 鱼饵 | D14: 5 | E14: 0 | F14: 0 | H14: 0 | I14: 0 | J14: 0 | K14: 0 | L14: 0 | M14: 19 | N14: 1 | O14: 52 | P14: =O14/2 -> 26 | T14: 2 | U14: 0 | V14: 0 | X14: false | Y14: 0 | Z14: 0 | AA14: 0 | AB14: 0 | AC14: 0 | AD14: 0 | AE14: 0 | AF14: 0 | AG14: 0 | AH14: 0 | AI14: 0 | AJ14: 用来引诱鱼类的饵料
A15: 食物配方 | B15: 20 | C15: 食物配方 | D15: 5 | E15: 1000 | F15: 0 | H15: 0 | I15: 0 | J15: 0 | K15: 0 | L15: 0 | M15: 9 | N15: 1 | O15: 500 | P15: =O15/2 -> 250 | T15: 2 | U15: 50 | V15: 0 | X15: false | Y15: 0 | Z15: 0 | AA15: 0 | AB15: 0 | AC15: 0 | AD15: 0 | AE15: 0 | AF15: 0 | AG15: 0 | AH15: 0 | AI15: 0 | AJ15: 未知的食物配方
A16: 酒水配方 | B16: 21 | C16: 酒水配方 | D16: 5 | E16: 1001 | F16: 0 | H16: 0 | I16: 0 | J16: 0 | K16: 0 | L16: 0 | M16: 9 | N16: 1 | O16: 500 | P16: =O16/2 -> 250 | T16: 2 | U16: 50 | V16: 0 | X16: false | Y16: 0 | Z16: 0 | AA16: 0 | AB16: 0 | AC16: 0 | AD16: 0 | AE16: 0 | AF16: 0 | AG16: 0 | AH16: 0 | AI16: 0 | AJ16: 未知的酒水配方
A17: 铸造配方 | B17: 22 | C17: 铸造配方 | D17: 5 | E17: 1002 | F17: 0 | H17: 0 | I17: 0 | J17: 0 | K17: 0 | L17: 0 | M17: 9 | N17: 1 | O17: 500 | P17: =O17/2 -> 250 | T17: 2 | U17: 50 | V17: 0 | X17: false | Y17: 0 | Z17: 0 | AA17: 0 | AB17: 0 | AC17: 0 | AD17: 0 | AE17: 0 | AF17: 0 | AG17: 0 | AH17: 0 | AI17: 0 | AJ17: 未知的铸造配方
A18: 缝纫配方 | B18: 23 | C18: 缝纫配方 | D18: 5 | E18: 1003 | F18: 0 | H18: 0 | I18: 0 | J18: 0 | K18: 0 | L18: 0 | M18: 9 | N18: 1 | O18: 500 | P18: =O18/2 -> 250 | T18: 2 | U18: 50 | V18: 0 | X18: false | Y18: 0 | Z18: 0 | AA18: 0 | AB18: 0 | AC18: 0 | AD18: 0 | AE18: 0 | AF18: 0 | AG18: 0 | AH18: 0 | AI18: 0 | AJ18: 未知的缝纫配方
A19: 书写配方 | B19: 24 | C19: 书写配方 | D19: 5 | E19: 1004 | F19: 0 | H19: 0 | I19: 0 | J19: 0 | K19: 0 | L19: 0 | M19: 9 | N19: 1 | O19: 500 | P19: =O19/2 -> 250 | T19: 2 | U19: 50 | V19: 0 | X19: false | Y19: 0 | Z19: 0 | AA19: 0 | AB19: 0 | AC19: 0 | AD19: 0 | AE19: 0 | AF19: 0 | AG19: 0 | AH19: 0 | AI19: 0 | AJ19: 未知的书写配方
A20: 牧草 | B20: 100 | C20: 牧草 | D20: -1 | E20: 0 | F20: 0 | H20: 10,11,2 | I20: 0 | J20: 0 | K20: 0 | L20: 0 | M20: 29 | N20: 1 | O20: =P20*3 -> 180 | P20: 60 | T20: 0 | U20: 0 | V20: 0 | X20: false | Y20: 0 | Z20: 0 | AA20: 0 | AB20: 0 | AC20: 0 | AD20: 0 | AE20: 0 | AF20: 0 | AG20: 0 | AH20: 0 | AI20: 0 | AJ20: 未成熟的植物制成的鲜嫩可口的饲料
A21: 木材 | B21: 101 | C21: 木材 | D21: 5 | E21: 0 | F21: 0 | G21: 5010 | H21: 10,14,9 | I21: 0 | J21: 0 | K21: 0 | L21: 0 | M21: 29 | N21: 1 | O21: =P21*3 -> 201 | P21: 67 | T21: 0 | U21: 0 | V21: 0 | X21: false | Y21: 0 | Z21: 0 | AA21: 0 | AB21: 0 | AC21: 0 | AD21: 0 | AE21: 0 | AF21: 0 | AG21: 0 | AH21: 0 | AI21: 0 | AJ21: 常见的建造材料
A22: 原木 | B22: 102 | C22: 原木 | D22: 5 | E22: 0 | F22: 0 | G22: 5010 | H22: 10,14,9 | I22: 0 | J22: 0 | K22: 0 | L22: 0 | M22: 9 | N22: 1 | O22: =P22*3 -> 267 | P22: =VLOOKUP(A22,材料!$P$4:$R$85,3,FALSE) -> 89 | T22: 0 | U22: 0 | V22: 0 | X22: false | Y22: 0 | Z22: 0 | AA22: 0 | AB22: 0 | AC22: 0 | AD22: 0 | AE22: 0 | AF22: 0 | AG22: 0 | AH22: 0 | AI22: 0 | AJ22: 未加工过的原始木料
A23: 木柴 | B23: 103 | C23: 木柴 | D23: 5 | E23: 0 | F23: 0 | H23: 10,15 | I23: 0 | J23: 0 | K23: 0 | L23: 0 | M23: 49 | N23: 1 | O23: =P23*3 -> 147 | P23: 49 | T23: 0 | U23: 0 | V23: 0 | X23: false | Y23: 0 | Z23: 0 | AA23: 0 | AB23: 0 | AC23: 0 | AD23: 0 | AE23: 0 | AF23: 0 | AG23: 0 | AH23: 0 | AI23: 0 | AJ23: 细小的碎木条,除了做燃料似乎没有什么用处
A24: 木棒 | B24: 104 | C24: 木棒 | D24: 5 | E24: 0 | F24: 0 | G24: 5008,5010 | H24: 10,9,4 | I24: 0 | J24: 0 | K24: 0 | L24: 0 | M24: 39 | N24: 1 | O24: =P24*3 -> 147 | P24: =VLOOKUP(A24,材料!$P$4:$R$85,3,FALSE) -> 49 | T24: 0 | U24: 0 | V24: 0 | X24: false | Y24: 0 | Z24: 0 | AA24: 0 | AB24: 0 | AC24: 0 | AD24: 0 | AE24: 0 | AF24: 0 | AG24: 0 | AH24: 0 | AI24: 0 | AJ24: 细长结实的木制棍棒,很适合握持
A25: 干草 | B25: 105 | C25: 干草 | D25: 5 | E25: 0 | F25: 0 | G25: 5007 | H25: 10,11,2 | I25: 0 | J25: 0 | K25: 0 | L25: 0 | M25: 39 | N25: 1 | O25: =P25*3 -> 105 | P25: =VLOOKUP(A25,材料!$P$4:$R$85,3,FALSE) -> 35 | T25: 0 | U25: 0 | V25: 0 | X25: false | Y25: 0 | Z25: 0 | AA25: 0 | AB25: 0 | AC25: 0 | AD25: 0 | AE25: 0 | AF25: 0 | AG25: 0 | AH25: 0 | AI25: 0 | AJ25: 廉价的建筑材料
A26: 纯净水 | B26: 200 | C26: 纯净水 | D26: 5 | E26: 0 | F26: 0 | G26: 5002 | H26: 2,9 | I26: 0 | J26: 0 | K26: 0 | L26: 0 | M26: 49 | N26: 1 | O26: =P26*3 -> 75 | P26: 25 | T26: 0 | U26: 0 | V26: 0 | X26: false | Y26: 0 | Z26: 0 | AA26: 0 | AB26: 0 | AC26: 0 | AD26: 0 | AE26: 0 | AF26: 0 | AG26: 0 | AH26: 0 | AI26: 0 | AJ26: 不含杂质的水,用来煮汤最合适了
A27: 石块 | B27: 201 | C27: 石块 | D27: 5 | E27: 0 | F27: 0 | H27: 10,14,9 | I27: 0 | J27: 0 | K27: 0 | L27: 0 | M27: 49 | N27: 1 | O27: =P27*3 -> 75 | P27: =VLOOKUP(A27,材料!$P$4:$R$85,3,FALSE) -> 25 | T27: 0 | U27: 0 | V27: 0 | X27: false | Y27: 0 | Z27: 0 | AA27: 0 | AB27: 0 | AC27: 0 | AD27: 0 | AE27: 0 | AF27: 0 | AG27: 0 | AH27: 0 | AI27: 0 | AJ27: 一个平平无奇的石块.可以用来垒墙
A28: 龟壳 | B28: 202 | C28: 龟壳 | D28: 5 | E28: 0 | F28: 0 | G28: 5008 | H28: 11,9,18 | I28: 0 | J28: 0 | K28: 0 | L28: 0 | M28: 49 | N28: 1 | O28: =P28*3 -> 105 | P28: =VLOOKUP(A28,材料!$P$4:$R$85,3,FALSE) -> 35 | T28: 0 | U28: 0 | V28: 0 | X28: false | Y28: 0 | Z28: 0 | AA28: 0 | AB28: 0 | AC28: 0 | AD28: 0 | AE28: 0 | AF28: 0 | AG28: 0 | AH28: 0 | AI28: 0 | AJ28: 坚固的龟类甲壳,很好的防御材料
A29: 兽皮 | B29: 203 | C29: 兽皮 | D29: 5 | E29: 0 | F29: 0 | G29: 5013,5014 | H29: 11,12,6 | I29: 0 | J29: 0 | K29: 0 | L29: 0 | M29: 49 | N29: 1 | O29: =P29*3 -> 147 | P29: =VLOOKUP(A29,材料!$P$4:$R$85,3,FALSE) -> 49 | T29: 0 | U29: 0 | V29: 0 | X29: false | Y29: 0 | Z29: 0 | AA29: 0 | AB29: 0 | AC29: 0 | AD29: 0 | AE29: 0 | AF29: 0 | AG29: 0 | AH29: 0 | AI29: 0 | AJ29: =VLOOKUP(ItemData!A29,Sheet8!N:O,2,FALSE) -> #N/A
A30: 布片 | B30: 204 | C30: 布片 | D30: 5 | E30: 0 | F30: 0 | G30: 5007 | H30: 12,9,18 | I30: 0 | J30: 0 | K30: 0 | L30: 0 | M30: 49 | N30: 1 | O30: =P30*3 -> 147 | P30: =VLOOKUP(A30,材料!$P$4:$R$85,3,FALSE) -> 49 | T30: 0 | U30: 0 | V30: 0 | X30: false | Y30: 0 | Z30: 0 | AA30: 0 | AB30: 0 | AC30: 0 | AD30: 0 | AE30: 0 | AF30: 0 | AG30: 0 | AH30: 0 | AI30: 0 | AJ30: =VLOOKUP(ItemData!A30,Sheet8!N:O,2,FALSE) -> #N/A
A31: 石英砂 | B31: 205 | C31: 石英砂 | D31: 5 | E31: 0 | F31: 0 | G31: 5008 | H31: 10,13,15 | I31: 0 | J31: 0 | K31: 0 | L31: 0 | M31: 49 | N31: 1 | O31: =P31*3 -> 1065 | P31: =VLOOKUP(A31,材料!$P$4:$R$85,3,FALSE) -> 355 | T31: 0 | U31: 0 | V31: 0 | X31: false | Y31: 0 | Z31: 0 | AA31: 0 | AB31: 0 | AC31: 0 | AD31: 0 | AE31: 0 | AF31: 0 | AG31: 0 | AH31: 0 | AI31: 0 | AJ31: 纯净的碎砂,有很多用处
A32: 草药茶 | B32: 207 | C32: 草药茶 | D32: 5 | E32: 0 | F32: 0 | G32: 5002,5006 | H32: 10,15,26 | I32: 0 | J32: 0 | K32: 0 | L32: 0 | M32: 49 | N32: 1 | O32: =P32*3 -> 537 | P32: =VLOOKUP(A32,材料!$P$4:$R$85,3,FALSE) -> 179 | T32: 0 | U32: 0 | V32: 0 | X32: false | Y32: 0 | Z32: 0 | AA32: 0 | AB32: 0 | AC32: 0 | AD32: 0 | AE32: 0 | AF32: 0 | AG32: 0 | AH32: 0 | AI32: 0 | AJ32: 常见的野生植物,对身体有很多好处
A33: 风晶石 | B33: 208 | C33: 风晶石 | D33: 5 | E33: 0 | F33: 0 | G33: 5007,5008 | H33: 13,17,29 | I33: 0 | J33: 0 | K33: 0 | L33: 0 | M33: 49 | N33: 1 | O33: =P33*3 -> 537 | P33: =VLOOKUP(A33,材料!$P$4:$R$85,3,FALSE) -> 179 | T33: 0 | U33: 0 | V33: 0 | X33: false | Y33: 0 | Z33: 0 | AA33: 0 | AB33: 0 | AC33: 0 | AD33: 0 | AE33: 0 | AF33: 0 | AG33: 0 | AH33: 0 | AI33: 0 | AJ33: 风元素聚焦的晶石
A34: 琥珀 | B34: 210 | C34: 琥珀 | D34: 5 | E34: 0 | F34: 0 | G34: 5008,5006 | H34: 13,18,10 | I34: 0 | J34: 0 | K34: 0 | L34: 0 | M34: 49 | N34: 1 | O34: =P34*3 -> 651 | P34: =VLOOKUP(A34,材料!$P$4:$R$85,3,FALSE) -> 217 | T34: 0 | U34: 0 | V34: 0 | X34: false | Y34: 0 | Z34: 0 | AA34: 0 | AB34: 0 | AC34: 0 | AD34: 0 | AE34: 0 | AF34: 0 | AG34: 0 | AH34: 0 | AI34: 0 | AJ34: 蕴含着奇怪能量的宝石
A35: 狼牙 | B35: 211 | C35: 狼牙 | D35: 5 | E35: 0 | F35: 0 | G35: 5007,5008 | H35: 11,4,18 | I35: 0 | J35: 0 | K35: 0 | L35: 0 | M35: 49 | N35: 1 | O35: =P35*3 -> 777 | P35: =VLOOKUP(A35,材料!$P$4:$R$85,3,FALSE) -> 259 | T35: 0 | U35: 0 | V35: 0 | X35: false | Y35: 0 | Z35: 0 | AA35: 0 | AB35: 0 | AC35: 0 | AD35: 0 | AE35: 0 | AF35: 0 | AG35: 0 | AH35: 0 | AI35: 0 | AJ35: =VLOOKUP(ItemData!A35,Sheet8!N:O,2,FALSE) -> #N/A
A36: 粘土 | B36: 212 | C36: 粘土 | D36: 5 | E36: 0 | F36: 0 | G36: 5008 | H36: 10,14,15 | I36: 0 | J36: 0 | K36: 0 | L36: 0 | M36: 49 | N36: 1 | O36: =P36*3 -> 1995 | P36: =VLOOKUP(A36,材料!$P$4:$R$85,3,FALSE) -> 665 | T36: 0 | U36: 0 | V36: 0 | X36: false | Y36: 0 | Z36: 0 | AA36: 0 | AB36: 0 | AC36: 0 | AD36: 0 | AE36: 0 | AF36: 0 | AG36: 0 | AH36: 0 | AI36: 0 | AJ36: 常见的材料,一些武器的制作却离不开它
A37: 尖刺 | B37: 213 | C37: 尖刺 | D37: 5 | E37: 0 | F37: 0 | G37: 5007,5008 | H37: 4,10,6 | I37: 0 | J37: 0 | K37: 0 | L37: 0 | M37: 49 | N37: 1 | O37: =P37*3 -> 777 | P37: =VLOOKUP(A37,材料!$P$4:$R$85,3,FALSE) -> 259 | T37: 0 | U37: 0 | V37: 0 | X37: false | Y37: 0 | Z37: 0 | AA37: 0 | AB37: 0 | AC37: 0 | AD37: 0 | AE37: 0 | AF37: 0 | AG37: 0 | AH37: 0 | AI37: 0 | AJ37: 刺猬身上的尖利的刺,小心扎破你的手
A38: 蛛丝 | B38: 214 | C38: 蛛丝 | D38: 5 | E38: 0 | F38: 0 | G38: 5007 | H38: 10,11,12 | I38: 0 | J38: 0 | K38: 0 | L38: 0 | M38: 49 | N38: 1 | O38: =P38*3 -> 915 | P38: =VLOOKUP(A38,材料!$P$4:$R$85,3,FALSE) -> 305 | T38: 0 | U38: 0 | V38: 0 | X38: false | Y38: 0 | Z38: 0 | AA38: 0 | AB38: 0 | AC38: 0 | AD38: 0 | AE38: 0 | AF38: 0 | AG38: 0 | AH38: 0 | AI38: 0 | AJ38: =VLOOKUP(ItemData!A38,Sheet8!N:O,2,FALSE) -> #N/A
A39: 铁矿 | B39: 215 | C39: 铁矿 | D39: 5 | E39: 0 | F39: 0 | H39: 14,10,9 | I39: 0 | J39: 0 | K39: 0 | L39: 0 | M39: 49 | N39: 1 | O39: =P39*3 -> 105 | P39: 35 | T39: 0 | U39: 0 | V39: 0 | X39: false | Y39: 0 | Z39: 0 | AA39: 0 | AB39: 0 | AC39: 0 | AD39: 0 | AE39: 0 | AF39: 0 | AG39: 0 | AH39: 0 | AI39: 0 | AJ39: 富含铁元素的矿石
A40: 盐矿 | B40: 216 | C40: 盐矿 | D40: 5 | E40: 0 | F40: 0 | G40: 5009 | H40: 10,15, | I40: 0 | J40: 0 | K40: 0 | L40: 0 | M40: 49 | N40: 1 | O40: =P40*3 -> 1065 | P40: =VLOOKUP(A40,材料!$P$4:$R$85,3,FALSE) -> 355 | T40: 0 | U40: 0 | V40: 0 | X40: false | Y40: 0 | Z40: 0 | AA40: 0 | AB40: 0 | AC40: 0 | AD40: 0 | AE40: 0 | AF40: 0 | AG40: 0 | AH40: 0 | AI40: 0 | AJ40: 富含食盐的结晶体
A41: 肥皂 | B41: 217 | C41: 肥皂 | D41: 5 | E41: 0 | F41: 0 | H41: 15,26,17 | I41: 0 | J41: 0 | K41: 0 | L41: 0 | M41: 49 | N41: 1 | O41: =P41*3 -> 1065 | P41: 355 | T41: 0 | U41: 0 | V41: 0 | X41: false | Y41: 0 | Z41: 0 | AA41: 0 | AB41: 0 | AC41: 0 | AD41: 0 | AE41: 0 | AF41: 0 | AG41: 0 | AH41: 0 | AI41: 0 | AJ41: 放在水里会生出很多泡沫
...

Sheet Sheet6
J4: 芜菁
J6: 芜菁根圆润饱满，是腌菜好原料，简单加工后，带着质朴清甜，能为日常餐桌添独特风味。
J8: 卷心菜
J10: 卷心菜叶片层层紧裹，形成紧实叶球，颜色翠绿，口感脆嫩，是餐桌上常见的蔬菜。
J12: 葱
J14: 葱身姿纤细修长，有着独特且浓郁的香气，轻轻一嗅，便能提神醒脑，是调味的好帮手。
J16: 萝卜
J18: 萝卜形态多样，有长有圆，口感更是一绝，咬下瞬间，清甜汁水率先散开，随后一丝辛辣巧妙涌上舌尖，丰富口感令人难忘。
J20: 紫甘蓝
J22: 紫甘蓝有着深紫色外衣，神秘又迷人，它富含花青素，营养满满，好看又好吃。
J24: 黄瓜
J26: 黄瓜浑身带刺，表皮翠绿，内里果肉水润脆嫩，直接咬上一口，清甜汁水在口中迸发，满是清爽。
... J102: 甜菜根粗壮厚实，富含糖分，既可以直接食用，也是制糖的重要原料。

Sheet Sheet4
H1: 洞穴天使鱼 | I1: 1,18
H2: 沙丁鱼 | I2: 1,2
H3: 竹荚鱼 | I3: 1,2
H4: 海鳗 | I4: 1,2
H5: 章鱼 | I5: 1,2
H6: 比目鱼 | I6: 1,2
H7: 河豚 | I7: 1,2
H8: 水母 | I8: 1,18
H9: 条石鲷 | I9: 1,2
H10: 红鲷鱼 | I10: 1,2
H11: 蓝蟹 | I11: 1,2
H12: 鲯鳅鱼 | I12: 1,2
... H320: 甜菜 | I320: 24,2,15

Sheet Sheet13
I1: 小龙虾
I2: 鲤鱼
I3: 鲮鱼
I4: 手套蟹
I5: 鲶鱼
I6: 丁鱼
I7: 锦鲤
I8: 线鱼
I9: 梭鲈
I10: 兰寿金鱼
I11: 樱桃鲑鱼
I12: 虹鳟鱼
... I31: 鲯鳅鱼
I32: 龙虾 | R32: 回春卷轴 | S32: 展开此卷，绿意盎然，生命之力涓涓流淌，能让伤者重焕生机，逆转危局。
I33: 金枪鱼 | R33: 振奋卷轴 | S33: 闪耀光芒的卷轴，激发潜能，使使用者力量奔涌，勇猛向前。
I34: 斑马狮子鱼 | R34: 昏睡卷轴 | S34: 神秘符文遍布，一经施展，让目标陷入沉睡，任人摆布。
R35: 感电卷轴 | S35: 电芒在卷上跃动，释放可使敌人周身麻痹，似遭雷电突袭，行动瞬间受阻。
R36: 冰氛卷轴 | S36: 散发凛冽寒气，开启后冰雾弥漫，冻结周遭空气，让对手陷入寒冷困境。
R37: 火氛卷轴 | S37: 熊熊火焰图案，点燃后火海肆虐，炽热高温席卷，燃尽一切阻碍，威力惊人。
R38: 沉默卷轴 | S38: 古朴的卷轴，展开令目标无法施法，如被禁言枷锁束缚，魔法力量戛然而止。
R39: 减速卷轴 | S39: 携带着迟缓力量，触发时让对方行动变缓，好似陷入泥沼，举步维艰。
R40: 闪避卷轴 | S40: 轻启此卷，使用者似有灵动幻影附身，能巧妙避开攻击，身姿飘逸难捉摸。
R41: 力量卷轴 | S41: 闪耀力量光辉，使用后肌肉贲张，力量如泉涌，可瞬间提升战斗爆发力。
R42: 魅惑卷轴 | S42: 带有迷人魔力，展开让目标心智迷失，如被甜蜜幻境迷惑，敌我不分。
Q47: 回春卷轴 | R47: 生命之息涌，伤痛速愈，重燃战斗希望之光。
I48: 米饭 | J48: 散发淡淡稻香，软糯口感，是饱腹的基础主食。 | Q48: 振奋卷轴 | R48: 力量泉眼开，活力满溢，战场斗志陡然澎湃。
I49: 发酵粉 | J49: 神奇的粉末，能赋予酿造的独特魅力。 | Q49: 昏睡卷轴 | R49: 目标陷沉睡，意识迷离，片刻安宁暗藏危机。
I50: 盐 | J50: 烹饪中不可或缺的调味关键。 | Q50: 感电卷轴 | R50: 电流周身窜，麻痹一瞬，敌人行动即刻受限。
I51: 酸味香料 | J51: 清新酸爽，为菜肴注入活力。 | Q51: 冰氛卷轴 | R51: 寒气肆意漫，冻结空间，对手困于霜寒之境。
I52: 蜂蜜 | J52: 流淌着自然甜香，甜蜜滋味令人心醉。 | Q52: 火氛卷轴 | R52: 烈焰熊熊燃，高温炙烤，障碍皆化灰烬飘散。
I53: 牛奶 | J53: 富含营养，口感醇厚丝滑，适合多种烹饪。 | Q53: 沉默卷轴 | R53: 魔法难施展，咒术禁言，敌方策略瞬间瘫痪。
I54: 鸡蛋 | J54: 圆润晶莹，是厨房中万能的美味担当。 | Q54: 减速卷轴 | R54: 步伐变迟缓，行动受阻，仿若深陷泥泞之中。
I55: 猪肉 | J55: 能变幻出多样风味，满足众多食客的需求。 | Q55: 闪避卷轴 | R55: 身形幻如影，攻击巧避，周旋敌阵自在随心。
I56: 面粉 | J56: 麦类的粉末，经巧手加工，成为各种形状，承载丰富口感。 | Q56: 力量卷轴 | R56: 力量猛激增，肌肉贲张，挥击皆有千钧之力。
I57: 咖啡粉 | J57: 咖啡粉散发浓郁醇香，冲泡后苦涩与香醇交织。 | Q57: 魅惑卷轴 | R57: 心智被迷离，敌我不辨，受控走向未知命运。
I58: 海苔 | J58: 酥脆可口，常作零食或包裹食材，增添别样风味。
I59: 黄油 | J59: 黄油色泽金黄，质地柔软，赋予食物奢华口感。
I60: 腌芜菁 | J60: 咸酸适度，爽脆开胃，为餐桌增添一份独特的风味刺激。
I61: 蔬菜沙拉 | J61: 新鲜脆爽，多种蔬菜汇聚，轻食之选，健康与美味并存。
I62: 三明治 | J62: 层次丰富，夹裹各种食材，是快捷美味的饱腹佳肴。
...

Sheet Sheet2
D5: 价值 | E5: 322
B6: 1600 | C6: 长剑 | D6: =VLOOKUP(C6,装备!$B$2:$J$60,9,FALSE)*0.75 -> 7.5 | E6: 1 | F6: 木材 | G6: 铸造 | I6: 长剑 | K6: 铁块 | L6: =VLOOKUP(K6,Sheet8!$A$1:$B$165,2,FALSE) -> #N/A | M6: 刀刃 | N6: =VLOOKUP(M6,Sheet8!$A$1:$B$155,2,FALSE) -> #N/A | S6: =VLOOKUP(K6,ItemData!$A$4:$B$415,2,FALSE) -> 298 | T6: =VLOOKUP(M6,ItemData!$A$4:$B$415,2,FALSE) -> 274 | X6: =S6&","&T6&IF(U6<>"",","&U6,"")&IF(V6<>"",","&V6,"") -> 298,274
B7: 1601 | C7: 诅咒之剑 | D7: =VLOOKUP(C7,装备!$B$2:$J$60,9,FALSE)*0.75 -> 20.25 | E7: 2 | F7: 原木 | G7: 铸造 | H7: 诅咒猎杀 | I7: 诅咒之剑 | K7: 长剑 | L7: =VLOOKUP(K7,Sheet8!$A$1:$B$155,2,FALSE) -> #N/A | M7: 眼球 | N7: =VLOOKUP(M7,Sheet8!$A$1:$B$155,2,FALSE) -> #N/A | O7: 诅咒宝珠 | P7: =VLOOKUP(O7,Sheet8!$A$1:$B$155,2,FALSE) -> #N/A | S7: =VLOOKUP(K7,ItemData!$A$4:$B$415,2,FALSE) -> 1600 | T7: =VLOOKUP(M7,ItemData!$A$4:$B$415,2,FALSE) -> 220 | U7: =VLOOKUP(O7,ItemData!$A$4:$B$415,2,FALSE) -> 257 | X7: =S7&","&T7&IF(U7<>"",","&U7,"")&IF(V7<>"",","&V7,"") -> 1600,220,257
B8: 1602 | C8: 烈焰之刃 | D8: =VLOOKUP(C8,装备!$B$2:$J$60,9,FALSE)*0.75 -> 52.5 | E8: 3 | F8: 木柴 | G8: 铸造 | H8: 烈焰斩 | I8: 烈焰之刃 | K8: 长剑 | L8: =VLOOKUP(K8,Sheet8!$A$1:$B$155,2,FALSE) -> #N/A | M8: 火晶石 | N8: =VLOOKUP(M8,Sheet8!$A$1:$B$155,2,FALSE) -> #N/A | O8: 石英砂 | P8: =VLOOKUP(O8,Sheet8!$A$1:$B$155,2,FALSE) -> #N/A | Q8: 白磷粉末 | R8: =VLOOKUP(Q8,Sheet8!$A$1:$B$155,2,FALSE) -> #N/A | S8: =VLOOKUP(K8,ItemData!$A$4:$B$415,2,FALSE) -> 1600 | T8: =VLOOKUP(M8,ItemData!$A$4:$B$415,2,FALSE) -> 229 | U8: =VLOOKUP(O8,ItemData!$A$4:$B$415,2,FALSE) -> 205 | V8: =VLOOKUP(Q8,ItemData!$A$4:$B$415,2,FALSE) -> 284 | X8: =S8&","&T8&IF(U8<>"",","&U8,"")&IF(V8<>"",","&V8,"") -> 1600,229,205,284
B9: 1603 | C9: 大地之剑 | D9: =VLOOKUP(C9,装备!$B$2:$J$60,9,FALSE)*0.75 -> 47.25 | E9: 3 | F9: 木棒 | G9: 铸造 | H9: 地刺 | I9: 大地之剑 | K9: 长剑 | L9: =VLOOKUP(K9,Sheet8!$A$1:$B$155,2,FALSE) -> #N/A | M9: 土晶石 | N9: =VLOOKUP(M9,Sheet8!$A$1:$B$155,2,FALSE) -> #N/A | O9: 钢 | P9: =VLOOKUP(O9,Sheet8!$A$1:$B$155,2,FALSE) -> #N/A | Q9: 粘土 | R9: =VLOOKUP(Q9,Sheet8!$A$1:$B$155,2,FALSE) -> #N/A | S9: =VLOOKUP(K9,ItemData!$A$4:$B$415,2,FALSE) -> 1600 | T9: =VLOOKUP(M9,ItemData!$A$4:$B$415,2,FALSE) -> 218 | U9: =VLOOKUP(O9,ItemData!$A$4:$B$415,2,FALSE) -> 299 | V9: =VLOOKUP(Q9,ItemData!$A$4:$B$415,2,FALSE) -> 212 | X9: =S9&","&T9&IF(U9<>"",","&U9,"")&IF(V9<>"",","&V9,"") -> 1600,218,299,212
B10: 1604 | C10: 冰之刃 | D10: =VLOOKUP(C10,装备!$B$2:$J$60,9,FALSE)*0.75 -> 54 | E10: 3 | G10: 铸造 | H10: 寒冰斩 | I10: 冰之刃 | K10: 长剑 | L10: =VLOOKUP(K10,Sheet8!$A$1:$B$155,2,FALSE) -> #N/A | M10: 冰晶石 | N10: =VLOOKUP(M10,Sheet8!$A$1:$B$155,2,FALSE) -> #N/A | O10: 冰的结晶 | P10: =VLOOKUP(O10,Sheet8!$A$1:$B$155,2,FALSE) -> #N/A | Q10: 雪球 | R10: =VLOOKUP(Q10,Sheet8!$A$1:$B$155,2,FALSE) -> #N/A | S10: =VLOOKUP(K10,ItemData!$A$4:$B$415,2,FALSE) -> 1600 | T10: =VLOOKUP(M10,ItemData!$A$4:$B$415,2,FALSE) -> 260 | U10: =VLOOKUP(O10,ItemData!$A$4:$B$415,2,FALSE) -> 261 | V10: =VLOOKUP(Q10,ItemData!$A$4:$B$415,2,FALSE) -> 253 | X10: =S10&","&T10&IF(U10<>"",","&U10,"")&IF(V10<>"",","&V10,"") -> 1600,260,261,253
B11: 1605 | C11: 铁枪 | D11: =VLOOKUP(C11,装备!$B$2:$J$60,9,FALSE)*0.75 -> 8.25 | E11: 1 | G11: 铸造 | I11: 铁枪 | K11: 木棒 | L11: =VLOOKUP(K11,Sheet8!$A$1:$B$155,2,FALSE) -> #N/A | M11: 鹿角 | N11: =VLOOKUP(M11,Sheet8!$A$1:$B$155,2,FALSE) -> #N/A | O11: 刀刃 | P11: =VLOOKUP(O11,Sheet8!$A$1:$B$155,2,FALSE) -> #N/A | S11: =VLOOKUP(K11,ItemData!$A$4:$B$415,2,FALSE) -> 104 | T11: =VLOOKUP(M11,ItemData!$A$4:$B$415,2,FALSE) -> 222 | U11: =VLOOKUP(O11,ItemData!$A$4:$B$415,2,FALSE) -> 274 | X11: =S11&","&T11&IF(U11<>"",","&U11,"")&IF(V11<>"",","&V11,"") -> 104,222,274
B12: 1606 | C12: 骑士长枪 | D12: =VLOOKUP(C12,装备!$B$2:$J$60,9,FALSE)*0.75 -> 28.5 | E12: 2 | G12: 铸造 | H12: 血腥囚笼 | I12: 血腥之枪 | K12: 铁枪 | L12: =VLOOKUP(K12,Sheet8!$A$1:$B$155,2,FALSE) -> #N/A | M12: 魔族之血 | N12: =VLOOKUP(M12,Sheet8!$A$1:$B$155,2,FALSE) -> #N/A | O12: 银块 | P12: =VLOOKUP(O12,Sheet8!$A$1:$B$155,2,FALSE) -> #N/A | Q12: 蜂刺 | R12: =VLOOKUP(Q12,Sheet8!$A$1:$B$155,2,FALSE) -> #N/A | S12: =VLOOKUP(K12,ItemData!$A$4:$B$415,2,FALSE) -> 1605 | T12: =VLOOKUP(M12,ItemData!$A$4:$B$415,2,FALSE) -> 259 | U12: =VLOOKUP(O12,ItemData!$A$4:$B$415,2,FALSE) -> 237 | V12: =VLOOKUP(Q12,ItemData!$A$4:$B$415,2,FALSE) -> 239 | X12: =S12&","&T12&IF(U12<>"",","&U12,"")&IF(V12<>"",","&V12,"") -> 1605,259,237,239
B13: 1607 | C13: 血腥之矛 | D13: =VLOOKUP(C13,装备!$B$2:$J$60,9,FALSE)*0.75 -> 31.875 | E13: 2 | G13: 铸造 | H13: 骑士冲击 | I13: 骑士长枪 | K13: 铁枪 | L13: =VLOOKUP(K13,Sheet8!$A$1:$B$155,2,FALSE) -> #N/A | M13: 骑士之证 | N13: =VLOOKUP(M13,Sheet8!$A$1:$B$155,2,FALSE) -> #N/A | O13: 钢 | P13: =VLOOKUP(O13,Sheet8!$A$1:$B$155,2,FALSE) -> #N/A | S13: =VLOOKUP(K13,ItemData!$A$4:$B$415,2,FALSE) -> 1605 | T13: =VLOOKUP(M13,ItemData!$A$4:$B$415,2,FALSE) -> 275 | U13: =VLOOKUP(O13,ItemData!$A$4:$B$415,2,FALSE) -> 299 | X13: =S13&","&T13&IF(U13<>"",","&U13,"")&IF(V13<>"",","&V13,"") -> 1605,275,299
B14: 1608 | C14: 三叉戟 | D14: =VLOOKUP(C14,装备!$B$2:$J$60,9,FALSE)*0.75 -> 44.25 | E14: 3 | G14: 铸造 | H14: 龙卷风 | I14: 三叉戟 | K14: 铁枪 | L14: =VLOOKUP(K14,Sheet8!$A$1:$B$155,2,FALSE) -> #N/A | M14: 珊瑚 | N14: =VLOOKUP(M14,Sheet8!$A$1:$B$155,2,FALSE) -> #N/A | O14: 象牙 | P14: =VLOOKUP(O14,Sheet8!$A$1:$B$155,2,FALSE) -> #N/A | Q14: 水晶石 | R14: =VLOOKUP(Q14,Sheet8!$A$1:$B$155,2,FALSE) -> #N/A | S14: =VLOOKUP(K14,ItemData!$A$4:$B$415,2,FALSE) -> 1605 | T14: =VLOOKUP(M14,ItemData!$A$4:$B$415,2,FALSE) -> 227 | U14: =VLOOKUP(O14,ItemData!$A$4:$B$415,2,FALSE) -> 240 | V14: =VLOOKUP(Q14,ItemData!$A$4:$B$415,2,FALSE) -> 232 | X14: =S14&","&T14&IF(U14<>"",","&U14,"")&IF(V14<>"",","&V14,"") -> 1605,227,240,232
B15: 1609 | C15: 战斧 | D15: =VLOOKUP(C15,装备!$B$2:$J$60,9,FALSE)*0.75 -> 17.25 | E15: 2 | G15: 铸造 | H15: 奇迹斩 | I15: 秘银长剑 | K15: 银块 | L15: =VLOOKUP(K15,Sheet8!$A$1:$B$155,2,FALSE) -> #N/A | M15: 刀刃 | N15: =VLOOKUP(M15,Sheet8!$A$1:$B$155,2,FALSE) -> #N/A | O15: 咒术药水 | P15: =VLOOKUP(O15,Sheet8!$A$1:$B$155,2,FALSE) -> #N/A | Q15: 暮光结晶 | R15: =VLOOKUP(Q15,Sheet8!$A$1:$B$155,2,FALSE) -> #N/A | S15: =VLOOKUP(K15,ItemData!$A$4:$B$415,2,FALSE) -> 237 | T15: =VLOOKUP(M15,ItemData!$A$4:$B$415,2,FALSE) -> 274 | U15: =VLOOKUP(O15,ItemData!$A$4:$B$415,2,FALSE) -> 256 | V15: =VLOOKUP(Q15,ItemData!$A$4:$B$415,2,FALSE) -> 285 | X15: =S15&","&T15&IF(U15<>"",","&U15,"")&IF(V15<>"",","&V15,"") -> 237,274,256,285
B16: 1610 | C16: 毒蜥之牙 | D16: =VLOOKUP(C16,装备!$B$2:$J$60,9,FALSE)*0.75 -> 27 | E16: 3 | G16: 铸造 | H16: 幻影突刺 | I16: 幻影长枪 | K16: 幻影水晶 | L16: =VLOOKUP(K16,Sheet8!$A$1:$B$155,2,FALSE) -> #N/A | M16: 铁枪 | N16: =VLOOKUP(M16,Sheet8!$A$1:$B$155,2,FALSE) -> #N/A | O16: 夜之幕 | P16: =VLOOKUP(O16,Sheet8!$A$1:$B$155,2,FALSE) -> #N/A | Q16: 风晶石 | R16: =VLOOKUP(Q16,Sheet8!$A$1:$B$155,2,FALSE) -> #N/A | S16: =VLOOKUP(K16,ItemData!$A$4:$B$415,2,FALSE) -> 269 | T16: =VLOOKUP(M16,ItemData!$A$4:$B$415,2,FALSE) -> 1605 | U16: =VLOOKUP(O16,ItemData!$A$4:$B$415,2,FALSE) -> 264 | V16: =VLOOKUP(Q16,ItemData!$A$4:$B$415,2,FALSE) -> 208 | X16: =S16&","&T16&IF(U16<>"",","&U16,"")&IF(V16<>"",","&V16,"") -> 269,1605,264,208
B17: 1611 | C17: 恶魔之斧 | D17: =VLOOKUP(C17,装备!$B$2:$J$60,9,FALSE)*0.75 -> 46.5 | E17: 3 | G17: 铸造 | I17: 战斧 | K17: 钢 | L17: =VLOOKUP(K17,Sheet8!$A$1:$B$155,2,FALSE) -> #N/A | M17: 刀刃 | N17: =VLOOKUP(M17,Sheet8!$A$1:$B$155,2,FALSE) -> #N/A | O17: 兽角 | P17: =VLOOKUP(O17,Sheet8!$A$1:$B$155,2,FALSE) -> #N/A | S17: =VLOOKUP(K17,ItemData!$A$4:$B$415,2,FALSE) -> 299 | T17: =VLOOKUP(M17,ItemData!$A$4:$B$415,2,FALSE) -> 274 | U17: =VLOOKUP(O17,ItemData!$A$4:$B$415,2,FALSE) -> 241 | X17: =S17&","&T17&IF(U17<>"",","&U17,"")&IF(V17<>"",","&V17,"") -> 299,274,241
B18: 1612 | C18: 蛇皮鞭 | D18: =VLOOKUP(C18,装备!$B$2:$J$60,9,FALSE)*0.75 -> 16.5 | E18: 1 | G18: 铸造 | H18: 剧毒风暴 | I18: 毒蜥之牙 | K18: 战斧 | L18: =VLOOKUP(K18,Sheet8!$A$1:$B$155,2,FALSE) -> #N/A | M18: 毒淤泥 | N18: =VLOOKUP(M18,Sheet8!$A$1:$B$155,2,FALSE) -> #N/A | O18: 狼牙 | P18: =VLOOKUP(O18,Sheet8!$A$1:$B$155,2,FALSE) -> #N/A | S18: =VLOOKUP(K18,ItemData!$A$4:$B$415,2,FALSE) -> 1609 | T18: =VLOOKUP(M18,ItemData!$A$4:$B$415,2,FALSE) -> 254 | U18: =VLOOKUP(O18,ItemData!$A$4:$B$415,2,FALSE) -> 211 | X18: =S18&","&T18&IF(U18<>"",","&U18,"")&IF(V18<>"",","&V18,"") -> 1609,254,211
B19: 1613 | C19: 荆棘鞭 | D19: =VLOOKUP(C19,装备!$B$2:$J$60,9,FALSE)*0.75 -> 13.5 | E19: 1 | G19: 铸造 | H19: 恶魔幻影 | I19: 恶魔之斧 | K19: 战斧 | L19: =VLOOKUP(K19,Sheet8!$A$1:$B$155,2,FALSE) -> #N/A | M19: 魔族之血 | N19: =VLOOKUP(M19,Sheet8!$A$1:$B$155,2,FALSE) -> #N/A | O19: 人狼之证 | P19: =VLOOKUP(O19,Sheet8!$A$1:$B$155,2,FALSE) -> #N/A | Q19: 石化之眼 | R19: =VLOOKUP(Q19,Sheet8!$A$1:$B$155,2,FALSE) -> #N/A | S19: =VLOOKUP(K19,ItemData!$A$4:$B$415,2,FALSE) -> 1609 | T19: =VLOOKUP(M19,ItemData!$A$4:$B$415,2,FALSE) -> 259 | U19: =VLOOKUP(O19,ItemData!$A$4:$B$415,2,FALSE) -> 258 | V19: =VLOOKUP(Q19,ItemData!$A$4:$B$415,2,FALSE) -> 263 | X19: =S19&","&T19&IF(U19<>"",","&U19,"")&IF(V19<>"",","&V19,"") -> 1609,259,258,263
B20: 1614 | C20: 女王之鞭 | D20: =VLOOKUP(C20,装备!$B$2:$J$60,9,FALSE)*0.75 -> 49.5 | E20: 2 | G20: 铸造 | H20: 暴风雪 | I20: 暴雪斧 | K20: 战斧 | L20: =VLOOKUP(K20,Sheet8!$A$1:$B$155,2,FALSE) -> #N/A | M20: 雪球 | N20: =VLOOKUP(M20,Sheet8!$A$1:$B$155,2,FALSE) -> #N/A | O20: 冰晶石 | P20: =VLOOKUP(O20,Sheet8!$A$1:$B$155,2,FALSE) -> #N/A | Q20: 寒冰气息 | R20: =VLOOKUP(Q20,Sheet8!$A$1:$B$155,2,FALSE) -> #N/A | S20: =VLOOKUP(K20,ItemData!$A$4:$B$415,2,FALSE) -> 1609 | T20: =VLOOKUP(M20,ItemData!$A$4:$B$415,2,FALSE) -> 253 | U20: =VLOOKUP(O20,ItemData!$A$4:$B$415,2,FALSE) -> 260 | V20: =VLOOKUP(Q20,ItemData!$A$4:$B$415,2,FALSE) -> 267 | X20: =S20&","&T20&IF(U20<>"",","&U20,"")&IF(V20<>"",","&V20,"") -> 1609,253,260,267
B21: 1615 | C21: 蛇牙鞭 | D21: =VLOOKUP(C21,装备!$B$2:$J$60,9,FALSE)*0.75 -> 43.5 | E21: 2 | G21: 缝纫 | I21: 蛇皮鞭 | K21: 蛇皮 | L21: =VLOOKUP(K21,Sheet8!$A$1:$B$155,2,FALSE) -> #N/A | M21: 马尾 | N21: =VLOOKUP(M21,Sheet8!$A$1:$B$155,2,FALSE) -> #N/A | O21: 蛛丝 | P21: =VLOOKUP(O21,Sheet8!$A$1:$B$155,2,FALSE) -> #N/A | S21: =VLOOKUP(K21,ItemData!$A$4:$B$415,2,FALSE) -> 238 | T21: =VLOOKUP(M21,ItemData!$A$4:$B$415,2,FALSE) -> 276 | U21: =VLOOKUP(O21,ItemData!$A$4:$B$415,2,FALSE) -> 214 | X21: =S21&","&T21&IF(U21<>"",","&U21,"")&IF(V21<>"",","&V21,"") -> 238,276,214
B22: 1616 | C22: 暴雪斧 | D22: =VLOOKUP(C22,装备!$B$2:$J$60,9,FALSE)*0.75 -> 73.5 | E22: 3 | G22: 缝纫 | I22: 藤鞭 | K22: 植物的藤 | L22: =VLOOKUP(K22,Sheet8!$A$1:$B$155,2,FALSE) -> #N/A | M22: 马尾 | N22: =VLOOKUP(M22,Sheet8!$A$1:$B$155,2,FALSE) -> #N/A | O22: 蛛丝 | P22: =VLOOKUP(O22,Sheet8!$A$1:$B$155,2,FALSE) -> #N/A | S22: =VLOOKUP(K22,ItemData!$A$4:$B$415,2,FALSE) -> 221 | T22: =VLOOKUP(M22,ItemData!$A$4:$B$415,2,FALSE) -> 276 | U22: =VLOOKUP(O22,ItemData!$A$4:$B$415,2,FALSE) -> 214 | X22: =S22&","&T22&IF(U22<>"",","&U22,"")&IF(V22<>"",","&V22,"") -> 221,276,214
B23: 1617 | C23: 秘银长剑 | D23: =VLOOKUP(C23,装备!$B$2:$J$60,9,FALSE)*0.75 -> 62.25 | E23: 4 | G23: 缝纫 | H23: 女王之春 | I23: 女王鞭 | K23: 荆棘鞭 | L23: =VLOOKUP(K23,Sheet8!$A$1:$B$155,2,FALSE) -> #N/A | M23: 尖刺 | N23: =VLOOKUP(M23,Sheet8!$A$1:$B$155,2,FALSE) -> #N/A | O23: 幽魂 | P23: =VLOOKUP(O23,Sheet8!$A$1:$B$155,2,FALSE) -> #N/A | S23: =VLOOKUP(K23,ItemData!$A$4:$B$415,2,FALSE) -> 1613 | T23: =VLOOKUP(M23,ItemData!$A$4:$B$415,2,FALSE) -> 213 | U23: =VLOOKUP(O23,ItemData!$A$4:$B$415,2,FALSE) -> 246 | X23: =S23&","&T23&IF(U23<>"",","&U23,"")&IF(V23<>"",","&V23,"") -> 1613,213,246
B24: 1618 | C24: 幻影长枪 | D24: =VLOOKUP(C24,装备!$B$2:$J$60,9,FALSE)*0.75 -> 70.5 | E24: 4 | G24: 缝纫 | H24: 刺颈鞭挞 | I24: 蛇牙鞭 | K24: 蛇皮鞭 | L24: =VLOOKUP(K24,Sheet8!$A$1:$B$155,2,FALSE) -> #N/A | M24: 狼牙 | N24: =VLOOKUP(M24,Sheet8!$A$1:$B$155,2,FALSE) -> #N/A | O24: 蛇皮鞭 | P24: =VLOOKUP(O24,Sheet8!$A$1:$B$155,2,FALSE) -> #N/A | S24: =VLOOKUP(K24,ItemData!$A$4:$B$415,2,FALSE) -> 1612 | T24: =VLOOKUP(M24,ItemData!$A$4:$B$415,2,FALSE) -> 211 | U24: =VLOOKUP(O24,ItemData!$A$4:$B$415,2,FALSE) -> 1612 | X24: =S24&","&T24&IF(U24<>"",","&U24,"")&IF(V24<>"",","&V24,"") -> 1612,211,1612
B25: 1619 | C25: 雷神之鞭 | D25: =VLOOKUP(C25,装备!$B$2:$J$60,9,FALSE)*0.75 -> 64.5 | E25: 4 | G25: 铸造 | H25: 雷暴 | I25: 雷神之鞭 | K25: 雷鸣宝珠 | L25: =VLOOKUP(K25,Sheet8!$A$1:$B$155,2,FALSE) -> #N/A | M25: 电偶瓶 | N25: =VLOOKUP(M25,Sheet8!$A$1:$B$155,2,FALSE) -> #N/A | O25: 蜂刺 | P25: =VLOOKUP(O25,Sheet8!$A$1:$B$155,2,FALSE) -> #N/A | Q25: 女王之鞭 | R25: =VLOOKUP(Q25,Sheet8!$A$1:$B$155,2,FALSE) -> #N/A | S25: =VLOOKUP(K25,ItemData!$A$4:$B$415,2,FALSE) -> 270 | T25: =VLOOKUP(M25,ItemData!$A$4:$B$415,2,FALSE) -> 225 | U25: =VLOOKUP(O25,ItemData!$A$4:$B$415,2,FALSE) -> 239 | V25: =VLOOKUP(Q25,ItemData!$A$4:$B$415,2,FALSE) -> 1614 | X25: =S25&","&T25&IF(U25<>"",","&U25,"")&IF(V25<>"",","&V25,"") -> 270,225,239,1614
B26: 1620 | C26: 死亡之鞭 | D26: =VLOOKUP(C26,装备!$B$2:$J$60,9,FALSE)*0.75 -> 69 | E26: 4 | G26: 铸造 | H26: 幽冥黑洞 | I26: 死亡之鞭 | K26: 脏绷带 | L26: =VLOOKUP(K26,Sheet8!$A$1:$B$155,2,FALSE) -> #N/A | M26: 亡者之土 | N26: =VLOOKUP(M26,Sheet8!$A$1:$B$155,2,FALSE) -> #N/A | O26: 寒冰火种 | P26: =VLOOKUP(O26,Sheet8!$A$1:$B$155,2,FALSE) -> #N/A | Q26: 蛇牙鞭 | R26: =VLOOKUP(Q26,Sheet8!$A$1:$B$155,2,FALSE) -> #N/A | S26: =VLOOKUP(K26,ItemData!$A$4:$B$415,2,FALSE) -> 245 | T26: =VLOOKUP(M26,ItemData!$A$4:$B$415,2,FALSE) -> 255 | U26: =VLOOKUP(O26,ItemData!$A$4:$B$415,2,FALSE) -> 268 | V26: =VLOOKUP(Q26,ItemData!$A$4:$B$415,2,FALSE) -> 1615 | X26: =S26&","&T26&IF(U26<>"",","&U26,"")&IF(V26<>"",","&V26,"") -> 245,255,268,1615
B27: 1650 | C27: 布衣 | D27: =VLOOKUP(C27,装备!$B$2:$J$60,9,FALSE)*0.75 -> 3.75 | E27: 1 | G27: 缝纫 | I27: 布衣 | K27: 布片 | L27: =VLOOKUP(K27,Sheet8!$A$1:$B$155,2,FALSE) -> #N/A | M27: 毛线 | N27: =VLOOKUP(M27,Sheet8!$A$1:$B$155,2,FALSE) -> #N/A | S27: =VLOOKUP(K27,ItemData!$A$4:$B$415,2,FALSE) -> 204 | T27: =VLOOKUP(M27,ItemData!$A$4:$B$415,2,FALSE) -> 277 | X27: =S27&","&T27&IF(U27<>"",","&U27,"")&IF(V27<>"",","&V27,"") -> 204,277
B28: 1651 | C28: 皮铠 | D28: =VLOOKUP(C28,装备!$B$2:$J$60,9,FALSE)*0.75 -> 7.5 | E28: 1 | G28: 缝纫 | I28: 皮铠 | K28: 皮革 | L28: =VLOOKUP(K28,Sheet8!$A$1:$B$155,2,FALSE) -> #N/A | M28: 粘液 | N28: =VLOOKUP(M28,Sheet8!$A$1:$B$155,2,FALSE) -> #N/A | O28: 蛛丝 | P28: =VLOOKUP(O28,Sheet8!$A$1:$B$155,2,FALSE) -> #N/A | S28: =VLOOKUP(K28,ItemData!$A$4:$B$415,2,FALSE) -> 271 | T28: =VLOOKUP(M28,ItemData!$A$4:$B$415,2,FALSE) -> 278 | U28: =VLOOKUP(O28,ItemData!$A$4:$B$415,2,FALSE) -> 214 | X28: =S28&","&T28&IF(U28<>"",","&U28,"")&IF(V28<>"",","&V28,"") -> 271,278,214
B29: 1652 | C29: 锁子甲 | D29: =VLOOKUP(C29,装备!$B$2:$J$60,9,FALSE)*0.75 -> 14.25 | E29: 2 | G29: 缝纫 | I29: 锁子甲 | K29: 皮铠 | L29: =VLOOKUP(K29,Sheet8!$A$1:$B$155,2,FALSE) -> #N/A | M29: 珊瑚 | N29: =VLOOKUP(M29,Sheet8!$A$1:$B$155,2,FALSE) -> #N/A | O29: 钢 | P29: =VLOOKUP(O29,Sheet8!$A$1:$B$155,2,FALSE) -> #N/A | S29: =VLOOKUP(K29,ItemData!$A$4:$B$415,2,FALSE) -> 1651 | T29: =VLOOKUP(M29,ItemData!$A$4:$B$415,2,FALSE) -> 227 | U29: =VLOOKUP(O29,ItemData!$A$4:$B$415,2,FALSE) -> 299 | X29: =S29&","&T29&IF(U29<>"",","&U29,"")&IF(V29<>"",","&V29,"") -> 1651,227,299
B30: 1653 | C30: 毛皮斗篷 | D30: =VLOOKUP(C30,装备!$B$2:$J$60,9,FALSE)*0.75 -> 22.5 | E30: 2 | G30: 缝纫 | I30: 毛皮斗篷 | K30: 皮铠 | L30: =VLOOKUP(K30,Sheet8!$A$1:$B$155,2,FALSE) -> #N/A | M30: 魔兽皮毛 | N30: =VLOOKUP(M30,Sheet8!$A$1:$B$155,2,FALSE) -> #N/A | O30: 鸭绒 | P30: =VLOOKUP(O30,Sheet8!$A$1:$B$155,2,FALSE) -> #N/A | S30: =VLOOKUP(K30,ItemData!$A$4:$B$415,2,FALSE) -> 1651 | T30: =VLOOKUP(M30,ItemData!$A$4:$B$415,2,FALSE) -> 223 | U30: =VLOOKUP(O30,ItemData!$A$4:$B$415,2,FALSE) -> 301 | X30: =S30&","&T30&IF(U30<>"",","&U30,"")&IF(V30<>"",","&V30,"") -> 1651,223,301
B31: 1654 | C31: 铁铠甲 | D31: =VLOOKUP(C31,装备!$B$2:$J$60,9,FALSE)*0.75 -> 28.5 | E31: 1 | G31: 铸造 | I31: 铁铠甲 | K31: 铁块 | L31: =VLOOKUP(K31,Sheet8!$A$1:$B$155,2,FALSE) -> #N/A | M31: 石英砂 | N31: =VLOOKUP(M31,Sheet8!$A$1:$B$155,2,FALSE) -> #N/A | S31: =VLOOKUP(K31,ItemData!$A$4:$B$415,2,FALSE) -> 298 | T31: =VLOOKUP(M31,ItemData!$A$4:$B$415,2,FALSE) -> 205 | X31: =S31&","&T31&IF(U31<>"",","&U31,"")&IF(V31<>"",","&V31,"") -> 298,205
B32: 1655 | C32: 红莲之铠 | D32: =VLOOKUP(C32,装备!$B$2:$J$60,9,FALSE)*0.75 -> 36 | E32: 3 | G32: 铸造 | I32: 红莲之铠 | K32: 铁铠甲 | L32: =VLOOKUP(K32,Sheet8!$A$1:$B$155,2,FALSE) -> #N/A | M32: 遗骨 | N32: =VLOOKUP(M32,Sheet8!$A$1:$B$155,2,FALSE) -> #N/A | O32: 火晶石 | P32: =VLOOKUP(O32,Sheet8!$A$1:$B$155,2,FALSE) -> #N/A | Q32: 魔力之土 | R32: =VLOOKUP(Q32,Sheet8!$A$1:$B$155,2,FALSE) -> #N/A | S32: =VLOOKUP(K32,ItemData!$A$4:$B$415,2,FALSE) -> 1654 | T32: =VLOOKUP(M32,ItemData!$A$4:$B$415,2,FALSE) -> 250 | U32: =VLOOKUP(O32,ItemData!$A$4:$B$415,2,FALSE) -> 229 | V32: =VLOOKUP(Q32,ItemData!$A$4:$B$415,2,FALSE) -> 286 | X32: =S32&","&T32&IF(U32<>"",","&U32,"")&IF(V32<>"",","&V32,"") -> 1654,250,229,286
B33: 1656 | C33: 铁龟铠 | D33: =VLOOKUP(C33,装备!$B$2:$J$60,9,FALSE)*0.75 -> 34.5 | E33: 2 | G33: 铸造 | I33: 铁龟铠 | K33: 龟壳 | L33: =VLOOKUP(K33,Sheet8!$A$1:$B$155,2,FALSE) -> #N/A | M33: 铁铠甲 | N33: =VLOOKUP(M33,Sheet8!$A$1:$B$155,2,FALSE) -> #N/A | O33: 琥珀 | P33: =VLOOKUP(O33,Sheet8!$A$1:$B$155,2,FALSE) -> #N/A | S33: =VLOOKUP(K33,ItemData!$A$4:$B$415,2,FALSE) -> 202 | T33: =VLOOKUP(M33,ItemData!$A$4:$B$415,2,FALSE) -> 1654 | U33: =VLOOKUP(O33,ItemData!$A$4:$B$415,2,FALSE) -> 210 | X33: =S33&","&T33&IF(U33<>"",","&U33,"")&IF(V33<>"",","&V33,"") -> 202,1654,210
B34: 1657 | C34: 华丽背心 | D34: =VLOOKUP(C34,装备!$B$2:$J$60,9,FALSE)*0.75 -> 31.5 | E34: 3 | G34: 缝纫 | I34: 华丽背心 | K34: 彩色的布 | L34: =VLOOKUP(K34,Sheet8!$A$1:$B$155,2,FALSE) -> #N/A | M34: 彩色羽毛 | N34: =VLOOKUP(M34,Sheet8!$A$1:$B$155,2,FALSE) -> #N/A | O34: 毛线 | P34: =VLOOKUP(O34,Sheet8!$A$1:$B$155,2,FALSE) -> #N/A | Q34: 鸭绒 | R34: =VLOOKUP(Q34,Sheet8!$A$1:$B$155,2,FALSE) -> #N/A | S34: =VLOOKUP(K34,ItemData!$A$4:$B$415,2,FALSE) -> 272 | T34: =VLOOKUP(M34,ItemData!$A$4:$B$415,2,FALSE) -> 228 | U34: =VLOOKUP(O34,ItemData!$A$4:$B$415,2,FALSE) -> 277 | X34: =S34&","&T34&IF(U34<>"",","&U34,"")&IF(V34<>"",","&V34,"") -> 272,228,277
B35: 1658 | C35: 鳞铠 | D35: =VLOOKUP(C35,装备!$B$2:$J$60,9,FALSE)*0.75 -> 36 | E35: 2 | G35: 缝纫 | I35: 鳞铠 | K35: 鳞片 | L35: =VLOOKUP(K35,Sheet8!$A$1:$B$155,2,FALSE) -> #N/A | M35: 粘液 | N35: =VLOOKUP(M35,Sheet8!$A$1:$B$155,2,FALSE) -> #N/A | O35: 皮革 | P35: =VLOOKUP(O35,Sheet8!$A$1:$B$155,2,FALSE) -> #N/A | S35: =VLOOKUP(K35,ItemData!$A$4:$B$415,2,FALSE) -> 273 | T35: =VLOOKUP(M35,ItemData!$A$4:$B$415,2,FALSE) -> 278 | U35: =VLOOKUP(O35,ItemData!$A$4:$B$415,2,FALSE) -> 271 | X35: =S35&","&T35&IF(U35<>"",","&U35,"")&IF(V35<>"",","&V35,"") -> 273,278,271
B36: 1659 | C36: 暗之袍 | D36: =VLOOKUP(C36,装备!$B$2:$J$60,9,FALSE)*0.75 -> 31.5 | E36: 3 | G36: 缝纫 | I36: 暗之袍 | K36: 夜之幕 | L36: =VLOOKUP(K36,Sheet8!$A$1:$B$155,2,FALSE) -> #N/A | M36: 毛线 | N36: =VLOOKUP(M36,Sheet8!$A$1:$B$155,2,FALSE) -> #N/A | O36: 亡者之土 | P36: =VLOOKUP(O36,Sheet8!$A$1:$B$155,2,FALSE) -> #N/A | Q36: 幽魂 | R36: =VLOOKUP(Q36,Sheet8!$A$1:$B$155,2,FALSE) -> #N/A | S36: =VLOOKUP(K36,ItemData!$A$4:$B$415,2,FALSE) -> 264 | T36: =VLOOKUP(M36,ItemData!$A$4:$B$415,2,FALSE) -> 277 | U36: =VLOOKUP(O36,ItemData!$A$4:$B$415,2,FALSE) -> 255 | V36: =VLOOKUP(Q36,ItemData!$A$4:$B$415,2,FALSE) -> 246 | X36: =S36&","&T36&IF(U36<>"",","&U36,"")&IF(V36<>"",","&V36,"") -> 264,277,255,246
B37: 1660 | C37: 疾风背心 | D37: =VLOOKUP(C37,装备!$B$2:$J$60,9,FALSE)*0.75 -> 36.75 | E37: 3 | G37: 缝纫 | I37: 疾风背心 | K37: 布衣 | L37: =VLOOKUP(K37,Sheet8!$A$1:$B$155,2,FALSE) -> #N/A | M37: 风晶石 | N37: =VLOOKUP(M37,Sheet8!$A$1:$B$155,2,FALSE) -> #N/A | O37: 奇美拉之翼 | P37: =VLOOKUP(O37,Sheet8!$A$1:$B$155,2,FALSE) -> #N/A | S37: =VLOOKUP(K37,ItemData!$A$4:$B$415,2,FALSE) -> 1650 | T37: =VLOOKUP(M37,ItemData!$A$4:$B$415,2,FALSE) -> 208 | U37: =VLOOKUP(O37,ItemData!$A$4:$B$415,2,FALSE) -> 224 | X37: =S37&","&T37&IF(U37<>"",","&U37,"")&IF(V37<>"",","&V37,"") -> 1650,208,224
B38: 1661 | C38: 魔法铠甲 | D38: =VLOOKUP(C38,装备!$B$2:$J$60,9,FALSE)*0.75 -> 53.25 | E38: 4 | G38: 缝纫 | I38: 魔法铠甲 | K38: 皮铠 | L38: =VLOOKUP(K38,Sheet8!$A$1:$B$155,2,FALSE) -> #N/A | M38: 水晶球 | N38: =VLOOKUP(M38,Sheet8!$A$1:$B$155,2,FALSE) -> #N/A | O38: 金块 | P38: =VLOOKUP(O38,Sheet8!$A$1:$B$155,2,FALSE) -> #N/A | Q38: 兽角 | R38: =VLOOKUP(Q38,Sheet8!$A$1:$B$155,2,FALSE) -> #N/A | S38: =VLOOKUP(K38,ItemData!$A$4:$B$415,2,FALSE) -> 1651 | T38: =VLOOKUP(M38,ItemData!$A$4:$B$415,2,FALSE) -> 242 | U38: =VLOOKUP(O38,ItemData!$A$4:$B$415,2,FALSE) -> 247 | V38: =VLOOKUP(Q38,ItemData!$A$4:$B$415,2,FALSE) -> 241 | X38: =S38&","&T38&IF(U38<>"",","&U38,"")&IF(V38<>"",","&V38,"") -> 1651,242,247,241
B39: 1662 | C39: 钢刃锁甲 | D39: =VLOOKUP(C39,装备!$B$2:$J$60,9,FALSE)*0.75 -> 57 | E39: 4 | G39: 铸造 | I39: 钢刃锁甲 | K39: 铁铠甲 | L39: =VLOOKUP(K39,Sheet8!$A$1:$B$155,2,FALSE) -> #N/A | M39: 刀刃 | N39: =VLOOKUP(M39,Sheet8!$A$1:$B$155,2,FALSE) -> #N/A | O39: 钢 | P39: =VLOOKUP(O39,Sheet8!$A$1:$B$155,2,FALSE) -> #N/A | Q39: 土晶石 | R39: =VLOOKUP(Q39,Sheet8!$A$1:$B$155,2,FALSE) -> #N/A | S39: =VLOOKUP(K39,ItemData!$A$4:$B$415,2,FALSE) -> 1654 | T39: =VLOOKUP(M39,ItemData!$A$4:$B$415,2,FALSE) -> 274 | U39: =VLOOKUP(O39,ItemData!$A$4:$B$415,2,FALSE) -> 299 | V39: =VLOOKUP(Q39,ItemData!$A$4:$B$415,2,FALSE) -> 218 | X39: =S39&","&T39&IF(U39<>"",","&U39,"")&IF(V39<>"",","&V39,"") -> 1654,274,299,218
B40: 1663 | C40: 丝织长袍 | D40: =VLOOKUP(C40,装备!$B$2:$J$60,9,FALSE)*0.75 -> 42.75 | E40: 4 | G40: 缝纫 | I40: 丝织长袍 | K40: 布片 | L40: =VLOOKUP(K40,Sheet8!$A$1:$B$155,2,FALSE) -> #N/A | M40: 蛛丝 | N40: =VLOOKUP(M40,Sheet8!$A$1:$B$155,2,FALSE) -> #N/A | O40: 彩色羽毛 | P40: =VLOOKUP(O40,Sheet8!$A$1:$B$155,2,FALSE) -> #N/A | S40: =VLOOKUP(K40,ItemData!$A$4:$B$415,2,FALSE) -> 204 | T40: =VLOOKUP(M40,ItemData!$A$4:$B$415,2,FALSE) -> 214 | U40: =VLOOKUP(O40,ItemData!$A$4:$B$415,2,FALSE) -> 228 | X40: =S40&","&T40&IF(U40<>"",","&U40,"")&IF(V40<>"",","&V40,"") -> 204,214,228
B41: 1664 | C41: 水之羽衣 | D41: =VLOOKUP(C41,装备!$B$2:$J$60,9,FALSE)*0.75 -> 42.75 | E41: 4 | G41: 缝纫 | I41: 水之羽衣 | K41: 布衣 | L41: =VLOOKUP(K41,Sheet8!$A$1:$B$155,2,FALSE) -> #N/A | M41: 水晶石 | N41: =VLOOKUP(M41,Sheet8!$A$1:$B$155,2,FALSE) -> #N/A | O41: 防水皮革 | P41: =VLOOKUP(O41,Sheet8!$A$1:$B$155,2,FALSE) -> #N/A | S41: =VLOOKUP(K41,ItemData!$A$4:$B$415,2,FALSE) -> 1650 | T41: =VLOOKUP(M41,ItemData!$A$4:$B$415,2,FALSE) -> 232 | U41: =VLOOKUP(O41,ItemData!$A$4:$B$415,2,FALSE) -> 282 | X41: =S41&","&T41&IF(U41<>"",","&U41,"")&IF(V41<>"",","&V41,"") -> 1650,232,282
B42: 1665 | C42: 贵族长裙 | D42: =VLOOKUP(C42,装备!$B$2:$J$60,9,FALSE)*0.75 -> 41.25 | E42: 4 | G42: 缝纫 | I42: 贵族长裙 | K42: 华丽背心 | L42: =VLOOKUP(K42,Sheet8!$A$1:$B$155,2,FALSE) -> #N/A | M42: 贵族徽章 | N42: =VLOOKUP(M42,Sheet8!$A$1:$B$155,2,FALSE) -> #N/A | O42: 珍珠 | P42: =VLOOKUP(O42,Sheet8!$A$1:$B$155,2,FALSE) -> #N/A | Q42: 金块 | R42: =VLOOKUP(Q42,Sheet8!$A$1:$B$155,2,FALSE) -> #N/A | S42: =VLOOKUP(K42,ItemData!$A$4:$B$415,2,FALSE) -> 1657 | T42: =VLOOKUP(M42,ItemData!$A$4:$B$415,2,FALSE) -> 279 | U42: =VLOOKUP(O42,ItemData!$A$4:$B$415,2,FALSE) -> 234 | V42: =VLOOKUP(Q42,ItemData!$A$4:$B$415,2,FALSE) -> 247 | X42: =S42&","&T42&IF(U42<>"",","&U42,"")&IF(V42<>"",","&V42,"") -> 1657,279,234,247
B43: 1666 | C43: 幸运之衣 | D43: =VLOOKUP(C43,装备!$B$2:$J$60,9,FALSE)*0.75 -> 41.25 | E43: 4 | G43: 缝纫 | I43: 幸运之衣 | K43: 远古的硬币 | L43: =VLOOKUP(K43,Sheet8!$A$1:$B$155,2,FALSE) -> #N/A | M43: 布衣 | N43: =VLOOKUP(M43,Sheet8!$A$1:$B$155,2,FALSE) -> #N/A | O43: 脏绷带 | P43: =VLOOKUP(O43,Sheet8!$A$1:$B$155,2,FALSE) -> #N/A | Q43: 暮光结晶 | R43: =VLOOKUP(Q43,Sheet8!$A$1:$B$155,2,FALSE) -> #N/A | S43: =VLOOKUP(K43,ItemData!$A$4:$B$415,2,FALSE) -> 248 | T43: =VLOOKUP(M43,ItemData!$A$4:$B$415,2,FALSE) -> 1650 | U43: =VLOOKUP(O43,ItemData!$A$4:$B$415,2,FALSE) -> 245 | V43: =VLOOKUP(Q43,ItemData!$A$4:$B$415,2,FALSE) -> 285 | X43: =S43&","&T43&IF(U43<>"",","&U43,"")&IF(V43<>"",","&V43,"") -> 248,1650,245,285
B44: 1700 | C44: 布鞋 | D44: =VLOOKUP(C44,装备!$B$2:$J$60,9,FALSE)*0.75 -> 3 | E44: 1 | G44: 缝纫 | I44: 布鞋 | K44: 布片 | L44: =VLOOKUP(K44,Sheet8!$A$1:$B$155,2,FALSE) -> #N/A | M44: 兔子脚 | N44: =VLOOKUP(M44,Sheet8!$A$1:$B$165,2,FALSE) -> #N/A | O44: 粘液 | P44: =VLOOKUP(O44,Sheet8!$A$1:$B$155,2,FALSE) -> #N/A | S44: =VLOOKUP(K44,ItemData!$A$4:$B$415,2,FALSE) -> 204 | T44: =VLOOKUP(M44,ItemData!$A$4:$B$415,2,FALSE) -> 302 | U44: =VLOOKUP(O44,ItemData!$A$4:$B$415,2,FALSE) -> 278 | X44: =S44&","&T44&IF(U44<>"",","&U44,"")&IF(V44<>"",","&V44,"") -> 204,302,278
...

Sheet Sheet3
E5: 长剑 | G5: =$I5&","&$J5&","&$K5&","&$L5 -> 铁块,刀刃,, | I5: 铁块 | J5: 刀刃 | N5: 铸造,废铁,焦炭, | T5: 铸造,废铁,焦炭, | U5: 刀刃 | Z5: =T5&","&U5&","&V5&","&W5 -> 铸造,废铁,焦炭,,刀刃,,
E6: 诅咒之剑 | G6: =$I6&","&$J6&","&$K6&","&$L6 -> 长剑,眼球,诅咒宝珠, | I6: 长剑 | J6: 眼球 | K6: 诅咒宝珠 | N6: 铁块,刀刃,, | T6: 铁块,刀刃,, | U6: 眼球 | V6: 诅咒宝珠 | Z6: =T6&","&U6&","&V6&","&W6 -> 铁块,刀刃,,,眼球,诅咒宝珠,
E7: 烈焰之刃 | G7: =$I7&","&$J7&","&$K7&","&$L7 -> 长剑,火晶石,石英砂,白磷粉末 | I7: 长剑 | J7: 火晶石 | K7: 石英砂 | L7: 白磷粉末 | N7: 铁块,刀刃,, | T7: 铁块,刀刃,, | U7: 火晶石 | V7: 石英砂 | W7: 白磷粉末 | Z7: =T7&","&U7&","&V7&","&W7 -> 铁块,刀刃,,,火晶石,石英砂,白磷粉末
E8: 大地之剑 | G8: =$I8&","&$J8&","&$K8&","&$L8 -> 长剑,土晶石,钢,粘土 | I8: 长剑 | J8: 土晶石 | K8: 钢 | L8: 粘土 | N8: 铁块,刀刃,, | P8: 铸造,铁块,焦炭, | T8: 铁块,刀刃,, | U8: 土晶石 | V8: 铸造,铁块,焦炭, | W8: 粘土 | Z8: =T8&","&U8&","&V8&","&W8 -> 铁块,刀刃,,,土晶石,铸造,铁块,焦炭,,粘土
E9: 冰之刃 | G9: =$I9&","&$J9&","&$K9&","&$L9 -> 长剑,冰晶石,冰的结晶,雪球 | I9: 长剑 | J9: 冰晶石 | K9: 冰的结晶 | L9: 雪球 | N9: 铁块,刀刃,, | T9: 铁块,刀刃,, | U9: 冰晶石 | V9: 冰的结晶 | W9: 雪球 | Z9: =T9&","&U9&","&V9&","&W9 -> 铁块,刀刃,,,冰晶石,冰的结晶,雪球
E10: 铁枪 | G10: =$I10&","&$J10&","&$K10&","&$L10 -> 木棒,铁块,刀刃, | I10: 木棒 | J10: 铁块 | K10: 刀刃 | O10: 铸造,废铁,焦炭, | T10: 木棒 | U10: 铸造,废铁,焦炭, | V10: 刀刃 | Z10: =T10&","&U10&","&V10&","&W10 -> 木棒,铸造,废铁,焦炭,,刀刃,
E11: 血腥之枪 | G11: =$I11&","&$J11&","&$K11&","&$L11 -> 铁枪,魔族之血,银块,蜂刺 | I11: 铁枪 | J11: 魔族之血 | K11: 银块 | L11: 蜂刺 | N11: 木棒,铁块,刀刃, | T11: 木棒,铁块,刀刃, | U11: 魔族之血 | V11: 银块 | W11: 蜂刺 | Z11: =T11&","&U11&","&V11&","&W11 -> 木棒,铁块,刀刃,,魔族之血,银块,蜂刺
E12: 骑士长枪 | G12: =$I12&","&$J12&","&$K12&","&$L12 -> 铁枪,骑士之证,钢, | I12: 铁枪 | J12: 骑士之证 | K12: 钢 | N12: 木棒,铁块,刀刃, | P12: 铸造,铁块,焦炭, | T12: 木棒,铁块,刀刃, | U12: 骑士之证 | V12: 铸造,铁块,焦炭, | Z12: =T12&","&U12&","&V12&","&W12 -> 木棒,铁块,刀刃,,骑士之证,铸造,铁块,焦炭,,
E13: 三叉戟 | G13: =$I13&","&$J13&","&$K13&","&$L13 -> 铁枪,珊瑚,象牙,水晶石 | I13: 铁枪 | J13: 珊瑚 | K13: 象牙 | L13: 水晶石 | N13: 木棒,铁块,刀刃, | T13: 木棒,铁块,刀刃, | U13: 珊瑚 | V13: 象牙 | W13: 水晶石 | Z13: =T13&","&U13&","&V13&","&W13 -> 木棒,铁块,刀刃,,珊瑚,象牙,水晶石
E14: 秘银长剑 | G14: =$I14&","&$J14&","&$K14&","&$L14 -> 银块,刀刃,咒术药水,暮光结晶 | I14: 银块 | J14: 刀刃 | K14: 咒术药水 | L14: 暮光结晶 | T14: 银块 | U14: 刀刃 | V14: 咒术药水 | W14: 暮光结晶 | Z14: =T14&","&U14&","&V14&","&W14 -> 银块,刀刃,咒术药水,暮光结晶
E15: 幻影长枪 | G15: =$I15&","&$J15&","&$K15&","&$L15 -> 幻影水晶,铁枪,夜之幕,风晶石 | I15: 幻影水晶 | J15: 铁枪 | K15: 夜之幕 | L15: 风晶石 | O15: 木棒,铁块,刀刃, | T15: 幻影水晶 | U15: 木棒,铁块,刀刃, | V15: 夜之幕 | W15: 风晶石 | Z15: =T15&","&U15&","&V15&","&W15 -> 幻影水晶,木棒,铁块,刀刃,,夜之幕,风晶石
E16: 战斧 | G16: =$I16&","&$J16&","&$K16&","&$L16 -> 钢,刀刃,兽角, | I16: 钢 | J16: 刀刃 | K16: 兽角 | N16: 铸造,铁块,焦炭, | T16: 铸造,铁块,焦炭, | U16: 刀刃 | V16: 兽角 | Z16: =T16&","&U16&","&V16&","&W16 -> 铸造,铁块,焦炭,,刀刃,兽角,
E17: 毒蜥之牙 | G17: =$I17&","&$J17&","&$K17&","&$L17 -> 战斧,毒淤泥,狼牙, | I17: 战斧 | J17: 毒淤泥 | K17: 狼牙 | N17: 钢,刀刃,兽角, | T17: 钢,刀刃,兽角, | U17: 毒淤泥 | V17: 狼牙 | Z17: =T17&","&U17&","&V17&","&W17 -> 钢,刀刃,兽角,,毒淤泥,狼牙,
E18: 恶魔之斧 | G18: =$I18&","&$J18&","&$K18&","&$L18 -> 战斧,魔族之血,人狼之证,石化之眼 | I18: 战斧 | J18: 魔族之血 | K18: 人狼之证 | L18: 石化之眼 | N18: 钢,刀刃,兽角, | T18: 钢,刀刃,兽角, | U18: 魔族之血 | V18: 人狼之证 | W18: 石化之眼 | Z18: =T18&","&U18&","&V18&","&W18 -> 钢,刀刃,兽角,,魔族之血,人狼之证,石化之眼
E19: 暴雪斧 | G19: =$I19&","&$J19&","&$K19&","&$L19 -> 战斧,雪球,冰晶石,寒冰气息 | I19: 战斧 | J19: 雪球 | K19: 冰晶石 | L19: 寒冰气息 | N19: 钢,刀刃,兽角, | T19: 钢,刀刃,兽角, | U19: 雪球 | V19: 冰晶石 | W19: 寒冰气息 | Z19: =T19&","&U19&","&V19&","&W19 -> 钢,刀刃,兽角,,雪球,冰晶石,寒冰气息
E20: 蛇皮鞭 | G20: =$I20&","&$J20&","&$K20&","&$L20 -> 蛇皮,马尾,蛛丝, | I20: 蛇皮 | J20: 马尾 | K20: 蛛丝 | T20: 蛇皮 | U20: 马尾 | V20: 蛛丝 | Z20: =T20&","&U20&","&V20&","&W20 -> 蛇皮,马尾,蛛丝,
E21: 藤鞭 | G21: =$I21&","&$J21&","&$K21&","&$L21 -> 植物的藤,马尾,蛛丝, | I21: 植物的藤 | J21: 马尾 | K21: 蛛丝 | T21: 植物的藤 | U21: 马尾 | V21: 蛛丝 | Z21: =T21&","&U21&","&V21&","&W21 -> 植物的藤,马尾,蛛丝,
E22: 女王鞭 | G22: =$I22&","&$J22&","&$K22&","&$L22 -> 藤鞭,尖刺,幽魂, | I22: 藤鞭 | J22: 尖刺 | K22: 幽魂 | N22: 植物的藤,马尾,蛛丝, | T22: 植物的藤,马尾,蛛丝, | U22: 尖刺 | V22: 幽魂 | Z22: =T22&","&U22&","&V22&","&W22 -> 植物的藤,马尾,蛛丝,,尖刺,幽魂,
E23: 蛇牙鞭 | G23: =$I23&","&$J23&","&$K23&","&$L23 -> 蛇皮鞭,狼牙,, | I23: 蛇皮鞭 | J23: 狼牙 | N23: 蛇皮,马尾,蛛丝, | P23: 蛇皮,马尾,蛛丝, | T23: 蛇皮,马尾,蛛丝, | U23: 狼牙 | V23: 蛇皮,马尾,蛛丝, | Z23: =T23&","&U23&","&V23&","&W23 -> 蛇皮,马尾,蛛丝,,狼牙,蛇皮,马尾,蛛丝,,
E24: 雷神之鞭 | G24: =$I24&","&$J24&","&$K24&","&$L24 -> 雷鸣宝珠,电偶瓶,蜂刺,女王鞭 | I24: 雷鸣宝珠 | J24: 电偶瓶 | K24: 蜂刺 | L24: 女王鞭 | Q24: 植物的藤,马尾,蛛丝,尖刺,幽魂, | T24: 雷鸣宝珠 | U24: 电偶瓶 | V24: 蜂刺 | W24: 植物的藤,马尾,蛛丝,尖刺,幽魂, | Z24: =T24&","&U24&","&V24&","&W24 -> 雷鸣宝珠,电偶瓶,蜂刺,植物的藤,马尾,蛛丝,尖刺,幽魂,
E25: 死亡之鞭 | G25: =$I25&","&$J25&","&$K25&","&$L25 -> 脏绷带,亡者之土,寒冰火种,蛇牙鞭 | I25: 脏绷带 | J25: 亡者之土 | K25: 寒冰火种 | L25: 蛇牙鞭 | Q25: 蛇皮,马尾,蛛丝,,狼牙, | T25: 脏绷带 | U25: 亡者之土 | V25: 寒冰火种 | W25: 蛇皮,马尾,蛛丝,,狼牙, | Z25: =T25&","&U25&","&V25&","&W25 -> 脏绷带,亡者之土,寒冰火种,蛇皮,马尾,蛛丝,,狼牙,
E26: 布衣 | G26: =$I26&","&$J26&","&$K26&","&$L26 -> 布片,毛线,, | I26: 布片 | J26: 毛线 | N26: 纺织,毛线,, | O26: 纺线,羊毛,, | T26: 纺织,毛线,, | U26: 纺线,羊毛,, | Z26: =T26&","&U26&","&V26&","&W26 -> 纺织,毛线,,,纺线,羊毛,,,,
E27: 皮铠 | G27: =$I27&","&$J27&","&$K27&","&$L27 -> 皮革,粘液,蛛丝, | I27: 皮革 | J27: 粘液 | K27: 蛛丝 | N27: 鞣制,兽皮,, | T27: 鞣制,兽皮,, | U27: 粘液 | V27: 蛛丝 | Z27: =T27&","&U27&","&V27&","&W27 -> 鞣制,兽皮,,,粘液,蛛丝,
E28: 锁子甲 | G28: =$I28&","&$J28&","&$K28&","&$L28 -> 皮铠,珊瑚,钢, | I28: 皮铠 | J28: 珊瑚 | K28: 钢 | N28: 皮革,粘液,蛛丝, | P28: 铸造,铁块,焦炭, | T28: 皮革,粘液,蛛丝, | U28: 珊瑚 | V28: 铸造,铁块,焦炭, | Z28: =T28&","&U28&","&V28&","&W28 -> 皮革,粘液,蛛丝,,珊瑚,铸造,铁块,焦炭,,
E29: 毛皮斗篷 | G29: =$I29&","&$J29&","&$K29&","&$L29 -> 皮铠,魔兽皮毛,羊毛, | I29: 皮铠 | J29: 魔兽皮毛 | K29: 羊毛 | N29: 皮革,粘液,蛛丝, | T29: 皮革,粘液,蛛丝, | U29: 魔兽皮毛 | V29: 羊毛 | Z29: =T29&","&U29&","&V29&","&W29 -> 皮革,粘液,蛛丝,,魔兽皮毛,羊毛,
E30: 铁铠甲 | G30: =$I30&","&$J30&","&$K30&","&$L30 -> 铁块,石英砂,, | I30: 铁块 | J30: 石英砂 | N30: 铸造,废铁,焦炭, | T30: 铸造,废铁,焦炭, | U30: 石英砂 | Z30: =T30&","&U30&","&V30&","&W30 -> 铸造,废铁,焦炭,,石英砂,,
E31: 红莲之铠 | G31: =$I31&","&$J31&","&$K31&","&$L31 -> 铁铠甲,遗骨,火晶石,魔力之土 | I31: 铁铠甲 | J31: 遗骨 | K31: 火晶石 | L31: 魔力之土 | N31: 铁块,石英砂,, | T31: 铁块,石英砂,, | U31: 遗骨 | V31: 火晶石 | W31: 魔力之土 | Z31: =T31&","&U31&","&V31&","&W31 -> 铁块,石英砂,,,遗骨,火晶石,魔力之土
E32: 铁龟铠 | G32: =$I32&","&$J32&","&$K32&","&$L32 -> 龟壳,铁铠甲,琥珀, | I32: 龟壳 | J32: 铁铠甲 | K32: 琥珀 | O32: 铁块,石英砂,, | T32: 龟壳 | U32: 铁块,石英砂,, | V32: 琥珀 | Z32: =T32&","&U32&","&V32&","&W32 -> 龟壳,铁块,石英砂,,,琥珀,
E33: 华丽背心 | G33: =$I33&","&$J33&","&$K33&","&$L33 -> 彩色的布,彩色羽毛,毛线, | I33: 彩色的布 | J33: 彩色羽毛 | K33: 毛线 | P33: 纺线,羊毛,, | T33: 彩色的布 | U33: 彩色羽毛 | V33: 纺线,羊毛,, | Z33: =T33&","&U33&","&V33&","&W33 -> 彩色的布,彩色羽毛,纺线,羊毛,,,
E34: 鳞铠 | G34: =$I34&","&$J34&","&$K34&","&$L34 -> 鳞片,粘液,皮革, | I34: 鳞片 | J34: 粘液 | K34: 皮革 | P34: 鞣制,兽皮,, | T34: 鳞片 | U34: 粘液 | V34: 鞣制,兽皮,, | Z34: =T34&","&U34&","&V34&","&W34 -> 鳞片,粘液,鞣制,兽皮,,,
E35: 暗之袍 | G35: =$I35&","&$J35&","&$K35&","&$L35 -> 夜之幕,毛线,亡者之土,幽魂 | I35: 夜之幕 | J35: 毛线 | K35: 亡者之土 | L35: 幽魂 | O35: 纺线,羊毛,, | T35: 夜之幕 | U35: 纺线,羊毛,, | V35: 亡者之土 | W35: 幽魂 | Z35: =T35&","&U35&","&V35&","&W35 -> 夜之幕,纺线,羊毛,,,亡者之土,幽魂
E36: 疾风背心 | G36: =$I36&","&$J36&","&$K36&","&$L36 -> 布衣,风晶石,奇美拉之翼, | I36: 布衣 | J36: 风晶石 | K36: 奇美拉之翼 | N36: 布片,毛线,, | T36: 布片,毛线,, | U36: 风晶石 | V36: 奇美拉之翼 | Z36: =T36&","&U36&","&V36&","&W36 -> 布片,毛线,,,风晶石,奇美拉之翼,
E37: 魔法铠甲 | G37: =$I37&","&$J37&","&$K37&","&$L37 -> 皮铠,水晶球,金块,兽角 | I37: 皮铠 | J37: 水晶球 | K37: 金块 | L37: 兽角 | N37: 皮革,粘液,蛛丝, | T37: 皮革,粘液,蛛丝, | U37: 水晶球 | V37: 金块 | W37: 兽角 | Z37: =T37&","&U37&","&V37&","&W37 -> 皮革,粘液,蛛丝,,水晶球,金块,兽角
E38: 钢刃锁甲 | G38: =$I38&","&$J38&","&$K38&","&$L38 -> 铁铠甲,刀刃,钢,土晶石 | I38: 铁铠甲 | J38: 刀刃 | K38: 钢 | L38: 土晶石 | N38: 铁块,石英砂,, | P38: 铸造,铁块,焦炭, | T38: 铁块,石英砂,, | U38: 刀刃 | V38: 铸造,铁块,焦炭, | W38: 土晶石 | Z38: =T38&","&U38&","&V38&","&W38 -> 铁块,石英砂,,,刀刃,铸造,铁块,焦炭,,土晶石
E39: 丝织长袍 | G39: =$I39&","&$J39&","&$K39&","&$L39 -> 布片,蛛丝,彩色羽毛, | I39: 布片 | J39: 蛛丝 | K39: 彩色羽毛 | N39: 纺织,毛线,, | T39: 纺织,毛线,, | U39: 蛛丝 | V39: 彩色羽毛 | Z39: =T39&","&U39&","&V39&","&W39 -> 纺织,毛线,,,蛛丝,彩色羽毛,
E40: 水之羽衣 | G40: =$I40&","&$J40&","&$K40&","&$L40 -> 布衣,水晶石,防水皮革, | I40: 布衣 | J40: 水晶石 | K40: 防水皮革 | N40: 布片,毛线,, | T40: 布片,毛线,, | U40: 水晶石 | V40: 防水皮革 | Z40: =T40&","&U40&","&V40&","&W40 -> 布片,毛线,,,水晶石,防水皮革,
E41: 贵族长裙 | G41: =$I41&","&$J41&","&$K41&","&$L41 -> 华丽背心,贵族徽章,珍珠,金块 | I41: 华丽背心 | J41: 贵族徽章 | K41: 珍珠 | L41: 金块 | N41: 彩色的布,彩色羽毛,毛线, | T41: 彩色的布,彩色羽毛,毛线, | U41: 贵族徽章 | V41: 珍珠 | W41: 金块 | Z41: =T41&","&U41&","&V41&","&W41 -> 彩色的布,彩色羽毛,毛线,,贵族徽章,珍珠,金块
E42: 幸运之衣 | G42: =$I42&","&$J42&","&$K42&","&$L42 -> 远古的硬币,布衣,脏绷带,暮光结晶 | I42: 远古的硬币 | J42: 布衣 | K42: 脏绷带 | L42: 暮光结晶 | O42: 布片,毛线,, | T42: 远古的硬币 | U42: 布片,毛线,, | V42: 脏绷带 | W42: 暮光结晶 | Z42: =T42&","&U42&","&V42&","&W42 -> 远古的硬币,布片,毛线,,,脏绷带,暮光结晶
E43: 布鞋 | G43: =$I43&","&$J43&","&$K43&","&$L43 -> 布片,鹿角,粘液, | I43: 布片 | J43: 鹿角 | K43: 粘液 | N43: 纺织,毛线,, | T43: 纺织,毛线,, | U43: 鹿角 | V43: 粘液 | Z43: =T43&","&U43&","&V43&","&W43 -> 纺织,毛线,,,鹿角,粘液,
E44: 皮鞋 | G44: =$I44&","&$J44&","&$K44&","&$L44 -> 皮革,鹿角,粘液, | I44: 皮革 | J44: 鹿角 | K44: 粘液 | N44: 鞣制,兽皮,, | T44: 鞣制,兽皮,, | U44: 鹿角 | V44: 粘液 | Z44: =T44&","&U44&","&V44&","&W44 -> 鞣制,兽皮,,,鹿角,粘液,
...

Sheet Sheet1
C3: 1 | D3: 2 | E3: 3 | F3: 4 | G3: 5 | H3: 6 | I3: 7 | J3: 8
D4: hp | E4: mp | F4: 体力 | G4: 攻击buff | H4: 防御buff | I4: 速度buff | J4: 幸运buff
C5: 腌芜菁 | D5: 15
C6: 蔬菜沙拉 | D6: 50
C7: 三明治 | F7: 80 | I7: 25
C8: 腌萝卜 | D8: 20
C9: 拉面 | F9: 120
C10: 蜂蜜蛋糕 | F10: 100
C11: 披萨 | F11: 140
C12: 腌黄瓜 | D12: 25
C13: 烤西兰花 | D13: 35
C14: 水煮蛋 | E14: 10
C15: 烤肉串 | H15: 40
C16: 饭团 | F16: 20
C17: 面包 | F17: 60
C18: 烤海苔 | I18: 7
C19: 烤肉饼 | H19: 55
C20: 汉堡 | F20: 160
C21: 辣蟹堡 | E21: 50
C22: 土豆泥 | D22: 80
C23: 海鲜饭 | F23: 180
C24: 烤玉米 | D24: 100
C25: 蔬菜汁 | I25: 10
C26: 西瓜果汁 | J26: 15
C27: 奇异果汁 | J27: 20
C28: 葡萄汁 | J28: 26
C29: 菠萝汁 | J29: 25
C30: 草莓汁 | J30: 28
C31: 蓝莓汁 | J31: 28
C32: 玉米汁 | I32: 15
C33: 烤蜜薯 | D33: 140
C34: 甜菜汁 | I34: 35
C35: 奶酪
C36: 烤茄子 | D36: 90
C37: 饺子 | D37: 80 | E37: 30 | F37: 80
C38: 炖菜 | D38: 140 | E38: 80
C39: 烤芦笋 | D39: 40
C40: 红菜汤 | E40: 70
C41: 豌豆汤 | E41: 80
C42: 草莓牛奶 | E42: 100 | J42: 35
...

Sheet Sheet5
N10: 1 | O10: =ROUND(81.431*POWER(N10,0.5173),0) -> 81 | Q10: 82
N11: 2 | O11: =ROUND(81.431*POWER(N11,0.5173),0) -> 117 | P11: =O11-O10 -> 36 | Q11: 115
N12: 3 | O12: =ROUND(81.431*POWER(N12,0.5173),0) -> 144 | P12: =O12-O11 -> 27 | Q12: 144
K13: 82 | N13: 4 | O13: =ROUND(81.431*POWER(N13,0.5173),0) -> 167 | P13: =O13-O12 -> 23 | Q13: 166
K14: 115 | L14: =K14-K13 -> 33 | N14: 5 | O14: =ROUND(81.431*POWER(N14,0.5173),0) -> 187 | P14: =O14-O13 -> 20 | Q14: 189
K15: 144 | L15: =K15-K14 -> 29 | N15: 6 | O15: =ROUND(81.431*POWER(N15,0.5173),0) -> 206 | P15: =O15-O14 -> 19 | Q15: 206
K16: 166 | L16: =K16-K15 -> 22 | N16: 7 | O16: =ROUND(81.431*POWER(N16,0.5173),0) -> 223 | P16: =O16-O15 -> 17 | Q16: 224
K17: 189 | L17: =K17-K16 -> 23 | N17: 8 | O17: =ROUND(81.431*POWER(N17,0.5173),0) -> 239 | P17: =O17-O16 -> 16 | Q17: 238
K18: 206 | L18: =K18-K17 -> 17 | N18: 9 | O18: =ROUND(81.431*POWER(N18,0.5173),0) -> 254 | P18: =O18-O17 -> 15 | Q18: 253
K19: 224 | L19: =K19-K18 -> 18 | N19: 10 | O19: =ROUND(81.431*POWER(N19,0.5173),0) -> 268 | P19: =O19-O18 -> 14
K20: 238 | L20: =K20-K19 -> 14 | N20: 11 | O20: =ROUND(81.431*POWER(N20,0.5173),0) -> 282 | P20: =O20-O19 -> 14
K21: 253 | L21: =K21-K20 -> 15 | N21: 12 | O21: =ROUND(81.431*POWER(N21,0.5173),0) -> 294 | P21: =O21-O20 -> 12
N22: 13 | O22: =ROUND(81.431*POWER(N22,0.5173),0) -> 307 | P22: =O22-O21 -> 13
N23: 14 | O23: =ROUND(81.431*POWER(N23,0.5173),0) -> 319 | P23: =O23-O22 -> 12
N24: 15 | O24: =ROUND(81.431*POWER(N24,0.5173),0) -> 331 | P24: =O24-O23 -> 12
N25: 16 | O25: =ROUND(81.431*POWER(N25,0.5173),0) -> 342 | P25: =O25-O24 -> 11
K40: 82 | L40: 33 | N40: 1 | O40: =N40*N40*N40*2.5-N40*N40*2.5+23*N40+59 -> 82
K41: =K40+L40 -> 115 | L41: =L40+M41 -> 58 | M41: 25 | N41: 2 | O41: =N41*N41*N41*2.5-N41*N41*2.5+23*N41+59 -> 115
K42: =K41+L41 -> 173 | L42: =L41+M42 -> 98 | M42: 40 | N42: 3 | O42: =N42*N42*N42*2.5-N42*N42*2.5+23*N42+59 -> 173
K43: =K42+L42 -> 271 | L43: =L42+M43 -> 153 | M43: 55 | N43: 4 | O43: =N43*N43*N43*2.5-N43*N43*2.5+23*N43+59 -> 271
K44: =K43+L43 -> 424 | L44: =L43+M44 -> 223 | M44: 70 | N44: 5 | O44: =N44*N44*N44*2.5-N44*N44*2.5+23*N44+59 -> 424
K45: =K44+L44 -> 647 | L45: =L44+M45 -> 308 | M45: 85 | N45: 6 | O45: =N45*N45*N45*2.5-N45*N45*2.5+23*N45+59 -> 647
K46: =K45+L45 -> 955 | L46: =L45+M46 -> 408 | M46: 100 | N46: 7 | O46: =N46*N46*N46*2.5-N46*N46*2.5+23*N46+59 -> 955
K47: =K46+L46 -> 1363 | N47: 8 | O47: =N47*N47*N47*2.5-N47*N47*2.5+23*N47+59 -> 1363
N48: 9 | O48: =N48*N48*N48*2.5-N48*N48*2.5+23*N48+59 -> 1886
N49: 10 | O49: =N49*N49*N49*2.5-N49*N49*2.5+23*N49+59 -> 2539
N50: 11 | O50: =N50*N50*N50*2.5-N50*N50*2.5+23*N50+59 -> 3337
N51: 12 | O51: =N51*N51*N51*2.5-N51*N51*2.5+23*N51+59 -> 4295
N52: 13 | O52: =N52*N52*N52*2.5-N52*N52*2.5+23*N52+59 -> 5428
N53: 14 | O53: =N53*N53*N53*2.5-N53*N53*2.5+23*N53+59 -> 6751

Sheet 植物
C3: 芜菁
C4: 卷心菜
C5: 葱
C6: 萝卜
C7: 紫甘蓝
C8: 黄瓜
C9: 西兰花
C10: 番茄
C11: 胡萝卜
C12: 西瓜
C13: 辣椒
C14: 奇异果
... C28: 蓝莓
C29: 红薯 | Q29: =Q33*9 -> 375
C30: 甜菜
B32: 收益倍率 | E32: 产量 | F32: 价格 | G32: 天 | H32: 采摘次数 | I32: 采摘周期 | J32: 存活总天数 | K32: 寿命 | L32: 一年存活循环 | M32: 一年总花费 | N32: 一年总收获 | O32: 一年总收益 | P32: 净收入 | Q32: 产物单价
B33: 5 | C33: 芜菁种子 | E33: 3 | F33: =ROUND(F86*0.3,0) -> 25 | G33: 3 | H33: 1 | I33: =IF(H33=1,0,ROUND(G33*0.4,0)) -> 0 | J33: =G33+(H33-1)*I33 -> 3 | L33: =120/J33 -> 40 | M33: =L33*F33 -> 1000 | N33: =L33*E33*H33 -> 120 | O33: =M33*B33 -> 5000 | P33: =O33-M33 -> 4000 | Q33: =O33/N33 -> 41.666667 | S33: 83
B34: 5 | C34: 卷心菜种子 | E34: 3 | F34: =ROUND(F87*0.3,0) -> 25 | G34: 3 | H34: 1 | I34: =IF(H34=1,0,ROUND(G34*0.4,0)) -> 0 | J34: =G34+(H34-1)*I34 -> 3 | L34: =120/J34 -> 40 | M34: =L34*F34 -> 1000 | N34: =L34*E34*H34 -> 120 | O34: =M34*B34 -> 5000 | P34: =O34-M34 -> 4000 | Q34: =O34/N34 -> 41.666667 | S34: 114
B35: 5 | C35: 葱种子 | E35: 4 | F35: =ROUND(F88*0.3,0) -> 35 | G35: 4 | H35: 1 | I35: =IF(H35=1,0,ROUND(G35*0.4,0)) -> 0 | J35: =G35+(H35-1)*I35 -> 4 | L35: =120/J35 -> 30 | M35: =L35*F35 -> 1050 | N35: =L35*E35*H35 -> 120 | O35: =M35*B35 -> 5250 | P35: =O35-M35 -> 4200 | Q35: =O35/N35 -> 43.75 | S35: 148
B36: 5 | C36: 萝卜种子 | E36: 4 | F36: =ROUND(F89*0.3,0) -> 35 | G36: 4 | H36: 1 | I36: =IF(H36=1,0,ROUND(G36*0.4,0)) -> 0 | J36: =G36+(H36-1)*I36 -> 4 | L36: =120/J36 -> 30 | M36: =L36*F36 -> 1050 | N36: =L36*E36*H36 -> 120 | O36: =M36*B36 -> 5250 | P36: =O36-M36 -> 4200 | Q36: =O36/N36 -> 43.75 | S36: 183
B37: 5 | C37: 紫甘蓝种子 | E37: 3 | F37: =ROUND(F90*0.3,0) -> 52 | G37: 4 | H37: 1 | I37: =IF(H37=1,0,ROUND(G37*0.4,0)) -> 0 | J37: =G37+(H37-1)*I37 -> 4 | L37: =120/J37 -> 30 | M37: =L37*F37 -> 1560 | N37: =L37*E37*H37 -> 90 | O37: =M37*B37 -> 7800 | P37: =O37-M37 -> 6240 | Q37: =O37/N37 -> 86.666667 | S37: 221 | U37: 鸡蛋
B38: 12 | C38: 黄瓜种子 | E38: 4 | F38: =ROUND(F91*0.3,0) -> 52 | G38: 6 | H38: 3 | I38: =IF(H38=1,0,ROUND(G38*0.4,0)) -> 2 | J38: =G38+(H38-1)*I38 -> 10 | L38: =120/J38 -> 12 | M38: =L38*F38 -> 624 | N38: =L38*E38*H38 -> 144 | O38: =M38*B38 -> 7488 | P38: =O38-M38 -> 6864 | Q38: =O38/N38 -> 52 | S38: 261 | U38: 鸭绒
B39: 5 | C39: 西兰花种子 | E39: 3 | F39: =ROUND(F92*0.3,0) -> 52 | G39: 5 | H39: 1 | I39: =IF(H39=1,0,ROUND(G39*0.4,0)) -> 0 | J39: =G39+(H39-1)*I39 -> 5 | L39: =120/J39 -> 24 | M39: =L39*F39 -> 1248 | N39: =L39*E39*H39 -> 72 | O39: =M39*B39 -> 6240 | P39: =O39-M39 -> 4992 | Q39: =O39/N39 -> 86.666667 | S39: 303 | U39: 兔耳
B40: 12 | C40: 番茄种子 | E40: 4 | F40: =ROUND(F93*0.3,0) -> 81 | G40: 8 | H40: 2 | I40: =IF(H40=1,0,ROUND(G40*0.4,0)) -> 3 | J40: =G40+(H40-1)*I40 -> 11 | L40: =120/J40 -> 10.909091 | M40: =L40*F40 -> 883.63636 | N40: =L40*E40*H40 -> 87.272727 | O40: =M40*B40 -> 10603.636 | P40: =O40-M40 -> 9720 | Q40: =O40/N40 -> 121.5 | S40: 348
B41: 5 | C41: 胡萝卜种子 | E41: 3 | F41: =ROUND(F94*0.3,0) -> 81 | G41: 5 | H41: 1 | I41: =IF(H41=1,0,ROUND(G41*0.4,0)) -> 0 | J41: =G41+(H41-1)*I41 -> 5 | L41: =120/J41 -> 24 | M41: =L41*F41 -> 1944 | N41: =L41*E41*H41 -> 72 | O41: =M41*B41 -> 9720 | P41: =O41-M41 -> 7776 | Q41: =O41/N41 -> 135 | S41: 395 | U41: 羊毛
B42: 6 | C42: 西瓜种子 | E42: 2 | F42: =ROUND(F95*0.3,0) -> 81 | G42: 6 | H42: 1 | I42: =IF(H42=1,0,ROUND(G42*0.4,0)) -> 0 | J42: =G42+(H42-1)*I42 -> 6 | L42: =120/J42 -> 20 | M42: =L42*F42 -> 1620 | N42: =L42*E42*H42 -> 40 | O42: =M42*B42 -> 9720 | P42: =O42-M42 -> 8100 | Q42: =O42/N42 -> 243 | S42: 444
B43: 15 | C43: 辣椒种子 | E43: 5 | F43: =ROUND(F96*0.3,0) -> 127 | G43: 10 | H43: 3 | I43: =IF(H43=1,0,ROUND(G43*0.4,0)) -> 4 | J43: =G43+(H43-1)*I43 -> 18 | L43: =120/J43 -> 6.6666667 | M43: =L43*F43 -> 846.66667 | N43: =L43*E43*H43 -> 100 | O43: =M43*B43 -> 12700 | P43: =O43-M43 -> 11853.333 | Q43: =O43/N43 -> 127 | S43: 495
B44: 10 | C44: 茄子种子 | E44: 6 | F44: =ROUND(F97*0.3,0) -> 127 | G44: 7 | H44: 2 | I44: =IF(H44=1,0,ROUND(G44*0.4,0)) -> 3 | J44: =G44+(H44-1)*I44 -> 10 | L44: =120/J44 -> 12 | M44: =L44*F44 -> 1524 | N44: =L44*E44*H44 -> 144 | O44: =M44*B44 -> 15240 | P44: =O44-M44 -> 13716 | Q44: =O44/N44 -> 105.83333 | S44: 548 | U44: 猪肉
B45: 26 | C45: 奇异果种子 | E45: 3 | F45: =ROUND(F98*0.3,0) -> 127 | G45: 16 | H45: 4 | I45: =IF(H45=1,0,ROUND(G45*0.4,0)) -> 6 | J45: =G45+(H45-1)*I45 -> 34 | L45: =120/J45 -> 3.5294118 | M45: =L45*F45 -> 448.23529 | N45: =L45*E45*H45 -> 42.352941 | O45: =M45*B45 -> 11654.118 | P45: =O45-M45 -> 11205.882 | Q45: =O45/N45 -> 275.16667 | S45: 604
B46: 6 | C46: 豌豆种子 | E46: 6 | F46: =ROUND(F99*0.3,0) -> 194 | G46: 6 | H46: 1 | I46: =IF(H46=1,0,ROUND(G46*0.4,0)) -> 0 | J46: =G46+(H46-1)*I46 -> 6 | L46: =120/J46 -> 20 | M46: =L46*F46 -> 3880 | N46: =L46*E46*H46 -> 120 | O46: =M46*B46 -> 23280 | P46: =O46-M46 -> 19400 | Q46: =O46/N46 -> 194 | S46: 662 | U46: 牛奶
B47: 7 | C47: 土豆种子 | E47: 4 | F47: =ROUND(F100*0.3,0) -> 194 | G47: 8 | H47: 1 | I47: =IF(H47=1,0,ROUND(G47*0.4,0)) -> 0 | J47: =G47+(H47-1)*I47 -> 8 | L47: =120/J47 -> 15 | M47: =L47*F47 -> 2910 | N47: =L47*E47*H47 -> 60 | O47: =M47*B47 -> 20370 | P47: =O47-M47 -> 17460 | Q47: =O47/N47 -> 339.5
B48: 7 | C48: 大蒜种子 | E48: 6 | F48: =ROUND(F101*0.3,0) -> 194 | G48: 8 | H48: 1 | I48: =IF(H48=1,0,ROUND(G48*0.4,0)) -> 0 | J48: =G48+(H48-1)*I48 -> 8 | L48: =120/J48 -> 15 | M48: =L48*F48 -> 2910 | N48: =L48*E48*H48 -> 90 | O48: =M48*B48 -> 20370 | P48: =O48-M48 -> 17460 | Q48: =O48/N48 -> 226.33333
B49: 6 | C49: 芦笋种子 | E49: 4 | F49: =ROUND(F102*0.3,0) -> 287 | G49: 6 | H49: 1 | I49: =IF(H49=1,0,ROUND(G49*0.4,0)) -> 0 | J49: =G49+(H49-1)*I49 -> 6 | L49: =120/J49 -> 20 | M49: =L49*F49 -> 5740 | N49: =L49*E49*H49 -> 80 | O49: =M49*B49 -> 34440 | P49: =O49-M49 -> 28700 | Q49: =O49/N49 -> 430.5 | U49: 马尾
B50: 8 | C50: 南瓜种子 | E50: 3 | F50: =ROUND(F103*0.3,0) -> 287 | G50: 7 | H50: 2 | I50: =IF(H50=1,0,ROUND(G50*0.4,0)) -> 3 | J50: =G50+(H50-1)*I50 -> 10 | L50: =120/J50 -> 12 | M50: =L50*F50 -> 3444 | N50: =L50*E50*H50 -> 72 | O50: =M50*B50 -> 27552 | P50: =O50-M50 -> 24108 | Q50: =O50/N50 -> 382.66667
B51: 10 | C51: 玉米种子 | E51: 8 | F51: =ROUND(F104*0.3,0) -> 287 | G51: 12 | H51: 1 | I51: =IF(H51=1,0,ROUND(G51*0.4,0)) -> 0 | J51: =G51+(H51-1)*I51 -> 12 | L51: =120/J51 -> 10 | M51: =L51*F51 -> 2870 | N51: =L51*E51*H51 -> 80 | O51: =M51*B51 -> 28700 | P51: =O51-M51 -> 25830 | Q51: =O51/N51 -> 358.75
B52: 8 | C52: 大麦种子 | E52: 8 | F52: =ROUND(F105*0.3,0) -> 409 | G52: 12 | H52: 1 | I52: =IF(H52=1,0,ROUND(G52*0.4,0)) -> 0 | J52: =G52+(H52-1)*I52 -> 12 | L52: =120/J52 -> 10 | M52: =L52*F52 -> 4090 | N52: =L52*E52*H52 -> 80 | O52: =M52*B52 -> 32720 | P52: =O52-M52 -> 28630 | Q52: =O52/N52 -> 409
B53: 25 | C53: 啤酒花种子 | E53: 8 | F53: =ROUND(F106*0.3,0) -> 409 | G53: 20 | H53: 4 | I53: =IF(H53=1,0,ROUND(G53*0.4,0)) -> 8 | J53: =G53+(H53-1)*I53 -> 44 | L53: =120/J53 -> 2.7272727 | M53: =L53*F53 -> 1115.4545 | N53: =L53*E53*H53 -> 87.272727 | O53: =M53*B53 -> 27886.364 | P53: =O53-M53 -> 26770.909 | Q53: =O53/N53 -> 319.53125
B54: 40 | C54: 葡萄种子 | E54: 8 | F54: =ROUND(F107*0.3,0) -> 409 | G54: 22 | H54: 6 | I54: =IF(H54=1,0,ROUND(G54*0.4,0)) -> 9 | J54: =G54+(H54-1)*I54 -> 67 | L54: =120/J54 -> 1.7910448 | M54: =L54*F54 -> 732.53731 | N54: =L54*E54*H54 -> 85.970149 | O54: =M54*B54 -> 29301.493 | P54: =O54-M54 -> 28568.955 | Q54: =O54/N54 -> 340.83333
