Workbook

Sheet MapNpcData
A1: MapNpcData | B1: mapNpcDatas
A2: string | B2: int | C2: int | D2: bool | E2: int | F2: int2
A3: npcName | B3: id | C3: dataId | D3: initialBegin | E3: beginMap | F3: beginCoordinate
A4: 班尼迪克 | B4: 3000 | C4: =VLOOKUP(A4,Sheet1!$B$16:$C$54,2,FALSE) -> 3 | D4: TRUE | E4: 1014 | F4: 44,33
A5: 马 | B5: 3001 | C5: =VLOOKUP(A5,Sheet1!$B$16:$C$54,2,FALSE) -> 4 | D5: FALSE | E5: -1000 | F5: 2,3
A6: 布莱兹 | B6: 2000 | C6: =VLOOKUP(A6,Sheet1!$B$16:$C$54,2,FALSE) -> 6 | D6: FALSE | E6: 948 | F6: -10,12
A7: 玛德琳 | B7: 2001 | C7: =VLOOKUP(A7,Sheet1!$B$16:$C$54,2,FALSE) -> 5 | D7: FALSE | E7: 948 | F7: -50,20
A8: 丝特芬妮 | B8: 2002 | C8: =VLOOKUP(A8,Sheet1!$B$16:$C$54,2,FALSE) -> 7 | D8: FALSE | E8: 900 | F8: -68,15
A9: 格吉尔 | B9: 2003 | C9: =VLOOKUP(A9,Sheet1!$B$16:$C$54,2,FALSE) -> 8 | D9: FALSE | E9: 900 | F9: -60,33
A10: 琼 | B10: 2004 | C10: =VLOOKUP(A10,Sheet1!$B$16:$C$54,2,FALSE) -> 10 | D10: FALSE | E10: 5170 | F10: -26,6
A11: 强尼 | B11: 2005 | C11: =VLOOKUP(A11,Sheet1!$B$16:$C$54,2,FALSE) -> 31 | D11: FALSE | E11: 5170 | F11: 22,5
A12: 奥蒂莉亚 | B12: 2006 | C12: 14 | D12: FALSE | E12: 1014 | F12: 6,5
A13: 希拉 | B13: 2007 | C13: =VLOOKUP(A13,Sheet1!$B$16:$C$54,2,FALSE) -> 17 | D13: FALSE | E13: 1014 | F13: 0,37
A14: 坎蒂丝 | B14: 2008 | C14: 16 | D14: FALSE | E14: 2180 | F14: 0,23
A15: 黛芙妮 | B15: 2009 | C15: =VLOOKUP(A15,Sheet1!$B$16:$C$54,2,FALSE) -> 40 | D15: FALSE | E15: 2180 | F15: 15,5
A16: 艾琳娜 | B16: 2010 | C16: =VLOOKUP(A16,Sheet1!$B$16:$C$54,2,FALSE) -> 36 | D16: FALSE | E16: 2180 | F16: -20,6
A17: 希贝儿 | B17: 2011 | C17: =VLOOKUP(A17,Sheet1!$B$16:$C$54,2,FALSE) -> 22 | D17: FALSE | E17: 3056 | F17: 0,10
A18: 梅林 | B18: 2012 | C18: =VLOOKUP(A18,Sheet1!$B$16:$C$54,2,FALSE) -> 25 | D18: FALSE | E18: 3056 | F18: -4,16
A19: 帕特里克 | B19: 2013 | C19: =VLOOKUP(A19,Sheet1!$B$16:$C$54,2,FALSE) -> 23 | D19: FALSE | E19: 2015 | F19: 0,0
A20: 摩尔根 | B20: 2014 | C20: =VLOOKUP(A20,Sheet1!$B$16:$C$54,2,FALSE) -> 26 | D20: FALSE | E20: 2902 | F20: 0,9
A21: 瓦尔特 | B21: 2015 | C21: =VLOOKUP(A21,Sheet1!$B$16:$C$54,2,FALSE) -> 34 | D21: FALSE | E21: 1912 | F21: -8,-11
A22: 布拉德利 | B22: 2016 | C22: =VLOOKUP(A22,Sheet1!$B$16:$C$54,2,FALSE) -> 19 | D22: FALSE | E22: 1756 | F22: -6,-10
A23: 莱特 | B23: 2017 | C23: =VLOOKUP(A23,Sheet1!$B$16:$C$54,2,FALSE) -> 37 | D23: FALSE | E23: 1756 | F23: -27,16
A24: 阿尔杰农 | B24: 2018 | C24: =VLOOKUP(A24,Sheet1!$B$16:$C$54,2,FALSE) -> 39 | D24: FALSE | E24: 1912 | F24: -8,0
A25: 亚度尼斯 | B25: 2019 | C25: =VLOOKUP(A25,Sheet1!$B$16:$C$54,2,FALSE) -> 9 | D25: FALSE | E25: 5170 | F25: -2,-20
A26: 占卜婆婆 | B26: 2020 | C26: =VLOOKUP(A26,Sheet1!$B$16:$C$54,2,FALSE) -> 12 | D26: FALSE | E26: 4800 | F26: -2,15
... A36: 纺织婆婆 | B36: 2030 | C36: =VLOOKUP(A36,Sheet1!$B$16:$C$54,2,FALSE) -> 41 | D36: FALSE | E36: 5309 | F36: 10,14

Sheet Sheet1
B16: npcName | C16: id
B17: 班尼迪克 | C17: 3 | E17: 玛德琳 | F17: 亚度尼斯 | G17: 琼 | H17: 占卜婆婆 | I17: 布蓝达 | J17: 帕特里克 | K17: 梅林 | L17: 摩尔根 | M17: 马勒第兹 | N17: 爱格伯特 | O17: 阿普敦 | P17: 艾琳娜 | Q17: 阿尔杰农 | R17: 纺织婆婆 | S17: 莱特
B18: 马 | C18: 4
B19: 玛德琳 | C19: 5 | E19: 班尼迪克 | F19: 亚度尼斯 | G19: 琼 | H19: 占卜婆婆 | I19: 布蓝达 | J19: 帕特里克 | K19: 梅林 | L19: 摩尔根 | M19: 马勒第兹 | N19: 爱格伯特 | O19: 阿普敦 | P19: 艾琳娜 | Q19: 阿尔杰农 | R19: 纺织婆婆 | S19: 丝特芬妮 | T19: 希尔达 | U19: 朵儿洁 | V19: 奥蒂莉亚 | W19: 希拉
B20: 布莱兹 | C20: 6 | E20: 格吉尔 | F20: 亚度尼斯 | G20: 琼 | H20: 占卜婆婆 | I20: 坎蒂丝 | J20: 奥蒂莉亚 | K20: 希尔达 | L20: 布拉德利 | M20: 布莱兹 | N20: 希贝儿 | O20: 帕特里克 | P20: 摩尔根 | Q20: 考波特 | R20: 爱格伯特 | S20: 瓦尔特 | T20: 爱丽丝 | U20: 纺织婆婆 | V20: 黛芙妮
B21: 丝特芬妮 | C21: 7 | E21: 玛德琳 | F21: 占卜婆婆 | G21: 坎蒂丝 | H21: 奥蒂莉亚 | I21: 希拉 | J21: 布蓝达 | K21: 希贝儿 | L21: 朵儿洁 | M21: 艾琳娜 | N21: 爱丽丝 | O21: 纺织婆婆 | P21: 黛芙妮 | Q21: 帕特里克 | R21: 琼
B22: 格吉尔 | C22: 8 | E22: 班尼迪克 | F22: 布莱兹 | G22: 亚度尼斯 | H22: 占卜婆婆 | I22: 希尔达 | J22: 布拉德利 | K22: 布莱兹 | L22: 布蓝达 | M22: 希贝儿 | N22: 摩尔根 | O22: 马勒第兹 | P22: 考波特 | Q22: 爱格伯特 | R22: 夏佐 | S22: 瓦尔特 | T22: 阿普敦 | U22: 阿尔杰农 | V22: 纺织婆婆 | W22: 强尼
B23: 亚度尼斯 | C23: 9 | E23: 玛德琳 | F23: 班尼迪克 | G23: 琼 | H23: 希拉 | I23: 占卜婆婆 | J23: 布莱兹 | K23: 帕特里克 | L23: 梅林 | M23: 摩尔根 | N23: 考波特 | O23: 夏佐 | P23: 爱格伯特 | Q23: 杰克 | R23: 阿普敦 | S23: 阿尔杰农 | T23: 纺织婆婆
B24: 琼 | C24: 10 | E24: 班尼迪克 | F24: 玛德琳 | G24: 布莱兹 | H24: 丝特芬妮 | I24: 格吉尔 | J24: 亚度尼斯 | K24: 琼 | L24: 占卜婆婆 | M24: 坎蒂丝 | N24: 奥蒂莉亚 | O24: 希拉 | P24: 希尔达 | Q24: 布拉德利 | R24: 布莱兹 | S24: 布蓝达 | T24: 希贝儿 | U24: 帕特里克 | V24: 朵儿洁 | W24: 梅林 | X24: 摩尔根 | Y24: 马勒第兹 | Z24: 考波特 | AA24: 夏佐 | AB24: 爱格伯特 | AC24: 强尼 | AD24: 瓦尔特 | AE24: 阿普敦 | AF24: 艾琳娜 | AG24: 莱特 | AH24: 爱丽丝 | AI24: 阿尔杰农 | AJ24: 黛芙妮 | AK24: 纺织婆婆
B25: 莎拉 | C25: 11
B26: 占卜婆婆 | C26: 12 | E26: 玛德琳 | F26: 班尼迪克 | G26: 马勒第兹 | H26: 阿普敦 | I26: 阿尔杰农 | J26: 纺织婆婆 | K26: 梅林 | L26: 夏佐
B27: 罗伊 | C27: 13
B28: 坎蒂丝 | C28: 14 | E28: 班尼迪克 | F28: 玛德琳 | G28: 丝特芬妮 | H28: 琼 | I28: 占卜婆婆 | J28: 奥蒂莉亚 | K28: 希拉 | L28: 希尔达 | M28: 布蓝达 | N28: 希贝儿 | O28: 艾琳娜 | P28: 爱丽丝 | Q28: 黛芙妮 | R28: 纺织婆婆 | S28: 帕特里克
B29: 天使 | C29: 15
B30: 奥蒂莉亚 | C30: 16 | E30: 班尼迪克 | F30: 玛德琳 | G30: 丝特芬妮 | H30: 琼 | I30: 占卜婆婆 | J30: 奥蒂莉亚 | K30: 希拉 | L30: 希尔达 | M30: 布蓝达 | N30: 希贝儿 | O30: 艾琳娜 | P30: 爱丽丝 | Q30: 黛芙妮 | R30: 纺织婆婆 | S30: 坎蒂丝 | T30: 帕特里克 | U30: 爱格伯特 | V30: 阿尔杰农 | W30: 坎蒂丝
B31: 希拉 | C31: 17 | E31: 班尼迪克 | F31: 玛德琳 | G31: 丝特芬妮 | H31: 琼 | I31: 占卜婆婆 | J31: 奥蒂莉亚 | K31: 希尔达 | L31: 布蓝达 | M31: 希贝儿 | N31: 艾琳娜 | O31: 爱丽丝 | P31: 黛芙妮 | Q31: 纺织婆婆 | R31: 坎蒂丝 | S31: 帕特里克 | T31: 爱格伯特 | U31: 阿尔杰农 | V31: 坎蒂丝 | W31: 奥蒂莉亚
B32: 希尔达 | C32: 18 | E32: 班尼迪克 | F32: 玛德琳 | G32: 丝特芬妮 | H32: 琼 | I32: 占卜婆婆 | J32: 奥蒂莉亚 | K32: 希尔达 | L32: 布蓝达 | M32: 希贝儿 | N32: 艾琳娜 | O32: 爱丽丝 | P32: 黛芙妮 | Q32: 纺织婆婆 | R32: 坎蒂丝 | S32: 帕特里克 | T32: 爱格伯特 | U32: 阿尔杰农 | V32: 坎蒂丝 | W32: 奥蒂莉亚 | X32: 希拉
B33: 布拉德利 | C33: 19 | E33: 班尼迪克 | F33: 玛德琳 | G33: 布莱兹 | H33: 格吉尔 | I33: 亚度尼斯 | J33: 琼 | K33: 占卜婆婆 | L33: 布莱兹 | M33: 布蓝达 | N33: 帕特里克 | O33: 摩尔根 | P33: 马勒第兹 | Q33: 考波特 | R33: 夏佐 | S33: 爱格伯特 | T33: 瓦尔特 | U33: 阿普敦 | V33: 艾琳娜 | W33: 莱特 | X33: 阿尔杰农 | Y33: 纺织婆婆
B34: 布蓝达 | C34: 21 | E34: 班尼迪克 | F34: 玛德琳 | G34: 布莱兹 | H34: 丝特芬妮 | I34: 琼 | J34: 亚度尼斯 | K34: 占卜婆婆 | L34: 奥蒂莉亚 | M34: 希拉 | N34: 希尔达 | O34: 帕特里克 | P34: 马勒第兹 | Q34: 考波特 | R34: 夏佐 | S34: 爱格伯特 | T34: 阿普敦 | U34: 艾琳娜 | V34: 莱特 | W34: 阿尔杰农 | X34: 纺织婆婆
B35: 希贝儿 | C35: 22 | E35: 玛德琳 | F35: 占卜婆婆 | G35: 坎蒂丝 | H35: 奥蒂莉亚 | I35: 希拉 | J35: 布蓝达 | K35: 丝特芬妮 | L35: 朵儿洁 | M35: 艾琳娜 | N35: 爱丽丝 | O35: 纺织婆婆 | P35: 黛芙妮 | Q35: 帕特里克 | R35: 琼
B36: 帕特里克 | C36: 23 | E36: 班尼迪克 | F36: 玛德琳 | G36: 布莱兹 | H36: 丝特芬妮 | I36: 亚度尼斯 | J36: 琼 | K36: 占卜婆婆 | L36: 奥蒂莉亚 | M36: 希拉 | N36: 希尔达 | O36: 布拉德利 | P36: 布莱兹 | Q36: 布蓝达 | R36: 梅林 | S36: 摩尔根 | T36: 马勒第兹 | U36: 考波特 | V36: 夏佐 | W36: 爱格伯特 | X36: 强尼 | Y36: 瓦尔特 | Z36: 阿普敦 | AA36: 艾琳娜 | AB36: 莱特 | AC36: 阿尔杰农 | AD36: 纺织婆婆
B37: 朵儿洁 | C37: 24 | E37: 琼 | F37: 占卜婆婆 | G37: 布蓝达 | H37: 阿普敦 | I37: 纺织婆婆 | J37: 玛德琳 | K37: 梅林
B38: 梅林 | C38: 25 | E38: 占卜婆婆 | F38: 纺织婆婆 | G38: 阿普敦 | H38: 布蓝达 | I38: 玛德琳 | J38: 夏佐 | K38: 班尼迪克 | L38: 马勒第兹 | M38: 阿尔杰农
B39: 摩尔根 | C39: 26 | E39: 格吉尔 | F39: 亚度尼斯 | G39: 琼 | H39: 占卜婆婆 | I39: 坎蒂丝 | J39: 奥蒂莉亚 | K39: 希尔达 | L39: 布拉德利 | M39: 布莱兹 | N39: 希贝儿 | O39: 帕特里克 | P39: 布莱兹 | Q39: 考波特 | R39: 爱格伯特 | S39: 瓦尔特 | T39: 爱丽丝 | U39: 纺织婆婆 | V39: 黛芙妮
B40: 马勒第兹 | C40: 27 | E40: 玛德琳 | F40: 亚度尼斯 | G40: 琼 | H40: 占卜婆婆 | I40: 布蓝达 | J40: 帕特里克 | K40: 梅林 | L40: 摩尔根 | M40: 班尼迪克 | N40: 爱格伯特 | O40: 阿普敦 | P40: 艾琳娜 | Q40: 阿尔杰农 | R40: 纺织婆婆 | S40: 莱特
B41: 考波特 | C41: 28 | E41: 班尼迪克 | F41: 布莱兹 | G41: 亚度尼斯 | H41: 占卜婆婆 | I41: 希尔达 | J41: 布拉德利 | K41: 布莱兹 | L41: 布蓝达 | M41: 希贝儿 | N41: 摩尔根 | O41: 马勒第兹 | P41: 格吉尔 | Q41: 爱格伯特 | R41: 夏佐 | S41: 瓦尔特 | T41: 阿普敦 | U41: 阿尔杰农 | V41: 纺织婆婆 | W41: 强尼
B42: 夏佐 | C42: 29 | E42: 占卜婆婆 | F42: 布蓝达 | G42: 阿普敦 | H42: 纺织婆婆 | I42: 玛德琳 | J42: 梅林
B43: 爱格伯特 | C43: 30 | E43: 玛德琳 | F43: 班尼迪克 | G43: 琼 | H43: 希拉 | I43: 占卜婆婆 | J43: 布莱兹 | K43: 帕特里克 | L43: 梅林 | M43: 摩尔根 | N43: 考波特 | O43: 夏佐 | P43: 亚度尼斯 | Q43: 杰克 | R43: 阿普敦 | S43: 阿尔杰农 | T43: 纺织婆婆
B44: 强尼 | C44: 31 | E44: 班尼迪克 | F44: 布莱兹 | G44: 亚度尼斯 | H44: 占卜婆婆 | I44: 希尔达 | J44: 布拉德利 | K44: 布莱兹 | L44: 布蓝达 | M44: 希贝儿 | N44: 摩尔根 | O44: 马勒第兹 | P44: 考波特 | Q44: 爱格伯特 | R44: 夏佐 | S44: 瓦尔特 | T44: 阿普敦 | U44: 阿尔杰农 | V44: 纺织婆婆 | W44: 格吉尔
B45: 杰克 | C45: 32
B46: 黛娜 | C46: 33
B47: 瓦尔特 | C47: 34 | E47: 班尼迪克 | F47: 布莱兹 | G47: 亚度尼斯 | H47: 占卜婆婆 | I47: 希尔达 | J47: 布拉德利 | K47: 布莱兹 | L47: 布蓝达 | M47: 希贝儿 | N47: 摩尔根 | O47: 马勒第兹 | P47: 考波特 | Q47: 爱格伯特 | R47: 夏佐 | S47: 强尼 | T47: 阿普敦 | U47: 阿尔杰农 | V47: 纺织婆婆 | W47: 格吉尔
B48: 阿普敦 | C48: 35 | E48: 玛德琳 | F48: 亚度尼斯 | G48: 琼 | H48: 占卜婆婆 | I48: 布蓝达 | J48: 帕特里克 | K48: 梅林 | L48: 摩尔根 | M48: 马勒第兹 | N48: 爱格伯特 | O48: 班尼迪克 | P48: 艾琳娜 | Q48: 阿尔杰农 | R48: 纺织婆婆 | S48: 莱特
B49: 艾琳娜 | C49: 36 | E49: 班尼迪克 | F49: 亚度尼斯 | G49: 琼 | H49: 占卜婆婆 | I49: 布蓝达 | J49: 帕特里克 | K49: 梅林 | L49: 摩尔根 | M49: 马勒第兹 | N49: 爱格伯特 | O49: 阿普敦 | P49: 玛德琳 | Q49: 阿尔杰农 | R49: 纺织婆婆 | S49: 丝特芬妮 | T49: 希尔达 | U49: 朵儿洁 | V49: 奥蒂莉亚 | W49: 希拉
B50: 莱特 | C50: 37 | E50: 格吉尔 | F50: 亚度尼斯 | G50: 琼 | H50: 占卜婆婆 | I50: 坎蒂丝 | J50: 奥蒂莉亚 | K50: 希尔达 | L50: 布拉德利 | M50: 布莱兹 | N50: 希贝儿 | O50: 帕特里克 | P50: 布莱兹 | Q50: 考波特 | R50: 爱格伯特 | S50: 瓦尔特 | T50: 爱丽丝 | U50: 纺织婆婆 | V50: 黛芙妮
B51: 爱丽丝 | C51: 38 | E51: 班尼迪克 | F51: 玛德琳 | G51: 丝特芬妮 | H51: 琼 | I51: 占卜婆婆 | J51: 奥蒂莉亚 | K51: 希拉 | L51: 希尔达 | M51: 布蓝达 | N51: 希贝儿 | O51: 艾琳娜 | P51: 坎蒂丝 | Q51: 黛芙妮 | R51: 纺织婆婆 | S51: 帕特里克
B52: 阿尔杰农 | C52: 39 | E52: 玛德琳 | F52: 亚度尼斯 | G52: 琼 | H52: 占卜婆婆 | I52: 布蓝达 | J52: 帕特里克 | K52: 梅林 | L52: 摩尔根 | M52: 马勒第兹 | N52: 爱格伯特 | O52: 阿普敦 | P52: 艾琳娜 | Q52: 班尼迪克 | R52: 纺织婆婆 | S52: 莱特
B53: 黛芙妮 | C53: 40 | E53: 班尼迪克 | F53: 玛德琳 | G53: 丝特芬妮 | H53: 琼 | I53: 占卜婆婆 | J53: 奥蒂莉亚 | K53: 希拉 | L53: 希尔达 | M53: 布蓝达 | N53: 希贝儿 | O53: 艾琳娜 | P53: 坎蒂丝 | Q53: 爱丽丝 | R53: 纺织婆婆 | S53: 帕特里克
B54: 纺织婆婆 | C54: 41 | E54: 班尼迪克 | F54: 亚度尼斯 | G54: 琼 | H54: 占卜婆婆 | I54: 布蓝达 | J54: 帕特里克 | K54: 梅林 | L54: 摩尔根 | M54: 马勒第兹 | N54: 爱格伯特 | O54: 阿普敦 | P54: 艾琳娜 | Q54: 阿尔杰农 | R54: 玛德琳 | S54: 丝特芬妮 | T54: 希尔达 | U54: 朵儿洁 | V54: 奥蒂莉亚 | W54: 希拉

Sheet Sheet2
B2: 班尼迪克 | C2: 3 | D2: 玛德琳 | E2: 亚度尼斯 | F2: 琼 | G2: 占卜婆婆 | H2: 布蓝达 | I2: 帕特里克 | J2: 梅林 | K2: 摩尔根 | L2: 马勒第兹 | M2: 爱格伯特 | N2: 阿普敦 | O2: 艾琳娜 | P2: 阿尔杰农 | Q2: 纺织婆婆 | R2: 莱特
D3: =VLOOKUP(D2,Sheet1!$B$17:$C$54,2,FALSE) -> 5 | E3: =VLOOKUP(E2,Sheet1!$B$17:$C$54,2,FALSE) -> 9 | F3: =VLOOKUP(F2,Sheet1!$B$17:$C$54,2,FALSE) -> 10 | G3: =VLOOKUP(G2,Sheet1!$B$17:$C$54,2,FALSE) -> 12 | H3: =VLOOKUP(H2,Sheet1!$B$17:$C$54,2,FALSE) -> 21 | I3: =VLOOKUP(I2,Sheet1!$B$17:$C$54,2,FALSE) -> 23 | J3: =VLOOKUP(J2,Sheet1!$B$17:$C$54,2,FALSE) -> 25 | K3: =VLOOKUP(K2,Sheet1!$B$17:$C$54,2,FALSE) -> 26 | ... R3: =VLOOKUP(R2,Sheet1!$B$17:$C$54,2,FALSE) -> 37
D4: =IF(C4<>"",C4&"|"&D3&","&100,D3&","&100) -> 5,100 | E4: =IF(D4<>"",D4&"|"&E3&","&100,E3&","&100) -> 5,100|9,100 | F4: =IF(E4<>"",E4&"|"&F3&","&100,F3&","&100) -> 5,100|9,100|10,100 | G4: =IF(F4<>"",F4&"|"&G3&","&100,G3&","&100) -> 5,100|9,100|10,100|12,100 | H4: =IF(G4<>"",G4&"|"&H3&","&100,H3&","&100) -> 5,100|9,100|10,100|12,100|21,100 | I4: =IF(H4<>"",H4&"|"&I3&","&100,I3&","&100) -> 5,100|9,100|10,100|12,100|21,100|23,100 | J4: =IF(I4<>"",I4&"|"&J3&","&100,J3&","&100) -> 5,100|9,100|10,100|12,100|21,100|23,100|25,100 | K4: =IF(J4<>"",J4&"|"&K3&","&100,K3&","&100) -> 5,100|9,100|10,100|12,100|21,100|23,100|25,100|26,100 | ... R4: =IF(Q4<>"",Q4&"|"&R3&","&100,R3&","&100) -> 5,100|9,100|10,100|12,100|21,100|23,100|25,100|26,100|27,100|30,100|35,100|36,100|39,100|41,100|37,100
B5: 玛德琳 | C5: 5 | D5: 班尼迪克 | E5: 亚度尼斯 | F5: 琼 | G5: 占卜婆婆 | H5: 布蓝达 | I5: 帕特里克 | J5: 梅林 | K5: 摩尔根 | L5: 马勒第兹 | M5: 爱格伯特 | N5: 阿普敦 | O5: 艾琳娜 | P5: 阿尔杰农 | Q5: 纺织婆婆 | R5: 丝特芬妮 | S5: 希尔达 | T5: 朵儿洁 | U5: 奥蒂莉亚 | V5: 希拉
D6: =VLOOKUP(D5,Sheet1!$B$17:$C$54,2,FALSE) -> 3 | E6: =VLOOKUP(E5,Sheet1!$B$17:$C$54,2,FALSE) -> 9 | F6: =VLOOKUP(F5,Sheet1!$B$17:$C$54,2,FALSE) -> 10 | G6: =VLOOKUP(G5,Sheet1!$B$17:$C$54,2,FALSE) -> 12 | H6: =VLOOKUP(H5,Sheet1!$B$17:$C$54,2,FALSE) -> 21 | I6: =VLOOKUP(I5,Sheet1!$B$17:$C$54,2,FALSE) -> 23 | J6: =VLOOKUP(J5,Sheet1!$B$17:$C$54,2,FALSE) -> 25 | K6: =VLOOKUP(K5,Sheet1!$B$17:$C$54,2,FALSE) -> 26 | ... V6: =VLOOKUP(V5,Sheet1!$B$17:$C$54,2,FALSE) -> 17
D7: =IF(C7<>"",C7&"|"&D6&","&100,D6&","&100) -> 3,100 | E7: =IF(D7<>"",D7&"|"&E6&","&100,E6&","&100) -> 3,100|9,100 | F7: =IF(E7<>"",E7&"|"&F6&","&100,F6&","&100) -> 3,100|9,100|10,100 | G7: =IF(F7<>"",F7&"|"&G6&","&100,G6&","&100) -> 3,100|9,100|10,100|12,100 | H7: =IF(G7<>"",G7&"|"&H6&","&100,H6&","&100) -> 3,100|9,100|10,100|12,100|21,100 | I7: =IF(H7<>"",H7&"|"&I6&","&100,I6&","&100) -> 3,100|9,100|10,100|12,100|21,100|23,100 | J7: =IF(I7<>"",I7&"|"&J6&","&100,J6&","&100) -> 3,100|9,100|10,100|12,100|21,100|23,100|25,100 | K7: =IF(J7<>"",J7&"|"&K6&","&100,K6&","&100) -> 3,100|9,100|10,100|12,100|21,100|23,100|25,100|26,100 | ... V7: =IF(U7<>"",U7&"|"&V6&","&100,V6&","&100) -> 3,100|9,100|10,100|12,100|21,100|23,100|25,100|26,100|27,100|30,100|35,100|36,100|39,100|41,100|7,100|18,100|24,100|16,100|17,100
B8: 布莱兹 | C8: 6 | D8: 格吉尔 | E8: 亚度尼斯 | F8: 琼 | G8: 占卜婆婆 | H8: 坎蒂丝 | I8: 奥蒂莉亚 | J8: 希尔达 | K8: 布拉德利 | L8: 希贝儿 | M8: 帕特里克 | N8: 摩尔根 | O8: 考波特 | P8: 爱格伯特 | Q8: 瓦尔特 | R8: 爱丽丝 | S8: 纺织婆婆 | T8: 黛芙妮
D9: =VLOOKUP(D8,Sheet1!$B$17:$C$54,2,FALSE) -> 8 | E9: =VLOOKUP(E8,Sheet1!$B$17:$C$54,2,FALSE) -> 9 | F9: =VLOOKUP(F8,Sheet1!$B$17:$C$54,2,FALSE) -> 10 | G9: =VLOOKUP(G8,Sheet1!$B$17:$C$54,2,FALSE) -> 12 | H9: =VLOOKUP(H8,Sheet1!$B$17:$C$54,2,FALSE) -> 14 | I9: =VLOOKUP(I8,Sheet1!$B$17:$C$54,2,FALSE) -> 16 | J9: =VLOOKUP(J8,Sheet1!$B$17:$C$54,2,FALSE) -> 18 | K9: =VLOOKUP(K8,Sheet1!$B$17:$C$54,2,FALSE) -> 19 | ... T9: =VLOOKUP(T8,Sheet1!$B$17:$C$54,2,FALSE) -> 40
D10: =IF(C10<>"",C10&"|"&D9&","&100,D9&","&100) -> 8,100 | E10: =IF(D10<>"",D10&"|"&E9&","&100,E9&","&100) -> 8,100|9,100 | F10: =IF(E10<>"",E10&"|"&F9&","&100,F9&","&100) -> 8,100|9,100|10,100 | G10: =IF(F10<>"",F10&"|"&G9&","&100,G9&","&100) -> 8,100|9,100|10,100|12,100 | H10: =IF(G10<>"",G10&"|"&H9&","&100,H9&","&100) -> 8,100|9,100|10,100|12,100|14,100 | I10: =IF(H10<>"",H10&"|"&I9&","&100,I9&","&100) -> 8,100|9,100|10,100|12,100|14,100|16,100 | J10: =IF(I10<>"",I10&"|"&J9&","&100,J9&","&100) -> 8,100|9,100|10,100|12,100|14,100|16,100|18,100 | K10: =IF(J10<>"",J10&"|"&K9&","&100,K9&","&100) -> 8,100|9,100|10,100|12,100|14,100|16,100|18,100|19,100 | ... T10: =IF(S10<>"",S10&"|"&T9&","&100,T9&","&100) -> 8,100|9,100|10,100|12,100|14,100|16,100|18,100|19,100|22,100|23,100|26,100|28,100|30,100|34,100|38,100|41,100|40,100 | U10: =IF(T10<>"",T10&"|"&T9&","&100,T9&","&100) -> 8,100|9,100|10,100|12,100|14,100|16,100|18,100|19,100|22,100|23,100|26,100|28,100|30,100|34,100|38,100|41,100|40,100|40,100
B11: 丝特芬妮 | C11: 7 | D11: 玛德琳 | E11: 占卜婆婆 | F11: 坎蒂丝 | G11: 奥蒂莉亚 | H11: 希拉 | I11: 布蓝达 | J11: 希贝儿 | K11: 朵儿洁 | L11: 艾琳娜 | M11: 爱丽丝 | N11: 纺织婆婆 | O11: 黛芙妮 | P11: 帕特里克 | Q11: 琼
D12: =VLOOKUP(D11,Sheet1!$B$17:$C$54,2,FALSE) -> 5 | E12: =VLOOKUP(E11,Sheet1!$B$17:$C$54,2,FALSE) -> 12 | F12: =VLOOKUP(F11,Sheet1!$B$17:$C$54,2,FALSE) -> 14 | G12: =VLOOKUP(G11,Sheet1!$B$17:$C$54,2,FALSE) -> 16 | H12: =VLOOKUP(H11,Sheet1!$B$17:$C$54,2,FALSE) -> 17 | I12: =VLOOKUP(I11,Sheet1!$B$17:$C$54,2,FALSE) -> 21 | J12: =VLOOKUP(J11,Sheet1!$B$17:$C$54,2,FALSE) -> 22 | K12: =VLOOKUP(K11,Sheet1!$B$17:$C$54,2,FALSE) -> 24 | ... Q12: =VLOOKUP(Q11,Sheet1!$B$17:$C$54,2,FALSE) -> 10
D13: =IF(C13<>"",C13&"|"&D12&","&100,D12&","&100) -> 5,100 | E13: =IF(D13<>"",D13&"|"&E12&","&100,E12&","&100) -> 5,100|12,100 | F13: =IF(E13<>"",E13&"|"&F12&","&100,F12&","&100) -> 5,100|12,100|14,100 | G13: =IF(F13<>"",F13&"|"&G12&","&100,G12&","&100) -> 5,100|12,100|14,100|16,100 | H13: =IF(G13<>"",G13&"|"&H12&","&100,H12&","&100) -> 5,100|12,100|14,100|16,100|17,100 | I13: =IF(H13<>"",H13&"|"&I12&","&100,I12&","&100) -> 5,100|12,100|14,100|16,100|17,100|21,100 | J13: =IF(I13<>"",I13&"|"&J12&","&100,J12&","&100) -> 5,100|12,100|14,100|16,100|17,100|21,100|22,100 | K13: =IF(J13<>"",J13&"|"&K12&","&100,K12&","&100) -> 5,100|12,100|14,100|16,100|17,100|21,100|22,100|24,100 | ... Q13: =IF(P13<>"",P13&"|"&Q12&","&100,Q12&","&100) -> 5,100|12,100|14,100|16,100|17,100|21,100|22,100|24,100|36,100|38,100|41,100|40,100|23,100|10,100
B14: 格吉尔 | C14: 8 | D14: 班尼迪克 | E14: 布莱兹 | F14: 亚度尼斯 | G14: 占卜婆婆 | H14: 希尔达 | I14: 布拉德利 | J14: 布蓝达 | K14: 希贝儿 | L14: 摩尔根 | M14: 马勒第兹 | N14: 考波特 | O14: 爱格伯特 | P14: 夏佐 | Q14: 瓦尔特 | R14: 阿普敦 | S14: 阿尔杰农 | T14: 纺织婆婆 | U14: 强尼
D15: =VLOOKUP(D14,Sheet1!$B$17:$C$54,2,FALSE) -> 3 | E15: =VLOOKUP(E14,Sheet1!$B$17:$C$54,2,FALSE) -> 6 | F15: =VLOOKUP(F14,Sheet1!$B$17:$C$54,2,FALSE) -> 9 | G15: =VLOOKUP(G14,Sheet1!$B$17:$C$54,2,FALSE) -> 12 | H15: =VLOOKUP(H14,Sheet1!$B$17:$C$54,2,FALSE) -> 18 | I15: =VLOOKUP(I14,Sheet1!$B$17:$C$54,2,FALSE) -> 19 | J15: =VLOOKUP(J14,Sheet1!$B$17:$C$54,2,FALSE) -> 21 | K15: =VLOOKUP(K14,Sheet1!$B$17:$C$54,2,FALSE) -> 22 | ... U15: =VLOOKUP(U14,Sheet1!$B$17:$C$54,2,FALSE) -> 31
D16: =IF(C16<>"",C16&"|"&D15&","&100,D15&","&100) -> 3,100 | E16: =IF(D16<>"",D16&"|"&E15&","&100,E15&","&100) -> 3,100|6,100 | F16: =IF(E16<>"",E16&"|"&F15&","&100,F15&","&100) -> 3,100|6,100|9,100 | G16: =IF(F16<>"",F16&"|"&G15&","&100,G15&","&100) -> 3,100|6,100|9,100|12,100 | H16: =IF(G16<>"",G16&"|"&H15&","&100,H15&","&100) -> 3,100|6,100|9,100|12,100|18,100 | I16: =IF(H16<>"",H16&"|"&I15&","&100,I15&","&100) -> 3,100|6,100|9,100|12,100|18,100|19,100 | J16: =IF(I16<>"",I16&"|"&J15&","&100,J15&","&100) -> 3,100|6,100|9,100|12,100|18,100|19,100|21,100 | K16: =IF(J16<>"",J16&"|"&K15&","&100,K15&","&100) -> 3,100|6,100|9,100|12,100|18,100|19,100|21,100|22,100 | ... U16: =IF(T16<>"",T16&"|"&U15&","&100,U15&","&100) -> 3,100|6,100|9,100|12,100|18,100|19,100|21,100|22,100|26,100|27,100|28,100|30,100|29,100|34,100|35,100|39,100|41,100|31,100
B17: 亚度尼斯 | C17: 9 | D17: 玛德琳 | E17: 班尼迪克 | F17: 琼 | G17: 希拉 | H17: 占卜婆婆 | I17: 布莱兹 | J17: 帕特里克 | K17: 梅林 | L17: 摩尔根 | M17: 考波特 | N17: 夏佐 | O17: 爱格伯特 | P17: 杰克 | Q17: 阿普敦 | R17: 阿尔杰农 | S17: 纺织婆婆
D18: =VLOOKUP(D17,Sheet1!$B$17:$C$54,2,FALSE) -> 5 | E18: =VLOOKUP(E17,Sheet1!$B$17:$C$54,2,FALSE) -> 3 | F18: =VLOOKUP(F17,Sheet1!$B$17:$C$54,2,FALSE) -> 10 | G18: =VLOOKUP(G17,Sheet1!$B$17:$C$54,2,FALSE) -> 17 | H18: =VLOOKUP(H17,Sheet1!$B$17:$C$54,2,FALSE) -> 12 | I18: =VLOOKUP(I17,Sheet1!$B$17:$C$54,2,FALSE) -> 6 | J18: =VLOOKUP(J17,Sheet1!$B$17:$C$54,2,FALSE) -> 23 | K18: =VLOOKUP(K17,Sheet1!$B$17:$C$54,2,FALSE) -> 25 | ... S18: =VLOOKUP(S17,Sheet1!$B$17:$C$54,2,FALSE) -> 41
D19: =IF(C19<>"",C19&"|"&D18&","&100,D18&","&100) -> 5,100 | E19: =IF(D19<>"",D19&"|"&E18&","&100,E18&","&100) -> 5,100|3,100 | F19: =IF(E19<>"",E19&"|"&F18&","&100,F18&","&100) -> 5,100|3,100|10,100 | G19: =IF(F19<>"",F19&"|"&G18&","&100,G18&","&100) -> 5,100|3,100|10,100|17,100 | H19: =IF(G19<>"",G19&"|"&H18&","&100,H18&","&100) -> 5,100|3,100|10,100|17,100|12,100 | I19: =IF(H19<>"",H19&"|"&I18&","&100,I18&","&100) -> 5,100|3,100|10,100|17,100|12,100|6,100 | J19: =IF(I19<>"",I19&"|"&J18&","&100,J18&","&100) -> 5,100|3,100|10,100|17,100|12,100|6,100|23,100 | K19: =IF(J19<>"",J19&"|"&K18&","&100,K18&","&100) -> 5,100|3,100|10,100|17,100|12,100|6,100|23,100|25,100 | ... S19: =IF(R19<>"",R19&"|"&S18&","&100,S18&","&100) -> 5,100|3,100|10,100|17,100|12,100|6,100|23,100|25,100|26,100|28,100|29,100|30,100|32,100|35,100|39,100|41,100
B20: 琼 | C20: 10 | D20: 班尼迪克 | E20: 玛德琳 | F20: 布莱兹 | G20: 丝特芬妮 | H20: 格吉尔 | I20: 亚度尼斯 | J20: 琼 | K20: 占卜婆婆 | L20: 坎蒂丝 | M20: 奥蒂莉亚 | N20: 希拉 | O20: 希尔达 | P20: 布拉德利 | Q20: 布蓝达 | R20: 希贝儿 | S20: 帕特里克 | T20: 朵儿洁 | U20: 梅林 | V20: 摩尔根 | W20: 马勒第兹 | X20: 考波特 | Y20: 夏佐 | Z20: 爱格伯特 | AA20: 强尼 | AB20: 瓦尔特 | AC20: 阿普敦 | AD20: 艾琳娜 | AE20: 莱特 | AF20: 爱丽丝 | AG20: 阿尔杰农 | AH20: 黛芙妮 | AI20: 纺织婆婆
D21: =VLOOKUP(D20,Sheet1!$B$17:$C$54,2,FALSE) -> 3 | E21: =VLOOKUP(E20,Sheet1!$B$17:$C$54,2,FALSE) -> 5 | F21: =VLOOKUP(F20,Sheet1!$B$17:$C$54,2,FALSE) -> 6 | G21: =VLOOKUP(G20,Sheet1!$B$17:$C$54,2,FALSE) -> 7 | H21: =VLOOKUP(H20,Sheet1!$B$17:$C$54,2,FALSE) -> 8 | I21: =VLOOKUP(I20,Sheet1!$B$17:$C$54,2,FALSE) -> 9 | J21: =VLOOKUP(J20,Sheet1!$B$17:$C$54,2,FALSE) -> 10 | K21: =VLOOKUP(K20,Sheet1!$B$17:$C$54,2,FALSE) -> 12 | ... AI21: =VLOOKUP(AI20,Sheet1!$B$17:$C$54,2,FALSE) -> 41
D22: =IF(C22<>"",C22&"|"&D21&","&100,D21&","&100) -> 3,100 | E22: =IF(D22<>"",D22&"|"&E21&","&100,E21&","&100) -> 3,100|5,100 | F22: =IF(E22<>"",E22&"|"&F21&","&100,F21&","&100) -> 3,100|5,100|6,100 | G22: =IF(F22<>"",F22&"|"&G21&","&100,G21&","&100) -> 3,100|5,100|6,100|7,100 | H22: =IF(G22<>"",G22&"|"&H21&","&100,H21&","&100) -> 3,100|5,100|6,100|7,100|8,100 | I22: =IF(H22<>"",H22&"|"&I21&","&100,I21&","&100) -> 3,100|5,100|6,100|7,100|8,100|9,100 | J22: =IF(I22<>"",I22&"|"&J21&","&100,J21&","&100) -> 3,100|5,100|6,100|7,100|8,100|9,100|10,100 | K22: =IF(J22<>"",J22&"|"&K21&","&100,K21&","&100) -> 3,100|5,100|6,100|7,100|8,100|9,100|10,100|12,100 | ... AI22: =IF(AH22<>"",AH22&"|"&AI21&","&100,AI21&","&100) -> 3,100|5,100|6,100|7,100|8,100|9,100|10,100|12,100|14,100|16,100|17,100|18,100|19,100|21,100|22,100|23,100|24,100|25,100|26,100|27,100|28,100|29,100|30,100|31,100|34,100|35,100|36,100|37,100|38,100|39,100|40,100|41,100
B23: 占卜婆婆 | C23: 12 | D23: 玛德琳 | E23: 班尼迪克 | F23: 马勒第兹 | G23: 阿普敦 | H23: 阿尔杰农 | I23: 纺织婆婆 | J23: 梅林 | K23: 夏佐
D24: =VLOOKUP(D23,Sheet1!$B$17:$C$54,2,FALSE) -> 5 | E24: =VLOOKUP(E23,Sheet1!$B$17:$C$54,2,FALSE) -> 3 | F24: =VLOOKUP(F23,Sheet1!$B$17:$C$54,2,FALSE) -> 27 | G24: =VLOOKUP(G23,Sheet1!$B$17:$C$54,2,FALSE) -> 35 | H24: =VLOOKUP(H23,Sheet1!$B$17:$C$54,2,FALSE) -> 39 | I24: =VLOOKUP(I23,Sheet1!$B$17:$C$54,2,FALSE) -> 41 | J24: =VLOOKUP(J23,Sheet1!$B$17:$C$54,2,FALSE) -> 25 | K24: =VLOOKUP(K23,Sheet1!$B$17:$C$54,2,FALSE) -> 29
D25: =IF(C25<>"",C25&"|"&D24&","&100,D24&","&100) -> 5,100 | E25: =IF(D25<>"",D25&"|"&E24&","&100,E24&","&100) -> 5,100|3,100 | F25: =IF(E25<>"",E25&"|"&F24&","&100,F24&","&100) -> 5,100|3,100|27,100 | G25: =IF(F25<>"",F25&"|"&G24&","&100,G24&","&100) -> 5,100|3,100|27,100|35,100 | H25: =IF(G25<>"",G25&"|"&H24&","&100,H24&","&100) -> 5,100|3,100|27,100|35,100|39,100 | I25: =IF(H25<>"",H25&"|"&I24&","&100,I24&","&100) -> 5,100|3,100|27,100|35,100|39,100|41,100 | J25: =IF(I25<>"",I25&"|"&J24&","&100,J24&","&100) -> 5,100|3,100|27,100|35,100|39,100|41,100|25,100 | K25: =IF(J25<>"",J25&"|"&K24&","&100,K24&","&100) -> 5,100|3,100|27,100|35,100|39,100|41,100|25,100|29,100
B26: 坎蒂丝 | C26: 14 | D26: 班尼迪克 | E26: 玛德琳 | F26: 丝特芬妮 | G26: 琼 | H26: 占卜婆婆 | I26: 奥蒂莉亚 | J26: 希拉 | K26: 希尔达 | L26: 布蓝达 | M26: 希贝儿 | N26: 艾琳娜 | O26: 爱丽丝 | P26: 黛芙妮 | Q26: 纺织婆婆 | R26: 帕特里克
D27: =VLOOKUP(D26,Sheet1!$B$17:$C$54,2,FALSE) -> 3 | E27: =VLOOKUP(E26,Sheet1!$B$17:$C$54,2,FALSE) -> 5 | F27: =VLOOKUP(F26,Sheet1!$B$17:$C$54,2,FALSE) -> 7 | G27: =VLOOKUP(G26,Sheet1!$B$17:$C$54,2,FALSE) -> 10 | H27: =VLOOKUP(H26,Sheet1!$B$17:$C$54,2,FALSE) -> 12 | I27: =VLOOKUP(I26,Sheet1!$B$17:$C$54,2,FALSE) -> 16 | J27: =VLOOKUP(J26,Sheet1!$B$17:$C$54,2,FALSE) -> 17 | K27: =VLOOKUP(K26,Sheet1!$B$17:$C$54,2,FALSE) -> 18 | ... R27: =VLOOKUP(R26,Sheet1!$B$17:$C$54,2,FALSE) -> 23
D28: =IF(C28<>"",C28&"|"&D27&","&100,D27&","&100) -> 3,100 | E28: =IF(D28<>"",D28&"|"&E27&","&100,E27&","&100) -> 3,100|5,100 | F28: =IF(E28<>"",E28&"|"&F27&","&100,F27&","&100) -> 3,100|5,100|7,100 | G28: =IF(F28<>"",F28&"|"&G27&","&100,G27&","&100) -> 3,100|5,100|7,100|10,100 | H28: =IF(G28<>"",G28&"|"&H27&","&100,H27&","&100) -> 3,100|5,100|7,100|10,100|12,100 | I28: =IF(H28<>"",H28&"|"&I27&","&100,I27&","&100) -> 3,100|5,100|7,100|10,100|12,100|16,100 | J28: =IF(I28<>"",I28&"|"&J27&","&100,J27&","&100) -> 3,100|5,100|7,100|10,100|12,100|16,100|17,100 | K28: =IF(J28<>"",J28&"|"&K27&","&100,K27&","&100) -> 3,100|5,100|7,100|10,100|12,100|16,100|17,100|18,100 | ... R28: =IF(Q28<>"",Q28&"|"&R27&","&100,R27&","&100) -> 3,100|5,100|7,100|10,100|12,100|16,100|17,100|18,100|21,100|22,100|36,100|38,100|40,100|41,100|23,100
B29: 奥蒂莉亚 | C29: 16 | D29: 班尼迪克 | E29: 玛德琳 | F29: 丝特芬妮 | G29: 琼 | H29: 占卜婆婆 | I29: 奥蒂莉亚 | J29: 希拉 | K29: 希尔达 | L29: 布蓝达 | M29: 希贝儿 | N29: 艾琳娜 | O29: 爱丽丝 | P29: 黛芙妮 | Q29: 纺织婆婆 | R29: 坎蒂丝 | S29: 帕特里克 | T29: 爱格伯特 | U29: 阿尔杰农
D30: =VLOOKUP(D29,Sheet1!$B$17:$C$54,2,FALSE) -> 3 | E30: =VLOOKUP(E29,Sheet1!$B$17:$C$54,2,FALSE) -> 5 | F30: =VLOOKUP(F29,Sheet1!$B$17:$C$54,2,FALSE) -> 7 | G30: =VLOOKUP(G29,Sheet1!$B$17:$C$54,2,FALSE) -> 10 | H30: =VLOOKUP(H29,Sheet1!$B$17:$C$54,2,FALSE) -> 12 | I30: =VLOOKUP(I29,Sheet1!$B$17:$C$54,2,FALSE) -> 16 | J30: =VLOOKUP(J29,Sheet1!$B$17:$C$54,2,FALSE) -> 17 | K30: =VLOOKUP(K29,Sheet1!$B$17:$C$54,2,FALSE) -> 18 | ... U30: =VLOOKUP(U29,Sheet1!$B$17:$C$54,2,FALSE) -> 39
D31: =IF(C31<>"",C31&"|"&D30&","&100,D30&","&100) -> 3,100 | E31: =IF(D31<>"",D31&"|"&E30&","&100,E30&","&100) -> 3,100|5,100 | F31: =IF(E31<>"",E31&"|"&F30&","&100,F30&","&100) -> 3,100|5,100|7,100 | G31: =IF(F31<>"",F31&"|"&G30&","&100,G30&","&100) -> 3,100|5,100|7,100|10,100 | H31: =IF(G31<>"",G31&"|"&H30&","&100,H30&","&100) -> 3,100|5,100|7,100|10,100|12,100 | I31: =IF(H31<>"",H31&"|"&I30&","&100,I30&","&100) -> 3,100|5,100|7,100|10,100|12,100|16,100 | J31: =IF(I31<>"",I31&"|"&J30&","&100,J30&","&100) -> 3,100|5,100|7,100|10,100|12,100|16,100|17,100 | K31: =IF(J31<>"",J31&"|"&K30&","&100,K30&","&100) -> 3,100|5,100|7,100|10,100|12,100|16,100|17,100|18,100 | ... U31: =IF(T31<>"",T31&"|"&U30&","&100,U30&","&100) -> 3,100|5,100|7,100|10,100|12,100|16,100|17,100|18,100|21,100|22,100|36,100|38,100|40,100|41,100|14,100|23,100|30,100|39,100
B32: 希拉 | C32: 17 | D32: 班尼迪克 | E32: 玛德琳 | F32: 丝特芬妮 | G32: 琼 | H32: 占卜婆婆 | I32: 奥蒂莉亚 | J32: 希尔达 | K32: 布蓝达 | L32: 希贝儿 | M32: 艾琳娜 | N32: 爱丽丝 | O32: 黛芙妮 | P32: 纺织婆婆 | Q32: 坎蒂丝 | R32: 帕特里克 | S32: 爱格伯特 | T32: 阿尔杰农
D33: =VLOOKUP(D32,Sheet1!$B$17:$C$54,2,FALSE) -> 3 | E33: =VLOOKUP(E32,Sheet1!$B$17:$C$54,2,FALSE) -> 5 | F33: =VLOOKUP(F32,Sheet1!$B$17:$C$54,2,FALSE) -> 7 | G33: =VLOOKUP(G32,Sheet1!$B$17:$C$54,2,FALSE) -> 10 | H33: =VLOOKUP(H32,Sheet1!$B$17:$C$54,2,FALSE) -> 12 | I33: =VLOOKUP(I32,Sheet1!$B$17:$C$54,2,FALSE) -> 16 | J33: =VLOOKUP(J32,Sheet1!$B$17:$C$54,2,FALSE) -> 18 | K33: =VLOOKUP(K32,Sheet1!$B$17:$C$54,2,FALSE) -> 21 | ... T33: =VLOOKUP(T32,Sheet1!$B$17:$C$54,2,FALSE) -> 39
D34: =IF(C34<>"",C34&"|"&D33&","&100,D33&","&100) -> 3,100 | E34: =IF(D34<>"",D34&"|"&E33&","&100,E33&","&100) -> 3,100|5,100 | F34: =IF(E34<>"",E34&"|"&F33&","&100,F33&","&100) -> 3,100|5,100|7,100 | G34: =IF(F34<>"",F34&"|"&G33&","&100,G33&","&100) -> 3,100|5,100|7,100|10,100 | H34: =IF(G34<>"",G34&"|"&H33&","&100,H33&","&100) -> 3,100|5,100|7,100|10,100|12,100 | I34: =IF(H34<>"",H34&"|"&I33&","&100,I33&","&100) -> 3,100|5,100|7,100|10,100|12,100|16,100 | J34: =IF(I34<>"",I34&"|"&J33&","&100,J33&","&100) -> 3,100|5,100|7,100|10,100|12,100|16,100|18,100 | K34: =IF(J34<>"",J34&"|"&K33&","&100,K33&","&100) -> 3,100|5,100|7,100|10,100|12,100|16,100|18,100|21,100 | ... T34: =IF(S34<>"",S34&"|"&T33&","&100,T33&","&100) -> 3,100|5,100|7,100|10,100|12,100|16,100|18,100|21,100|22,100|36,100|38,100|40,100|41,100|14,100|23,100|30,100|39,100
B35: 希尔达 | C35: 18 | D35: 班尼迪克 | E35: 玛德琳 | F35: 丝特芬妮 | G35: 琼 | H35: 占卜婆婆 | I35: 奥蒂莉亚 | J35: 布蓝达 | K35: 希贝儿 | L35: 艾琳娜 | M35: 爱丽丝 | N35: 黛芙妮 | O35: 纺织婆婆 | P35: 坎蒂丝 | Q35: 帕特里克 | R35: 爱格伯特 | S35: 阿尔杰农 | T35: 希拉
D36: =VLOOKUP(D35,Sheet1!$B$17:$C$54,2,FALSE) -> 3 | E36: =VLOOKUP(E35,Sheet1!$B$17:$C$54,2,FALSE) -> 5 | F36: =VLOOKUP(F35,Sheet1!$B$17:$C$54,2,FALSE) -> 7 | G36: =VLOOKUP(G35,Sheet1!$B$17:$C$54,2,FALSE) -> 10 | H36: =VLOOKUP(H35,Sheet1!$B$17:$C$54,2,FALSE) -> 12 | I36: =VLOOKUP(I35,Sheet1!$B$17:$C$54,2,FALSE) -> 16 | J36: =VLOOKUP(J35,Sheet1!$B$17:$C$54,2,FALSE) -> 21 | K36: =VLOOKUP(K35,Sheet1!$B$17:$C$54,2,FALSE) -> 22 | ... T36: =VLOOKUP(T35,Sheet1!$B$17:$C$54,2,FALSE) -> 17
D37: =IF(C37<>"",C37&"|"&D36&","&100,D36&","&100) -> 3,100 | E37: =IF(D37<>"",D37&"|"&E36&","&100,E36&","&100) -> 3,100|5,100 | F37: =IF(E37<>"",E37&"|"&F36&","&100,F36&","&100) -> 3,100|5,100|7,100 | G37: =IF(F37<>"",F37&"|"&G36&","&100,G36&","&100) -> 3,100|5,100|7,100|10,100 | H37: =IF(G37<>"",G37&"|"&H36&","&100,H36&","&100) -> 3,100|5,100|7,100|10,100|12,100 | I37: =IF(H37<>"",H37&"|"&I36&","&100,I36&","&100) -> 3,100|5,100|7,100|10,100|12,100|16,100 | J37: =IF(I37<>"",I37&"|"&J36&","&100,J36&","&100) -> 3,100|5,100|7,100|10,100|12,100|16,100|21,100 | K37: =IF(J37<>"",J37&"|"&K36&","&100,K36&","&100) -> 3,100|5,100|7,100|10,100|12,100|16,100|21,100|22,100 | ... T37: =IF(S37<>"",S37&"|"&T36&","&100,T36&","&100) -> 3,100|5,100|7,100|10,100|12,100|16,100|21,100|22,100|36,100|38,100|40,100|41,100|14,100|23,100|30,100|39,100|17,100
B38: 布拉德利 | C38: 19 | D38: 班尼迪克 | E38: 玛德琳 | F38: 布莱兹 | G38: 格吉尔 | H38: 亚度尼斯 | I38: 琼 | J38: 占卜婆婆 | K38: 布蓝达 | L38: 帕特里克 | M38: 摩尔根 | N38: 马勒第兹 | O38: 考波特 | P38: 夏佐 | Q38: 爱格伯特 | R38: 瓦尔特 | S38: 阿普敦 | T38: 艾琳娜 | U38: 莱特 | V38: 阿尔杰农 | W38: 纺织婆婆
D39: =VLOOKUP(D38,Sheet1!$B$17:$C$54,2,FALSE) -> 3 | E39: =VLOOKUP(E38,Sheet1!$B$17:$C$54,2,FALSE) -> 5 | F39: =VLOOKUP(F38,Sheet1!$B$17:$C$54,2,FALSE) -> 6 | G39: =VLOOKUP(G38,Sheet1!$B$17:$C$54,2,FALSE) -> 8 | H39: =VLOOKUP(H38,Sheet1!$B$17:$C$54,2,FALSE) -> 9 | I39: =VLOOKUP(I38,Sheet1!$B$17:$C$54,2,FALSE) -> 10 | J39: =VLOOKUP(J38,Sheet1!$B$17:$C$54,2,FALSE) -> 12 | K39: =VLOOKUP(K38,Sheet1!$B$17:$C$54,2,FALSE) -> 21 | ... W39: =VLOOKUP(W38,Sheet1!$B$17:$C$54,2,FALSE) -> 41
D40: =IF(C40<>"",C40&"|"&D39&","&100,D39&","&100) -> 3,100 | E40: =IF(D40<>"",D40&"|"&E39&","&100,E39&","&100) -> 3,100|5,100 | F40: =IF(E40<>"",E40&"|"&F39&","&100,F39&","&100) -> 3,100|5,100|6,100 | G40: =IF(F40<>"",F40&"|"&G39&","&100,G39&","&100) -> 3,100|5,100|6,100|8,100 | H40: =IF(G40<>"",G40&"|"&H39&","&100,H39&","&100) -> 3,100|5,100|6,100|8,100|9,100 | I40: =IF(H40<>"",H40&"|"&I39&","&100,I39&","&100) -> 3,100|5,100|6,100|8,100|9,100|10,100 | J40: =IF(I40<>"",I40&"|"&J39&","&100,J39&","&100) -> 3,100|5,100|6,100|8,100|9,100|10,100|12,100 | K40: =IF(J40<>"",J40&"|"&K39&","&100,K39&","&100) -> 3,100|5,100|6,100|8,100|9,100|10,100|12,100|21,100 | ... W40: =IF(V40<>"",V40&"|"&W39&","&100,W39&","&100) -> 3,100|5,100|6,100|8,100|9,100|10,100|12,100|21,100|23,100|26,100|27,100|28,100|29,100|30,100|34,100|35,100|36,100|37,100|39,100|41,100
B41: 布蓝达 | C41: 21 | D41: 班尼迪克 | E41: 玛德琳 | F41: 布莱兹 | G41: 丝特芬妮 | H41: 琼 | I41: 亚度尼斯 | J41: 占卜婆婆 | K41: 奥蒂莉亚 | L41: 希拉 | M41: 希尔达 | N41: 帕特里克 | O41: 马勒第兹 | P41: 考波特 | Q41: 夏佐 | R41: 爱格伯特 | S41: 阿普敦 | T41: 艾琳娜 | U41: 莱特 | V41: 阿尔杰农 | W41: 纺织婆婆
...
